<?xml version="1.0" ?>
<!-- =================================================================================== -->
<!-- |    This document was autogenerated by xacro from simple_piper_gazebo.urdf.xacro | -->
<!-- |    EDITING THIS FILE BY HAND IS NOT RECOMMENDED                                 | -->
<!-- =================================================================================== -->
<robot name="simple_robot">
  <!-- Import all Gazebo-customization elements, including Gazebo colors -->
  <!-- World -->
  <gazebo reference="world"/>
  <!-- Evn Link -->
  <gazebo reference="env"/>
  <!-- ros_control plugin -->
  <link name="world"/>
  <joint name="robot1/env_arm_fixed" type="fixed">
    <parent link="world"/>
    <child link="robot1/base_link"/>
    <origin rpy="0 0 0" xyz="0 0 0"/>
  </joint>
  <mujoco>
    <compiler angle="radian" meshdir="../../" autolimits="true" strippath="false" fusestatic="false"/>
  </mujoco>
  <link name="robot1/base_link">
    <inertial>
      <origin rpy="0 0 0" xyz="-0.00473641164191482 2.56829134630247E-05 0.041451518036016"/>
      <mass value="1.02"/>
      <inertia ixx="0.00267433" ixy="-0.00000073" ixz="-0.00017389" iyy="0.00282612" iyz="0.0000004" izz="0.00089624"/>
    </inertial>
    <visual>
      <origin rpy="0 0 0" xyz="0 0 0"/>
      <geometry>
        <mesh filename="assets/piper/base_link.STL"/>
      </geometry>
      <material name="">
        <color rgba="0.792156862745098 0.819607843137255 0.933333333333333 1"/>
      </material>
    </visual>
    <collision>
      <origin rpy="0 0 0" xyz="0 0 0"/>
      <geometry>
        <mesh filename="assets/piper/base_link.STL"/>
      </geometry>
    </collision>
  </link>
  <link name="robot1/link1">
    <inertial>
      <origin rpy="0 0 0" xyz="0.000121504734057468 0.000104632162460536 -0.00438597309559853"/>
      <mass value="0.71"/>
      <inertia ixx="0.00048916" ixy="-0.00000036" ixz="-0.00000224" iyy="0.00040472" iyz="-0.00000242" izz="0.00043982"/>
    </inertial>
    <visual>
      <origin rpy="0 0 0" xyz="0 0 0"/>
      <geometry>
        <mesh filename="assets/piper/link1.STL"/>
      </geometry>
      <material name="">
        <color rgba="0.792156862745098 0.819607843137255 0.933333333333333 1"/>
      </material>
    </visual>
    <collision>
      <origin rpy="0 0 0" xyz="0 0 0"/>
      <geometry>
        <mesh filename="assets/piper/link1.STL"/>
      </geometry>
    </collision>
  </link>
  <joint name="robot1/joint1" type="revolute">
    <origin rpy="0 0 0" xyz="0 0 0.123"/>
    <parent link="robot1/base_link"/>
    <child link="robot1/link1"/>
    <axis xyz="0 0 1"/>
    <limit effort="100" lower="-2.618" upper="2.168" velocity="5"/>
  </joint>
  <transmission name="robot1/tran1">
    <type>transmission_interface/SimpleTransmission</type>
    <joint name="robot1/joint1">
      <hardwareInterface>hardware_interface/EffortJointInterface</hardwareInterface>
    </joint>
    <actuator name="robot1/motor1">
      <mechanicalReduction>1</mechanicalReduction>
    </actuator>
  </transmission>
  <link name="robot1/link2">
    <inertial>
      <origin rpy="0 0 0" xyz="0.198666145229743 -0.010926924140076 0.00142121714502687"/>
      <mass value="1.17"/>
      <inertia ixx="0.00116918" ixy="-0.00180037" ixz="0.00025146" iyy="0.06785384" iyz="-0.00000455" izz="0.06774489"/>
    </inertial>
    <visual>
      <origin rpy="0 0 0" xyz="0 0 0"/>
      <geometry>
        <mesh filename="assets/piper/link2.STL"/>
      </geometry>
      <material name="">
        <color rgba="0.792156862745098 0.819607843137255 0.933333333333333 1"/>
      </material>
    </visual>
    <collision>
      <origin rpy="0 0 0" xyz="0 0 0"/>
      <geometry>
        <mesh filename="assets/piper/link2.STL"/>
      </geometry>
    </collision>
  </link>
  <joint name="robot1/joint2" type="revolute">
    <origin rpy="1.5708 -0.10095 -3.1416" xyz="0 0 0"/>
    <parent link="robot1/link1"/>
    <child link="robot1/link2"/>
    <axis xyz="0 0 1"/>
    <limit effort="100" lower="0" upper="3.14" velocity="5"/>
  </joint>
  <transmission name="robot1/tran2">
    <type>transmission_interface/SimpleTransmission</type>
    <joint name="robot1/joint2">
      <hardwareInterface>hardware_interface/EffortJointInterface</hardwareInterface>
    </joint>
    <actuator name="robot1/motor2">
      <mechanicalReduction>1</mechanicalReduction>
    </actuator>
  </transmission>
  <link name="robot1/link3">
    <inertial>
      <origin rpy="0 0 0" xyz="-0.0202737662122021 -0.133914995944595 -0.000458682652737356"/>
      <mass value="0.5"/>
      <inertia ixx="0.01361711" ixy="0.00165794" ixz="-0.00000048" iyy="0.00045024" iyz="-0.00000045" izz="0.01380322"/>
    </inertial>
    <visual>
      <origin rpy="0 0 0" xyz="0 0 0"/>
      <geometry>
        <mesh filename="assets/piper/link3.STL"/>
      </geometry>
      <material name="">
        <color rgba="0.792156862745098 0.819607843137255 0.933333333333333 1"/>
      </material>
    </visual>
    <collision>
      <origin rpy="0 0 0" xyz="0 0 0"/>
      <geometry>
        <mesh filename="assets/piper/link3.STL"/>
      </geometry>
    </collision>
  </link>
  <joint name="robot1/joint3" type="revolute">
    <origin rpy="0 0 -1.759" xyz="0.28503 0 0"/>
    <parent link="robot1/link2"/>
    <child link="robot1/link3"/>
    <axis xyz="0 0 1"/>
    <limit effort="100" lower="-2.967" upper="0" velocity="5"/>
  </joint>
  <transmission name="robot1/tran3">
    <type>transmission_interface/SimpleTransmission</type>
    <joint name="robot1/joint3">
      <hardwareInterface>hardware_interface/EffortJointInterface</hardwareInterface>
    </joint>
    <actuator name="robot1/motor3">
      <mechanicalReduction>1</mechanicalReduction>
    </actuator>
  </transmission>
  <link name="robot1/link4">
    <inertial>
      <origin rpy="0 0 0" xyz="-9.66635791618542E-05 0.000876064475651083 -0.00496880904640868"/>
      <mass value="0.38"/>
      <inertia ixx="0.00018501" ixy="0.00000054" ixz="0.00000120" iyy="0.00018965" iyz="-0.00000841" izz="0.00015484"/>
    </inertial>
    <visual>
      <origin rpy="0 0 0" xyz="0 0 0"/>
      <geometry>
        <mesh filename="assets/piper/link4.STL"/>
      </geometry>
      <material name="">
        <color rgba="0.792156862745098 0.819607843137255 0.933333333333333 1"/>
      </material>
    </visual>
    <collision>
      <origin rpy="0 0 0" xyz="0 0 0"/>
      <geometry>
        <mesh filename="assets/piper/link4.STL"/>
      </geometry>
    </collision>
  </link>
  <joint name="robot1/joint4" type="revolute">
    <origin rpy="1.5708 0 0" xyz="-0.021984 -0.25075 0"/>
    <parent link="robot1/link3"/>
    <child link="robot1/link4"/>
    <axis xyz="0 0 1"/>
    <limit effort="100" lower="-1.745" upper="1.745" velocity="5"/>
  </joint>
  <transmission name="robot1/tran4">
    <type>transmission_interface/SimpleTransmission</type>
    <joint name="robot1/joint4">
      <hardwareInterface>hardware_interface/EffortJointInterface</hardwareInterface>
    </joint>
    <actuator name="robot1/motor4">
      <mechanicalReduction>1</mechanicalReduction>
    </actuator>
  </transmission>
  <link name="robot1/link5">
    <inertial>
      <origin rpy="0 0 0" xyz="-4.10554118924211E-05 -0.0566486692356075 -0.0037205791677906"/>
      <mass value="0.383"/>
      <inertia ixx="0.00166169" ixy="0.00000006" ixz="-0.00000007" iyy="0.00018510" iyz="0.00001026" izz="0.00164321"/>
    </inertial>
    <visual>
      <origin rpy="0 0 0" xyz="0 0 0"/>
      <geometry>
        <mesh filename="assets/piper/link5.STL"/>
      </geometry>
      <material name="">
        <color rgba="0.792156862745098 0.819607843137255 0.933333333333333 1"/>
      </material>
    </visual>
    <collision>
      <origin rpy="0 0 0" xyz="0 0 0"/>
      <geometry>
        <mesh filename="assets/piper/link5.STL"/>
      </geometry>
    </collision>
  </link>
  <joint name="robot1/joint5" type="revolute">
    <origin rpy="-1.5708 0 0" xyz="0 0 0"/>
    <parent link="robot1/link4"/>
    <child link="robot1/link5"/>
    <axis xyz="0 0 1"/>
    <limit effort="100" lower="-1.22" upper="1.22" velocity="5"/>
  </joint>
  <transmission name="robot1/tran5">
    <type>transmission_interface/SimpleTransmission</type>
    <joint name="robot1/joint5">
      <hardwareInterface>hardware_interface/EffortJointInterface</hardwareInterface>
    </joint>
    <actuator name="robot1/motor5">
      <mechanicalReduction>1</mechanicalReduction>
    </actuator>
  </transmission>
  <link name="robot1/link6">
    <inertial>
      <origin rpy="0 0 0" xyz="-8.82590762930069E-05 9.0598378529832E-06 -0.002"/>
      <mass value="0.00699089613564366"/>
      <inertia ixx="5.73015540542155E-07" ixy="-1.98305403089247E-22" ixz="-7.2791893904596E-23" iyy="5.73015540542155E-07" iyz="-3.4146026640245E-24" izz="1.06738869138926E-06"/>
    </inertial>
    <visual>
      <origin rpy="0 0 0" xyz="0 0 0"/>
      <geometry>
        <mesh filename="assets/piper/link6.STL"/>
      </geometry>
      <material name="">
        <color rgba="0.898039215686275 0.917647058823529 0.929411764705882 1"/>
      </material>
    </visual>
    <collision>
      <origin rpy="0 0 0" xyz="0 0 0"/>
      <geometry>
        <mesh filename="assets/piper/link6.STL"/>
      </geometry>
    </collision>
  </link>
  <joint name="robot1/joint6" type="revolute">
    <origin rpy="1.5708 0 0" xyz="8.8259E-05 -0.091 0"/>
    <parent link="robot1/link5"/>
    <child link="robot1/link6"/>
    <axis xyz="0 0 1"/>
    <limit effort="100" lower="-2.0944" upper="2.0944" velocity="5"/>
  </joint>
  <transmission name="robot1/tran6">
    <type>transmission_interface/SimpleTransmission</type>
    <joint name="robot1/joint6">
      <hardwareInterface>hardware_interface/EffortJointInterface</hardwareInterface>
    </joint>
    <actuator name="robot1/motor6">
      <mechanicalReduction>1</mechanicalReduction>
    </actuator>
  </transmission>
  <!-- <xacro:piper_ros2_control_gazebo systems="${systems}" system_prefix="${system_prefix}" arm_ids="${arm_ids}" controller_params="${controller_params}"/> -->
</robot>
