<mujoco model="papras_stand">
  <compiler angle="radian" meshdir="../../" autolimits="true"/>
 <include file="../../assets/scene/floor_sky.xml" />
  <asset>
    <mesh name="2arm_stand_simple" file="assets/scene/2arm_stand_simple.stl"/>
    <mesh name="link1" file="assets/papras/link1.stl" scale="0.001 0.001 0.001"/>
    <mesh name="link2" file="assets/papras/link2.stl" scale="0.001 0.001 0.001"/>
    <mesh name="link3" file="assets/papras/7dof/link3.stl"/>
    <mesh name="link4" file="assets/papras/7dof/link4.stl"/>
    <mesh name="link4_papras" file="assets/papras/link4_papras.stl" scale="0.001 0.001 0.001"/>
    <mesh name="link4_papras_simple" file="assets/papras/link4_papras_simple.stl" scale="0.001 0.001 0.001"/>
    <mesh name="link5" file="assets/papras/link5.stl" scale="0.001 0.001 0.001"/>
    <mesh name="link6_papras" file="assets/papras/link6_papras.stl" scale="0.001 0.001 0.001"/>
    <mesh name="link6_papras_simple" file="assets/papras/link6_papras_simple.stl" scale="0.001 0.001 0.001"/>
    <mesh name="end_link" file="assets/papras/end_link.stl" scale="0.001 0.001 0.001"/>
    <mesh name="rh_p12_rn_base" file="assets/robotis_hand_rh-p12-rn/rh_p12_rn_base.stl" scale="0.001 0.001 0.001"/>
    <mesh name="rh_p12_rn_r1" file="assets/robotis_hand_rh-p12-rn/rh_p12_rn_r1.stl" scale="0.001 0.001 0.001"/>
    <mesh name="rh_p12_rn_r2" file="assets/robotis_hand_rh-p12-rn/rh_p12_rn_r2.stl" scale="0.001 0.001 0.001"/>
    <mesh name="rh_p12_rn_l1" file="assets/robotis_hand_rh-p12-rn/rh_p12_rn_l1.stl" scale="0.001 0.001 0.001"/>
    <mesh name="rh_p12_rn_l2" file="assets/robotis_hand_rh-p12-rn/rh_p12_rn_l2.stl" scale="0.001 0.001 0.001"/>
    <mesh name="camera_mount_simple" file="assets/papras/camera_mount_simple.stl"/>
  </asset>
  <worldbody>
    <body name="env" quat="0.000796327 0 0 1">
      <inertial pos="-0.00217819 0.0115131 4.82153e-05" quat="0.707114 -9.18314e-06 9.18295e-06 0.707099" mass="24.32" diaginertia="3.22235 2.59731 0.632618"/>
      <geom type="mesh" contype="0" conaffinity="0" group="1" density="0" rgba="0.501961 0.501961 0.501961 1" mesh="2arm_stand_simple"/>
      <geom type="mesh" rgba="0.501961 0.501961 0.501961 1" mesh="2arm_stand_simple"/>
      <body name="robot1/link1" pos="0 0.05619 1.66" quat="0.500398 -0.5 0.5 0.499602">
        <inertial pos="0.00023 0 0.06223" quat="0.999978 0 -0.00662802 0" mass="0.85644" diaginertia="0.00121079 0.00120886 0.000380884"/>
        <geom type="mesh" contype="0" conaffinity="0" group="1" density="0" mesh="link1"/>
        <geom type="mesh" mesh="link1"/>
        <body name="robot1/link2" pos="0 0 0.126">
          <inertial pos="0 0.0008 0.03183" mass="0.94658" diaginertia="1 1 1"/>
          <joint name="robot1/joint1" pos="0 0 0" axis="0 0 1" range="-3.14159 3.14159" actuatorfrcrange="-100 100" damping="0.7"/>
          <geom type="mesh" contype="0" conaffinity="0" group="1" density="0" mesh="link2"/>
          <geom type="mesh" mesh="link2"/>
          <body name="robot1/link3" pos="0 0 0.033" quat="0.5 0.5 -0.5 0.5">
            <inertial pos="0 0.0008 0.03183" quat="0.703415 0.072218 0.0722276 0.703403" mass="0.49982" diaginertia="0.0012133 0.000790453 0.000735177"/>
            <joint name="robot1/joint2" pos="0 0 0" axis="0 0 1" range="-2 2" actuatorfrcrange="-100 100" damping="0.7"/>
            <geom type="mesh" contype="0" conaffinity="0" group="1" density="0" mesh="link3"/>
            <geom type="mesh" mesh="link3"/>
            <body name="robot1/link4" pos="0.156382 0 0.0004" quat="0.5 -0.5 -0.5 -0.5">
              <inertial pos="-4.86609e-06 0.120506 -0.0279123" quat="0.517023 0.479344 -0.474274 0.527239" mass="0.597399" diaginertia="0.00186711 0.00155302 0.000763407"/>
              <joint name="robot1/joint3" pos="0 0 0" axis="0 1 0" range="-3.14159 3.14159" actuatorfrcrange="-100 100" damping="0.7"/>
              <geom type="mesh" contype="0" conaffinity="0" group="1" density="0" mesh="link4"/>
              <geom type="mesh" mesh="link4"/>
              <body name="robot1/link5" pos="0.0575 0.107618 0.03" quat="-0.5 0.5 0.5 0.5">
                <inertial pos="0.12475 -0.05716 0.02979" mass="1.15977" diaginertia="1 1 1"/>
                <joint name="robot1/joint4" pos="0 0 0" axis="0 1 0" range="-3.14159 1.42" actuatorfrcrange="-100 100" damping="0.7"/>
                <geom pos="0.227 0.0085 -0.024" quat="0.000796327 0 0 1" type="mesh" contype="0" conaffinity="0" group="1" density="0" mesh="link4_papras"/>
                <geom pos="0.227 0.0085 -0.024" quat="0.000796327 0 0 1" type="mesh" mesh="link4_papras_simple"/>
                <body name="robot1/link6" pos="0.195 -0.0575 0.03">
                  <inertial pos="0.05642 -0.00217 2e-05" mass="0.44688" diaginertia="1 1 1"/>
                  <joint name="robot1/joint5" pos="0 0 0" axis="1 0 0" range="-2.74889 2.74889" actuatorfrcrange="-100 100" damping="0.7"/>
                  <geom type="mesh" contype="0" conaffinity="0" group="1" density="0" mesh="link5"/>
                  <geom type="mesh" mesh="link5"/>
                  <body name="robot1/link7" pos="0.063 0.045 0">
                    <inertial pos="0.06831 -0.04457 0" mass="0.43273" diaginertia="1 1 1"/>
                    <joint name="robot1/joint6" pos="0 0 0" axis="0 1 0" range="-1.5708 1.5708" actuatorfrcrange="-100 100" damping="0.7"/>
                    <geom pos="-0.034 -0.098 -0.028" type="mesh" contype="0" conaffinity="0" group="1" density="0" mesh="link6_papras"/>
                    <geom pos="-0.034 -0.098 -0.028" type="mesh" mesh="link6_papras_simple"/>
                    <body name="robot1/end_link" pos="0.123 -0.045 0">
                      <inertial pos="0.00337 0 0" mass="0.01919" diaginertia="1 1 1"/>
                      <joint name="robot1/joint7" pos="0 0 0" axis="1 0 0" range="-3.14159 3.14159" actuatorfrcrange="-100 100" damping="0.7"/>
                      <geom type="mesh" contype="0" conaffinity="0" group="1" density="0" mesh="end_link"/>
                      <geom type="mesh" mesh="end_link"/>
                      <body name="robot1/gripper_main_link" pos="0.006 0 0" quat="0 0.707107 0 0.707107">
                        <inertial pos="0 0 0.032" mass="0.236" diaginertia="1 1 1"/>
                        <geom type="mesh" mesh="rh_p12_rn_base"/>
                        <geom type="mesh" contype="0" conaffinity="0" group="1" density="0" mesh="rh_p12_rn_base"/>
                        <body name="robot1/gripper_link" pos="0 0.008 0.048">
                          <inertial pos="0 0.034 0.004" mass="0.068" diaginertia="1 1 1"/>
                          <joint name="robot1/gripper" pos="0 0 0" axis="1 0 0" range="0 1.1" actuatorfrcrange="-1000 1000" damping="0.7"/>
                          <geom type="mesh" mesh="rh_p12_rn_r1"/>
                          <geom type="mesh" contype="0" conaffinity="0" group="1" density="0" mesh="rh_p12_rn_r1"/>
                          <body name="robot1/gripper_link_r2" pos="0 0.0493634 0.0285">
                            <inertial pos="0 0.006 0.011" mass="0.022" diaginertia="1 1 1"/>
                            <joint name="robot1/gripper_r2" pos="0 0 0" axis="-1 0 0" range="0 1" actuatorfrcrange="-1000 1000" damping="0.7"/>
                            <geom type="mesh" mesh="rh_p12_rn_r2"/>
                            <geom type="mesh" contype="0" conaffinity="0" group="1" density="0" mesh="rh_p12_rn_r2"/>
                          </body>
                        </body>
                        <body name="robot1/gripper_link_l1" pos="0 -0.008 0.048">
                          <inertial pos="0 -0.034 0.004" mass="0.068" diaginertia="1 1 1"/>
                          <joint name="robot1/gripper_l1" pos="0 0 0" axis="-1 0 0" range="0 1.1" actuatorfrcrange="-1000 1000" damping="0.7"/>
                          <geom type="mesh" mesh="rh_p12_rn_l1"/>
                          <geom type="mesh" contype="0" conaffinity="0" group="1" density="0" mesh="rh_p12_rn_l1"/>
                          <body name="robot1/gripper_link_l2" pos="0 -0.0493634 0.0285">
                            <inertial pos="0 -0.006 0.011" mass="0.022" diaginertia="1 1 1"/>
                            <joint name="robot1/gripper_l2" pos="0 0 0" axis="1 0 0" range="0 1" actuatorfrcrange="-1000 1000" damping="0.7"/>
                            <geom type="mesh" mesh="rh_p12_rn_l2"/>
                            <geom type="mesh" contype="0" conaffinity="0" group="1" density="0" mesh="rh_p12_rn_l2"/>
                          </body>
                        </body>
                        <body name="robot1/end_effector_link" pos="0 0 0.135" quat="0 0.707107 0 0.707107">
                          <inertial pos="0 0 0" mass="0.001" diaginertia="1 1 1"/>
                          <geom size="0.005 0.005 0.005" type="box" contype="0" conaffinity="0" group="1" density="0" rgba="0.8 0 0 1"/>
                        </body>
                        <body name="robot1/camera_mount" pos="0.04452 -0.0167 0.049" quat="0.707107 0 0 0.707107">
                          <inertial pos="0 0 0" mass="0.088" diaginertia="1 1 1"/>
                          <geom quat="0.5 0.5 -0.5 0.5" type="mesh" contype="0" conaffinity="0" group="1" density="0" mesh="camera_mount_simple"/>
                          <geom quat="0.5 0.5 -0.5 0.5" type="mesh" mesh="camera_mount_simple"/>
                          <body name="robot1/camera_plugin_link" quat="0.5 0.5 -0.5 0.5"/>
                        </body>
                      </body>
                    </body>
                  </body>
                </body>
              </body>
            </body>
          </body>
        </body>
      </body>
      <body name="robot2/link1" pos="0 -0.05619 1.66" quat="0.500398 0.5 0.5 -0.499602">
        <inertial pos="0.00023 0 0.06223" quat="0.999978 0 -0.00662802 0" mass="0.85644" diaginertia="0.00121079 0.00120886 0.000380884"/>
        <geom type="mesh" contype="0" conaffinity="0" group="1" density="0" mesh="link1"/>
        <geom type="mesh" mesh="link1"/>
        <body name="robot2/link2" pos="0 0 0.126">
          <inertial pos="0 0.0008 0.03183" mass="0.94658" diaginertia="1 1 1"/>
          <joint name="robot2/joint1" pos="0 0 0" axis="0 0 1" range="-3.14159 3.14159" actuatorfrcrange="-100 100" damping="0.7"/>
          <geom type="mesh" contype="0" conaffinity="0" group="1" density="0" mesh="link2"/>
          <geom type="mesh" mesh="link2"/>
          <body name="robot2/link3" pos="0 0 0.033" quat="0.5 0.5 -0.5 0.5">
            <inertial pos="0 0.0008 0.03183" quat="0.703415 0.072218 0.0722276 0.703403" mass="0.49982" diaginertia="0.0012133 0.000790453 0.000735177"/>
            <joint name="robot2/joint2" pos="0 0 0" axis="0 0 1" range="-2 2" actuatorfrcrange="-100 100" damping="0.7"/>
            <geom type="mesh" contype="0" conaffinity="0" group="1" density="0" mesh="link3"/>
            <geom type="mesh" mesh="link3"/>
            <body name="robot2/link4" pos="0.156382 0 0.0004" quat="0.5 -0.5 -0.5 -0.5">
              <inertial pos="-4.86609e-06 0.120506 -0.0279123" quat="0.517023 0.479344 -0.474274 0.527239" mass="0.597399" diaginertia="0.00186711 0.00155302 0.000763407"/>
              <joint name="robot2/joint3" pos="0 0 0" axis="0 1 0" range="-3.14159 3.14159" actuatorfrcrange="-100 100" damping="0.7"/>
              <geom type="mesh" contype="0" conaffinity="0" group="1" density="0" mesh="link4"/>
              <geom type="mesh" mesh="link4"/>
              <body name="robot2/link5" pos="0.0575 0.107618 0.03" quat="-0.5 0.5 0.5 0.5">
                <inertial pos="0.12475 -0.05716 0.02979" mass="1.15977" diaginertia="1 1 1"/>
                <joint name="robot2/joint4" pos="0 0 0" axis="0 1 0" range="-3.14159 1.42" actuatorfrcrange="-100 100" damping="0.7"/>
                <geom pos="0.227 0.0085 -0.024" quat="0.000796327 0 0 1" type="mesh" contype="0" conaffinity="0" group="1" density="0" mesh="link4_papras"/>
                <geom pos="0.227 0.0085 -0.024" quat="0.000796327 0 0 1" type="mesh" mesh="link4_papras_simple"/>
                <body name="robot2/link6" pos="0.195 -0.0575 0.03">
                  <inertial pos="0.05642 -0.00217 2e-05" mass="0.44688" diaginertia="1 1 1"/>
                  <joint name="robot2/joint5" pos="0 0 0" axis="1 0 0" range="-2.74889 2.74889" actuatorfrcrange="-100 100" damping="0.7"/>
                  <geom type="mesh" contype="0" conaffinity="0" group="1" density="0" mesh="link5"/>
                  <geom type="mesh" mesh="link5"/>
                  <body name="robot2/link7" pos="0.063 0.045 0">
                    <inertial pos="0.06831 -0.04457 0" mass="0.43273" diaginertia="1 1 1"/>
                    <joint name="robot2/joint6" pos="0 0 0" axis="0 1 0" range="-1.5708 1.5708" actuatorfrcrange="-100 100" damping="0.7"/>
                    <geom pos="-0.034 -0.098 -0.028" type="mesh" contype="0" conaffinity="0" group="1" density="0" mesh="link6_papras"/>
                    <geom pos="-0.034 -0.098 -0.028" type="mesh" mesh="link6_papras_simple"/>
                    <body name="robot2/end_link" pos="0.123 -0.045 0">
                      <inertial pos="0.00337 0 0" mass="0.01919" diaginertia="1 1 1"/>
                      <joint name="robot2/joint7" pos="0 0 0" axis="1 0 0" range="-3.14159 3.14159" actuatorfrcrange="-100 100" damping="0.7"/>
                      <geom type="mesh" contype="0" conaffinity="0" group="1" density="0" mesh="end_link"/>
                      <geom type="mesh" mesh="end_link"/>
                      <body name="robot2/gripper_main_link" pos="0.006 0 0" quat="0 0.707107 0 0.707107">
                        <inertial pos="0 0 0.032" mass="0.236" diaginertia="1 1 1"/>
                        <geom type="mesh" mesh="rh_p12_rn_base"/>
                        <geom type="mesh" contype="0" conaffinity="0" group="1" density="0" mesh="rh_p12_rn_base"/>
                        <body name="robot2/gripper_link" pos="0 0.008 0.048">
                          <inertial pos="0 0.034 0.004" mass="0.068" diaginertia="1 1 1"/>
                          <joint name="robot2/gripper" pos="0 0 0" axis="1 0 0" range="0 1.1" actuatorfrcrange="-1000 1000" damping="0.7"/>
                          <geom type="mesh" mesh="rh_p12_rn_r1"/>
                          <geom type="mesh" contype="0" conaffinity="0" group="1" density="0" mesh="rh_p12_rn_r1"/>
                          <body name="robot2/gripper_link_r2" pos="0 0.0493634 0.0285">
                            <inertial pos="0 0.006 0.011" mass="0.022" diaginertia="1 1 1"/>
                            <joint name="robot2/gripper_r2" pos="0 0 0" axis="-1 0 0" range="0 1" actuatorfrcrange="-1000 1000" damping="0.7"/>
                            <geom type="mesh" mesh="rh_p12_rn_r2"/>
                            <geom type="mesh" contype="0" conaffinity="0" group="1" density="0" mesh="rh_p12_rn_r2"/>
                          </body>
                        </body>
                        <body name="robot2/gripper_link_l1" pos="0 -0.008 0.048">
                          <inertial pos="0 -0.034 0.004" mass="0.068" diaginertia="1 1 1"/>
                          <joint name="robot2/gripper_l1" pos="0 0 0" axis="-1 0 0" range="0 1.1" actuatorfrcrange="-1000 1000" damping="0.7"/>
                          <geom type="mesh" mesh="rh_p12_rn_l1"/>
                          <geom type="mesh" contype="0" conaffinity="0" group="1" density="0" mesh="rh_p12_rn_l1"/>
                          <body name="robot2/gripper_link_l2" pos="0 -0.0493634 0.0285">
                            <inertial pos="0 -0.006 0.011" mass="0.022" diaginertia="1 1 1"/>
                            <joint name="robot2/gripper_l2" pos="0 0 0" axis="1 0 0" range="0 1" actuatorfrcrange="-1000 1000" damping="0.7"/>
                            <geom type="mesh" mesh="rh_p12_rn_l2"/>
                            <geom type="mesh" contype="0" conaffinity="0" group="1" density="0" mesh="rh_p12_rn_l2"/>
                          </body>
                        </body>
                        <body name="robot2/end_effector_link" pos="0 0 0.135" quat="0 0.707107 0 0.707107">
                          <inertial pos="0 0 0" mass="0.001" diaginertia="1 1 1"/>
                          <geom size="0.005 0.005 0.005" type="box" contype="0" conaffinity="0" group="1" density="0" rgba="0.8 0 0 1"/>
                        </body>
                        <body name="robot2/camera_mount" pos="0.04452 -0.0167 0.049" quat="0.707107 0 0 0.707107">
                          <inertial pos="0 0 0" mass="0.088" diaginertia="1 1 1"/>
                          <geom quat="0.5 0.5 -0.5 0.5" type="mesh" contype="0" conaffinity="0" group="1" density="0" mesh="camera_mount_simple"/>
                          <geom quat="0.5 0.5 -0.5 0.5" type="mesh" mesh="camera_mount_simple"/>
                          <body name="robot2/camera_plugin_link" quat="0.5 0.5 -0.5 0.5"/>
                        </body>
                      </body>
                    </body>
                  </body>
                </body>
              </body>
            </body>
          </body>
        </body>
      </body>
    </body>
  </worldbody>
    <actuator>
    <!-- Arm joints -->
    <motor name="robot1/joint1" joint="robot1/joint1" ctrllimited="true" ctrlrange="-100 100" gear="1"/>
    <motor name="robot1/joint2" joint="robot1/joint2" ctrllimited="true" ctrlrange="-100 100" gear="1"/>
    <motor name="robot1/joint3" joint="robot1/joint3" ctrllimited="true" ctrlrange="-100 100" gear="1"/>
    <motor name="robot1/joint4" joint="robot1/joint4" ctrllimited="true" ctrlrange="-100 100" gear="1"/>
    <motor name="robot1/joint5" joint="robot1/joint5" ctrllimited="true" ctrlrange="-100 100" gear="1"/>
    <motor name="robot1/joint6" joint="robot1/joint6" ctrllimited="true" ctrlrange="-100 100" gear="1"/>
    <motor name="robot1/joint7" joint="robot1/joint7" ctrllimited="true" ctrlrange="-100 100" gear="1"/>

    <motor name="robot2/joint1" joint="robot2/joint1" ctrllimited="true" ctrlrange="-100 100" gear="1"/>
    <motor name="robot2/joint2" joint="robot2/joint2" ctrllimited="true" ctrlrange="-100 100" gear="1"/>
    <motor name="robot2/joint3" joint="robot2/joint3" ctrllimited="true" ctrlrange="-100 100" gear="1"/>
    <motor name="robot2/joint4" joint="robot2/joint4" ctrllimited="true" ctrlrange="-100 100" gear="1"/>
    <motor name="robot2/joint5" joint="robot2/joint5" ctrllimited="true" ctrlrange="-100 100" gear="1"/>
    <motor name="robot2/joint6" joint="robot2/joint6" ctrllimited="true" ctrlrange="-100 100" gear="1"/>
    <motor name="robot2/joint7" joint="robot2/joint7" ctrllimited="true" ctrlrange="-100 100" gear="1"/>

    <!-- Gripper joints -->
    <motor name="robot1/gripper" joint="robot1/gripper" ctrllimited="true" ctrlrange="-1000 1000" gear="1"/>
    <motor name="robot1/gripper_r2" joint="robot1/gripper_r2" ctrllimited="true" ctrlrange="-1000 1000" gear="1"/>
    <motor name="robot1/gripper_l1" joint="robot1/gripper_l1" ctrllimited="true" ctrlrange="-1000 1000" gear="1"/>
    <motor name="robot1/gripper_l2" joint="robot1/gripper_l2" ctrllimited="true" ctrlrange="-1000 1000" gear="1"/>

    <motor name="robot2/gripper" joint="robot2/gripper" ctrllimited="true" ctrlrange="-1000 1000" gear="1"/>
    <motor name="robot2/gripper_r2" joint="robot2/gripper_r2" ctrllimited="true" ctrlrange="-1000 1000" gear="1"/>
    <motor name="robot2/gripper_l1" joint="robot2/gripper_l1" ctrllimited="true" ctrlrange="-1000 1000" gear="1"/>
    <motor name="robot2/gripper_l2" joint="robot2/gripper_l2" ctrllimited="true" ctrlrange="-1000 1000" gear="1"/>
  </actuator>
  <contact>
    <exclude body1="robot1/link1" body2="robot1/link2" />
    <exclude body1="robot2/link1" body2="robot2/link2" />
    <exclude body1="robot1/gripper_link_r2" body2="robot1/gripper_link_l2" />
    <exclude body1="robot2/gripper_link_r2" body2="robot2/gripper_link_l2" />
  </contact>
</mujoco>
