<mujoco model="UF_ROBOT">
  <compiler angle="radian" meshdir="../"/>
  <asset>
    <mesh name="link_base" file="assets/xarm/xarm6/visual/link_base.stl"/>
    <mesh name="link1" file="assets/xarm/xarm6/visual/link1.stl"/>
    <mesh name="link2" file="assets/xarm/xarm6/visual/link2.stl"/>
    <mesh name="link3" file="assets/xarm/xarm6/visual/link3.stl"/>
    <mesh name="link4" file="assets/xarm/xarm6/visual/link4.stl"/>
    <mesh name="link5" file="assets/xarm/xarm6/visual/link5.stl"/>
    <mesh name="end_tool" file="assets/xarm/end_tool/collision/end_tool.stl"/>
    <mesh name="base_link" file="assets/xarm/gripper/xarm/base_link.stl"/>
    <mesh name="left_outer_knuckle" file="assets/xarm/gripper/xarm/left_outer_knuckle.stl"/>
    <mesh name="left_finger" file="assets/xarm/gripper/xarm/left_finger.stl"/>
    <mesh name="left_inner_knuckle" file="assets/xarm/gripper/xarm/left_inner_knuckle.stl"/>
    <mesh name="right_outer_knuckle" file="assets/xarm/gripper/xarm/right_outer_knuckle.stl"/>
    <mesh name="right_finger" file="assets/xarm/gripper/xarm/right_finger.stl"/>
    <mesh name="right_inner_knuckle" file="assets/xarm/gripper/xarm/right_inner_knuckle.stl"/>
  </asset>
  <worldbody>
    <body name="link_base">
      <inertial pos="0 0 0.09103" quat="0.981065 0.000747228 -0.0021866 -0.193666" mass="2.7" diaginertia="0.00495024 0.00494031 0.00221894"/>
      <geom type="mesh" rgba="1 1 1 1" mesh="link_base"/>
      <body name="link1" pos="0 0 0.267">
        <inertial pos="0.00022 0.02951 -0.0124" quat="0.976139 -0.216078 -0.00387312 -0.0211677" mass="2.3814" diaginertia="0.00585697 0.00544434 0.00312315"/>
        <joint name="joint1" pos="0 0 0" axis="0 0 1" range="-6.28319 6.28319" actuatorfrcrange="-50 50" damping="1" frictionloss="1"/>
        <geom type="mesh" rgba="1 1 1 1" mesh="link1"/>
        <body name="link2" quat="0.707105 -0.707108 0 0">
          <inertial pos="0.03881 -0.22783 0.03496" quat="0.635305 0.753023 0.170976 -0.010531" mass="2.2675" diaginertia="0.0294477 0.0281783 0.00383449"/>
          <joint name="joint2" pos="0 0 0" axis="0 0 1" range="-2.059 2.0944" actuatorfrcrange="-50 50" damping="1" frictionloss="1"/>
          <geom type="mesh" rgba="1 1 1 1" mesh="link2"/>
          <body name="link3" pos="0.0535 -0.2845 0">
            <inertial pos="0.07041 0.11631 0.0107" quat="0.845838 0.425539 -0.293179 0.132369" mass="1.875" diaginertia="0.00714132 0.00699471 0.00196753"/>
            <joint name="joint3" pos="0 0 0" axis="0 0 1" range="-3.927 0.19198" actuatorfrcrange="-32 32" damping="1" frictionloss="1"/>
            <geom type="mesh" rgba="1 1 1 1" mesh="link3"/>
            <body name="link4" pos="0.0775 0.3425 0" quat="0.707105 -0.707108 0 0">
              <inertial pos="-0.00018 0.01798 -0.02291" quat="0.99929 -0.0369702 0.00179434 -0.00701174" mass="1.3192" diaginertia="0.00489614 0.00447403 0.00132609"/>
              <joint name="joint4" pos="0 0 0" axis="0 0 1" range="-6.28319 6.28319" actuatorfrcrange="-32 32" damping="1" frictionloss="1"/>
              <geom type="mesh" rgba="1 1 1 1" mesh="link4"/>
              <body name="link5" quat="0.707105 0.707108 0 0">
                <inertial pos="0.0651 0.03096 0.00315" quat="-0.223008 0.771309 0.16027 0.574163" mass="1.33854" diaginertia="0.00241824 0.00213367 0.00108731"/>
                <joint name="joint5" pos="0 0 0" axis="0 0 1" range="-1.69297 3.14159" actuatorfrcrange="-32 32" damping="1" frictionloss="1"/>
                <geom type="mesh" rgba="1 1 1 1" mesh="link5"/>
                <body name="link6" pos="0.076 0.097 0" quat="0.707105 -0.707108 0 0">
                  <inertial pos="0 -0.00677 -0.01098" quat="0.487612 0.512088 -0.512088 0.487612" mass="0.17" diaginertia="0.000132176 9.3e-05 5.85236e-05"/>
                  <joint name="joint6" pos="0 0 0" axis="0 0 1" range="-6.28319 6.28319" actuatorfrcrange="-20 20" damping="1" frictionloss="1"/>
                  <geom type="mesh" rgba="0.753 0.753 0.753 1" mesh="end_tool"/>
                  <body name="link_eef">
                    <body name="xarm_gripper_base_link">
                      <inertial pos="-0.00065489 -0.0018497 0.048028" quat="0.997403 -0.0717512 -0.0061836 0.000477479" mass="0.54156" diaginertia="0.000471093 0.000332307 0.000254799"/>
                      <geom type="mesh" rgba="1 1 1 1" mesh="base_link"/>
                      <body name="left_outer_knuckle" pos="0 0.035 0.059098">
                        <inertial pos="0 0.021559 0.015181" quat="0.47789 0.87842 0 0" mass="0.033618" diaginertia="1.9111e-05 1.79089e-05 1.90167e-06"/>
                        <joint name="drive_joint" pos="0 0 0" axis="1 0 0" range="0 0.85" actuatorfrcrange="-50 50"/>
                        <geom type="mesh" rgba="0.753 0.753 0.753 1" mesh="left_outer_knuckle"/>
                        <body name="left_finger" pos="0 0.035465 0.042039">
                          <inertial pos="0 -0.016413 0.029258" quat="0.697634 0.115353 -0.115353 0.697634" mass="0.048304" diaginertia="1.88037e-05 1.7493e-05 3.56792e-06"/>
                          <joint name="left_finger_joint" pos="0 0 0" axis="-1 0 0" range="0 0.85" actuatorfrcrange="-50 50"/>
                          <geom type="mesh" rgba="0.753 0.753 0.753 1" mesh="left_finger"/>
                        </body>
                      </body>
                      <body name="left_inner_knuckle" pos="0 0.02 0.074098">
                        <inertial pos="1.86601e-06 0.0220468 0.0261335" quat="0.664139 -0.242732 0.242713 0.664146" mass="0.0230126" diaginertia="8.34216e-06 6.0949e-06 2.75601e-06"/>
                        <joint name="left_inner_knuckle_joint" pos="0 0 0" axis="1 0 0" range="0 0.85" actuatorfrcrange="-50 50"/>
                        <geom type="mesh" rgba="0.753 0.753 0.753 1" mesh="left_inner_knuckle"/>
                      </body>
                      <body name="right_outer_knuckle" pos="0 -0.035 0.059098">
                        <inertial pos="0 -0.021559 0.015181" quat="0.87842 0.47789 0 0" mass="0.033618" diaginertia="1.9111e-05 1.79089e-05 1.90167e-06"/>
                        <joint name="right_outer_knuckle_joint" pos="0 0 0" axis="-1 0 0" range="0 0.85" actuatorfrcrange="-50 50"/>
                        <geom type="mesh" rgba="0.753 0.753 0.753 1" mesh="right_outer_knuckle"/>
                        <body name="right_finger" pos="0 -0.035465 0.042039">
                          <inertial pos="0 0.016413 0.029258" quat="0.697634 -0.115356 0.115356 0.697634" mass="0.048304" diaginertia="1.88038e-05 1.7493e-05 3.56779e-06"/>
                          <joint name="right_finger_joint" pos="0 0 0" axis="1 0 0" range="0 0.85" actuatorfrcrange="-50 50"/>
                          <geom type="mesh" rgba="0.753 0.753 0.753 1" mesh="right_finger"/>
                        </body>
                      </body>
                      <body name="right_inner_knuckle" pos="0 -0.02 0.074098">
                        <inertial pos="1.866e-06 -0.022047 0.026133" quat="0.66415 0.242702 -0.242721 0.664144" mass="0.023013" diaginertia="8.34209e-06 6.0949e-06 2.75601e-06"/>
                        <joint name="right_inner_knuckle_joint" pos="0 0 0" axis="-1 0 0" range="0 0.85" actuatorfrcrange="-50 50"/>
                        <geom type="mesh" rgba="0.753 0.753 0.753 1" mesh="right_inner_knuckle"/>
                      </body>
                      <body name="link_tcp" pos="0 0 0.172"/>
                    </body>
                  </body>
                  <body name="link_eef_paprle" quat="2.31079e-07 0.707107 -2.31079e-07 0.707107"/>
                </body>
              </body>
            </body>
          </body>
        </body>
      </body>
    </body>
  </worldbody>
  <contact>
      <exclude body1="left_finger" body2="left_inner_knuckle" />
      <exclude body1="left_finger" body2="left_outer_knuckle" />
      <exclude body1="left_finger" body2="link4" />
      <exclude body1="left_finger" body2="link5" />
      <exclude body1="left_finger" body2="link6" />
      <exclude body1="left_finger" body2="right_finger" />
      <exclude body1="left_finger" body2="right_inner_knuckle" />
      <exclude body1="left_finger" body2="right_outer_knuckle" />
      <exclude body1="left_finger" body2="xarm_gripper_base_link" />
      <exclude body1="left_inner_knuckle" body2="left_outer_knuckle" />
      <exclude body1="left_inner_knuckle" body2="link4" />
      <exclude body1="left_inner_knuckle" body2="link5" />
      <exclude body1="left_inner_knuckle" body2="link6" />
      <exclude body1="left_inner_knuckle" body2="right_finger" />
      <exclude body1="left_inner_knuckle" body2="right_inner_knuckle" />
      <exclude body1="left_inner_knuckle" body2="right_outer_knuckle" />
      <exclude body1="left_inner_knuckle" body2="xarm_gripper_base_link" />
      <exclude body1="left_outer_knuckle" body2="link5" />
      <exclude body1="left_outer_knuckle" body2="link6" />
      <exclude body1="left_outer_knuckle" body2="right_finger" />
      <exclude body1="left_outer_knuckle" body2="right_inner_knuckle" />
      <exclude body1="left_outer_knuckle" body2="right_outer_knuckle" />
      <exclude body1="left_outer_knuckle" body2="xarm_gripper_base_link" />

      <exclude body1="link4" body2="right_finger" />
      <exclude body1="link4" body2="right_inner_knuckle" />
      <exclude body1="link5" body2="link6" />
      <exclude body1="link5" body2="right_finger" />
      <exclude body1="link5" body2="right_inner_knuckle" />
      <exclude body1="link5" body2="right_outer_knuckle" />
      <exclude body1="link5" body2="xarm_gripper_base_link" />
      <exclude body1="link6" body2="right_finger" />
      <exclude body1="link6" body2="right_inner_knuckle" />
      <exclude body1="link6" body2="right_outer_knuckle" />
      <exclude body1="link6" body2="xarm_gripper_base_link" />
      <exclude body1="right_finger" body2="right_inner_knuckle" />
      <exclude body1="right_finger" body2="right_outer_knuckle" />
      <exclude body1="right_finger" body2="xarm_gripper_base_link" />
      <exclude body1="right_inner_knuckle" body2="right_outer_knuckle" />
      <exclude body1="right_inner_knuckle" body2="xarm_gripper_base_link" />
      <exclude body1="right_outer_knuckle" body2="xarm_gripper_base_link" />

      <exclude body1="link_eef" body2="left_finger" />
      <exclude body1="link_eef" body2="left_inner_knuckle" />
      <exclude body1="link_eef" body2="left_outer_knuckle" />
      <exclude body1="link_eef" body2="right_finger" />
      <exclude body1="link_eef" body2="right_inner_knuckle" />
      <exclude body1="link_eef" body2="right_outer_knuckle" />
      <exclude body1="link_eef" body2="xarm_gripper_base_link" />
  </contact>
</mujoco>
