<?xml version="1.0" ?>
<!-- =================================================================================== -->
<!-- |    This document was autogenerated by xacro from teleop_table_7dof.urdf.xacro   | -->
<!-- |    EDITING THIS FILE BY HAND IS NOT RECOMMENDED                                 | -->
<!-- =================================================================================== -->
<robot name="teleop_table">
    <mujoco>
       <compiler angle="radian" meshdir="../../" autolimits="true" strippath="false" fusestatic="false"/>
    </mujoco>
  <!-- PAPRAS URDF Macros -->
  <!-- Main URDF File should contain:
        - world link
        - world-env joint
        - env link
        - env-robotn/link1 joint for each mount -->
  <!-- This file contains URDF geometry, transmission data and Gazebo references -->
  <material name="black">
    <color rgba="0.0 0.0 0.0 1.0"/>
  </material>
  <material name="blue">
    <color rgba="0.0 0.0 0.8 1.0"/>
  </material>
  <material name="green">
    <color rgba="0.0 0.8 0.0 1.0"/>
  </material>
  <material name="grey">
    <color rgba="0.5 0.5 0.5 1.0"/>
  </material>
  <material name="orange">
    <color rgba="1.0 0.4235294117647059 0.0392156862745098 1.0"/>
  </material>
  <material name="brown">
    <color rgba="0.8705882352941177 0.8117647058823529 0.7647058823529411 1.0"/>
  </material>
  <material name="red">
    <color rgba="0.8 0.0 0.0 1.0"/>
  </material>
  <material name="white">
    <color rgba="1.0 1.0 1.0 1.0"/>
  </material>
  <!-- Import all Gazebo-customization elements, including Gazebo colors -->
  <!-- World -->
  <gazebo reference="world"/>
  <!-- Evn Link -->
  <gazebo reference="env"/>
  <!-- ros_control plugin -->
  <gazebo>
    <plugin filename="libgazebo_ros_control.so" name="gazebo_ros_control">
      <robotSimType>gazebo_ros_control/DefaultRobotHWSim</robotSimType>
    </plugin>
  </gazebo>
  <link name="world"/>
  <joint name="world_env_fixed" type="fixed">
    <parent link="world"/>
    <child link="env"/>
    <origin rpy="0 0 3.14" xyz="0 0 0"/>
  </joint>
  <link name="env">
    <inertial>
      <origin rpy="0 0 0" xyz="-0.00217818989969598 0.0115130557907703 4.82152969644036E-05"/>
      <mass value="24.3199996241188"/>
      <inertia ixx="2.59730961995013" ixy="1.29430820761003E-05" ixz="9.65770339797831E-10" iyy="3.22235223758385" iyz="-6.72646520780374E-05" izz="0.632617930010872"/>
    </inertial>
    <visual>
      <origin rpy="0 0 0" xyz="0 0 0"/>
      <geometry>
        <mesh filename="assets/leaders/table.stl"/>
      </geometry>
      <material name="">
        <color rgba="0.501960784313725 0.501960784313725 0.501960784313725 1"/>
      </material>
    </visual>
    <collision>
      <origin rpy="0 0 0" xyz="0 0 0"/>
      <geometry>
        <mesh filename="assets/leaders/table.stl"/>
      </geometry>
    </collision>
  </link>
  <joint name="robot3/env_joint" type="fixed">
    <origin rpy="0 0 0" xyz="-0.2599 0.50565 -0.0518900000000005"/>
    <parent link="env"/>
    <child link="robot3/link1"/>
    <axis xyz="0 0 0"/>
  </joint>
  <joint name="robot4/env_joint" type="fixed">
    <origin rpy="0 0 0" xyz="-0.2599 -0.50535 -0.0518900000000004"/>
    <parent link="env"/>
    <child link="robot4/link1"/>
    <axis xyz="0 0 0"/>
  </joint>
  <!-- link 1 -->
  <link name="robot3/link1">
    <visual>
      <origin rpy="0 0 0" xyz="0 0 0"/>
      <geometry>
        <mesh filename="assets/papras/link1.stl" scale="0.001 0.001 0.001"/>
      </geometry>
      <material name="grey"/>
    </visual>
    <collision>
      <origin rpy="0 0 0" xyz="0 0 0"/>
      <geometry>
        <mesh filename="assets/papras/link1.stl" scale="0.001 0.001 0.001"/>
      </geometry>
    </collision>
    <inertial>
      <origin rpy="0 0 0" xyz="0.00023 0.00000 0.06223"/>
      <mass value="0.85644"/>
      <!-- <inertia ixx="1.0" ixy="0.0" ixz="0.0" iyy="1.0" iyz="0.0" izz="1.0" /> -->
      <inertia ixx="0.00121064" ixy="0.0" ixz="0.00001100" iyy="0.00120886" iyz="0.0" izz="0.00038103"/>
    </inertial>
  </link>
  <gazebo reference="robot3/link1">
    <kp>1000000.0</kp>
    <kd>100.0</kd>
    <mu1>30.0</mu1>
    <mu2>30.0</mu2>
    <maxVel>1.0</maxVel>
    <minDepth>0.001</minDepth>
    <material>Gazebo/White</material>
    <selfCollide>1</selfCollide>
    <dampingFactor>0.01</dampingFactor>
  </gazebo>
  <!-- Joint 1 -->
  <joint name="robot3/joint1" type="revolute">
    <parent link="robot3/link1"/>
    <child link="robot3/link2"/>
    <origin rpy="0 0 0" xyz="0.0 0.0 0.126"/>
    <axis xyz="0 0 1"/>
    <limit effort="100" lower="-3.141592653589793" upper="3.141592653589793" velocity="3.03687"/>
    <dynamics damping="0.7"/>
  </joint>
  <transmission name="robot3/tran1">
    <type>transmission_interface/SimpleTransmission</type>
    <joint name="robot3/joint1">
      <hardwareInterface>hardware_interface/PositionJointInterface</hardwareInterface>
    </joint>
    <actuator name="robot3/motor1">
      <mechanicalReduction>1</mechanicalReduction>
    </actuator>
  </transmission>
  <!-- link 2 -->
  <link name="robot3/link2">
    <visual>
      <origin rpy="0 0 0" xyz="0 0 0"/>
      <geometry>
        <mesh filename="assets/papras/link2.stl" scale="0.001 0.001 0.001"/>
      </geometry>
      <material name="grey"/>
    </visual>
    <collision>
      <origin rpy="0 0 0" xyz="0 0 0"/>
      <geometry>
        <mesh filename="assets/papras/link2.stl" scale="0.001 0.001 0.001"/>
      </geometry>
    </collision>
    <inertial>
      <origin rpy="0 0 0" xyz="0.00000 0.00080 0.03183"/>
      <!--<origin xyz="0.00000 -0.06820 -0.00117" rpy="0 0 0"/>-->
      <mass value="0.94658"/>
      <inertia ixx="1.0" ixy="0.0" ixz="0.0" iyy="1.0" iyz="0.0" izz="1.0"/>
      <!--<inertia ixx="0.00152547" ixy="0.0" ixz="0.0" iyy="0.00045954" iyz="-0.00001086" izz="0.00151740" />-->
    </inertial>
  </link>
  <gazebo reference="robot3/link2">
    <kp>1000000.0</kp>
    <kd>100.0</kd>
    <mu1>30.0</mu1>
    <mu2>30.0</mu2>
    <maxVel>1.0</maxVel>
    <minDepth>0.001</minDepth>
    <material>Gazebo/White</material>
    <selfCollide>1</selfCollide>
    <dampingFactor>0.01</dampingFactor>
  </gazebo>
  <!-- Joint 2 -->
  <joint name="robot3/joint2" type="revolute">
    <parent link="robot3/link2"/>
    <child link="robot3/link3"/>
    <origin rpy="1.5707963267948966 -1.5707963267948966 0" xyz="0.0 0.00 0.033"/>
    <axis xyz="0 0 1"/>
    <limit effort="100" lower="-2.0" upper="2.0" velocity="3.03687"/>
    <dynamics damping="0.7"/>
  </joint>
  <transmission name="robot3/tran2">
    <type>transmission_interface/SimpleTransmission</type>
    <joint name="robot3/joint2">
      <hardwareInterface>hardware_interface/PositionJointInterface</hardwareInterface>
    </joint>
    <actuator name="robot3/motor2">
      <mechanicalReduction>1</mechanicalReduction>
    </actuator>
  </transmission>
  <!-- link 2 -->
  <link name="robot3/link3">
    <visual>
      <origin rpy="0 0 0" xyz="0.0 0.0 0.0"/>
      <geometry>
        <mesh filename="assets/papras/7dof/link3.stl"/>
      </geometry>
      <material name="grey"/>
    </visual>
    <collision>
      <origin rpy="0 0 0" xyz="0 0 0"/>
      <geometry>
        <mesh filename="assets/papras/7dof/link3.stl"/>
      </geometry>
    </collision>
    <inertial>
      <origin rpy="0 0 0" xyz="0.00000 0.00080 0.03183"/>
      <!--<origin xyz="0.00000 -0.06820 -0.00117" rpy="0 0 0"/>-->
      <mass value="0.49982"/>
      <!-- <inertia ixx="1.0" ixy="0.0" ixz="0.0" iyy="1.0" iyz="0.0" izz="1.0" /> -->
      <inertia ixx="0.00078817" ixy="6.3729E-09" ixz="-1.0998E-05" iyy="0.0012133" iyz="-7.0637E-09" izz="0.00073746"/>
    </inertial>
  </link>
  <gazebo reference="robot3/link3">
    <kp>1000000.0</kp>
    <kd>100.0</kd>
    <mu1>30.0</mu1>
    <mu2>30.0</mu2>
    <maxVel>1.0</maxVel>
    <minDepth>0.001</minDepth>
    <material>Gazebo/White</material>
    <selfCollide>1</selfCollide>
    <dampingFactor>0.01</dampingFactor>
  </gazebo>
  <!-- Joint 2 -->
  <joint name="robot3/joint3" type="revolute">
    <parent link="robot3/link3"/>
    <child link="robot3/link4"/>
    <origin rpy="0 -1.5707963267948966 -1.5707963267948966" xyz="0.156382198147594 0 0.000400000000010851"/>
    <axis xyz="0 1 0"/>
    <limit effort="100" lower="-3.141592653589793" upper="3.141592653589793" velocity="3.03687"/>
    <dynamics damping="0.7"/>
  </joint>
  <transmission name="robot3/tran3">
    <type>transmission_interface/SimpleTransmission</type>
    <joint name="robot3/joint3">
      <hardwareInterface>hardware_interface/PositionJointInterface</hardwareInterface>
    </joint>
    <actuator name="robot3/motor3">
      <mechanicalReduction>1</mechanicalReduction>
    </actuator>
  </transmission>
  <!-- link 2 -->
  <link name="robot3/link4">
    <visual>
      <origin rpy="0 0 0" xyz="0.0 0.0 0.0"/>
      <geometry>
        <mesh filename="assets/papras/7dof/link4.stl"/>
      </geometry>
      <material name="grey"/>
    </visual>
    <collision>
      <origin rpy="0 0 0" xyz="0 0 0"/>
      <geometry>
        <mesh filename="assets/papras/7dof/link4.stl"/>
      </geometry>
    </collision>
    <inertial>
      <origin rpy="0 0 0" xyz="-4.86609203880829E-06 0.120506252053841 -0.0279123104678896"/>
      <mass value="0.597399042150493"/>
      <!-- <inertia ixx="1.0" ixy="0.0" ixz="0.0" iyy="1.0" iyz="0.0" izz="1.0" /> -->
      <inertia ixx="0.0015528567154149" ixy="1.16567414120262E-05" ixz="-2.90009974781987E-06" iyy="0.00077263780701987" iyz="9.95380938833158E-05" izz="0.0018580466481516"/>
    </inertial>
  </link>
  <gazebo reference="robot3/link4">
    <kp>1000000.0</kp>
    <kd>100.0</kd>
    <mu1>30.0</mu1>
    <mu2>30.0</mu2>
    <maxVel>1.0</maxVel>
    <minDepth>0.001</minDepth>
    <material>Gazebo/White</material>
    <selfCollide>1</selfCollide>
    <dampingFactor>0.01</dampingFactor>
  </gazebo>
  <!-- Joint 3 -->
  <joint name="robot3/joint4" type="revolute">
    <parent link="robot3/link4"/>
    <child link="robot3/link5"/>
    <origin rpy="3.141592653589793 -1.5707963267948966 1.5707963267948966" xyz="0.0575 0.10761780185239 0.0300000000000553"/>
    <axis xyz="0 1 0"/>
    <limit effort="100" lower="-3.141592653589793" upper="1.42" velocity="3.03687"/>
    <dynamics damping="0.7"/>
  </joint>
  <transmission name="robot3/tran4">
    <type>transmission_interface/SimpleTransmission</type>
    <joint name="robot3/joint4">
      <hardwareInterface>hardware_interface/PositionJointInterface</hardwareInterface>
    </joint>
    <actuator name="robot3/motor4">
      <mechanicalReduction>1</mechanicalReduction>
    </actuator>
  </transmission>
  <!-- link 5 -->
  <link name="robot3/link5">
    <visual>
      <origin rpy="0 0 3.14" xyz="0.227 0.0085 -0.024"/>
      <geometry>
        <mesh filename="assets/papras/link4_papras.stl" scale="0.001 0.001 0.001"/>
      </geometry>
      <material name="grey"/>
    </visual>
    <collision>
      <origin rpy="0 0 3.14" xyz="0.227 0.0085 -0.024"/>
      <geometry>
        <mesh filename="assets/papras/link4_papras_simple.stl" scale="0.001 0.001 0.001"/>
      </geometry>
    </collision>
    <inertial>
      <origin rpy="0 0 0" xyz="0.12475 -0.05716 0.02979"/>
      <!--<origin xyz="-0.07025 0.00034 -0.00021" rpy="0 0 0"/>-->
      <mass value="1.15977"/>
      <inertia ixx="1.0" ixy="0.0" ixz="0.0" iyy="1.0" iyz="0.0" izz="1.0"/>
      <!--<inertia ixx="0.00096726" ixy="0.00004383" ixz="-0.00002771" iyy="0.00318801" iyz="0.00000627" izz="0.00341484" />-->
    </inertial>
  </link>
  <gazebo reference="robot3/link5">
    <kp>1000000.0</kp>
    <kd>100.0</kd>
    <mu1>30.0</mu1>
    <mu2>30.0</mu2>
    <maxVel>1.0</maxVel>
    <minDepth>0.001</minDepth>
    <material>Gazebo/White</material>
    <selfCollide>1</selfCollide>
    <dampingFactor>0.01</dampingFactor>
  </gazebo>
  <!-- Joint 4 -->
  <joint name="robot3/joint5" type="revolute">
    <parent link="robot3/link5"/>
    <child link="robot3/link6"/>
    <origin rpy="0 0 0" xyz="0.19500 -0.05750 0.03000"/>
    <axis xyz="1 0 0"/>
    <limit effort="100" lower="-2.748893571891069" upper="2.748893571891069" velocity="3.03687"/>
    <dynamics damping="0.7"/>
  </joint>
  <transmission name="robot3/tran5">
    <type>transmission_interface/SimpleTransmission</type>
    <joint name="robot3/joint5">
      <hardwareInterface>hardware_interface/PositionJointInterface</hardwareInterface>
    </joint>
    <actuator name="robot3/motor5">
      <mechanicalReduction>1</mechanicalReduction>
    </actuator>
  </transmission>
  <!-- link 6 -->
  <link name="robot3/link6">
    <visual>
      <origin rpy="0 0 0" xyz="0 0 0"/>
      <geometry>
        <mesh filename="assets/papras/link5.stl" scale="0.001 0.001 0.001"/>
      </geometry>
      <material name="grey"/>
    </visual>
    <collision>
      <origin rpy="0 0 0" xyz="0 0 0"/>
      <geometry>
        <mesh filename="assets/papras/link5.stl" scale="0.001 0.001 0.001"/>
      </geometry>
    </collision>
    <inertial>
      <origin rpy="0 0 0" xyz="0.05642 -0.00217 0.00002"/>
      <!--<origin xyz="-0.00658 -0.04717 0.00002" rpy="0 0 0"/>-->
      <mass value="0.44688"/>
      <inertia ixx="1.0" ixy="0.0" ixz="0.0" iyy="1.0" iyz="0.0" izz="1.0"/>
      <!--<inertia ixx="0.00030285" ixy="0.00000761" ixz="0.00000031" iyy="0.00022339" iyz="-0.00000001" izz="0.00039766" />-->
    </inertial>
  </link>
  <gazebo reference="robot3/link6">
    <kp>1000000.0</kp>
    <kd>100.0</kd>
    <mu1>30.0</mu1>
    <mu2>30.0</mu2>
    <maxVel>1.0</maxVel>
    <minDepth>0.001</minDepth>
    <material>Gazebo/White</material>
    <selfCollide>1</selfCollide>
    <dampingFactor>0.01</dampingFactor>
  </gazebo>
  <!-- Joint 6 -->
  <joint name="robot3/joint6" type="revolute">
    <parent link="robot3/link6"/>
    <child link="robot3/link7"/>
    <origin rpy="0 0 0" xyz="0.06300 0.04500 0.00000"/>
    <axis xyz="0 1 0"/>
    <limit effort="100" lower="-1.5707963267948966" upper="1.5707963267948966" velocity="3.03687"/>
    <dynamics damping="0.7"/>
  </joint>
  <transmission name="robot3/tran6">
    <type>transmission_interface/SimpleTransmission</type>
    <joint name="robot3/joint6">
      <hardwareInterface>hardware_interface/PositionJointInterface</hardwareInterface>
    </joint>
    <actuator name="robot3/motor6">
      <mechanicalReduction>1</mechanicalReduction>
    </actuator>
  </transmission>
  <!-- link 6 -->
  <link name="robot3/link7">
    <visual>
      <origin rpy="0 0 0" xyz="-0.034 -0.098 -0.028"/>
      <geometry>
        <mesh filename="assets/papras/link6_papras.stl" scale="0.001 0.001 0.001"/>
      </geometry>
      <material name="grey"/>
    </visual>
    <collision>
      <origin rpy="0 0 0" xyz="-0.034 -0.098 -0.028"/>
      <geometry>
        <mesh filename="assets/papras/link6_papras_simple.stl" scale="0.001 0.001 0.001"/>
      </geometry>
    </collision>
    <inertial>
      <origin rpy="0 0 0" xyz="0.06831 -0.04457 0.00000"/>
      <!--<origin xyz="-0.05469 0.00043 0.00000" rpy="0 0 0"/>-->
      <mass value="0.43273"/>
      <inertia ixx="1.0" ixy="0.0" ixz="0.0" iyy="1.0" iyz="0.0" izz="1.0"/>
      <!--<inertia ixx="0.00021512" ixy="0.00001009" ixz="0.00000000" iyy="0.00042827" iyz="0.00000000" izz="0.00051436" />-->
    </inertial>
  </link>
  <gazebo reference="robot3/link7">
    <kp>1000000.0</kp>
    <kd>100.0</kd>
    <mu1>30.0</mu1>
    <mu2>30.0</mu2>
    <maxVel>1.0</maxVel>
    <minDepth>0.001</minDepth>
    <material>Gazebo/White</material>
    <selfCollide>1</selfCollide>
    <dampingFactor>0.01</dampingFactor>
  </gazebo>
  <!-- Joint 7 -->
  <joint name="robot3/joint7" type="revolute">
    <parent link="robot3/link7"/>
    <child link="robot3/end_link"/>
    <origin rpy="0 0 0" xyz="0.12300 -0.04500 0.00000"/>
    <axis xyz="1 0 0"/>
    <limit effort="100" lower="-3.141592653589793" upper="3.141592653589793" velocity="3.03687"/>
    <dynamics damping="0.7"/>
  </joint>
  <transmission name="robot3/tran7">
    <type>transmission_interface/SimpleTransmission</type>
    <joint name="robot3/joint7">
      <hardwareInterface>hardware_interface/PositionJointInterface</hardwareInterface>
    </joint>
    <actuator name="robot3/motor7">
      <mechanicalReduction>1</mechanicalReduction>
    </actuator>
  </transmission>
  <!-- end link -->
  <link name="robot3/end_link">
    <visual>
      <origin rpy="0 0 0" xyz="0.0 0.0 0.0"/>
      <geometry>
        <mesh filename="assets/papras/end_link.stl" scale="0.001 0.001 0.001"/>
      </geometry>
      <material name="grey"/>
    </visual>
    <collision>
      <origin rpy="0 0 0" xyz="0.0 0.0 0.0"/>
      <geometry>
        <mesh filename="assets/papras/end_link.stl" scale="0.001 0.001 0.001"/>
      </geometry>
    </collision>
    <inertial>
      <origin rpy="0 0 0" xyz="0.00337 0.00000 0.00000"/>
      <mass value="0.01919"/>
      <inertia ixx="1.0" ixy="0.0" ixz="0.0" iyy="1.0" iyz="0.0" izz="1.0"/>
      <!--<inertia ixx="0.00000938" ixy="0.0" ixz="0.0" iyy="0.00000338" iyz="0.0" izz="0.00000635" />-->
    </inertial>
  </link>
  
  <gazebo reference="robot3/end_link">
    <kp>1000000.0</kp>
    <kd>100.0</kd>
    <mu1>30.0</mu1>
    <mu2>30.0</mu2>
    <maxVel>1.0</maxVel>
    <minDepth>0.001</minDepth>
    <material>Gazebo/White</material>
    <selfCollide>1</selfCollide>
    <dampingFactor>0.01</dampingFactor>
  </gazebo>
  <link name="robot3/wrist_link">
  </link>
  <joint name="robot3/wrist_joint" type="fixed">
    <parent link="robot3/end_link"/>
    <child link="robot3/wrist_link"/>
    <origin rpy="0 0 0" xyz="0.006 0.0 0.0"/>
  </joint>
  <!-- gripper main fixed joint-->
  <joint name="robot3/end_link_fixed" type="fixed">
    <parent link="robot3/end_link"/>
    <child link="robot3/gripper_main_link"/>
    <origin rpy="0 -1.5707963267948966 3.141592653589793" xyz="0.006 0.0 0.0"/>
  </joint>
  <!-- gripper main link -->
   <!-- gripper main link -->
    <link name="robot3/gripper_main_link">
    <collision>
      <origin rpy="0 0 0" xyz="0 0 0"/>
      <geometry>
        <mesh filename="assets/robotis_hand_rh-p12-rn/rh_p12_rn_base.stl" scale="0.001 0.001 0.001"/>
      </geometry>
    </collision>
    <visual>
      <origin rpy="0 0 0" xyz="0 0 0"/>
      <geometry>
        <mesh filename="assets/robotis_hand_rh-p12-rn/rh_p12_rn_base.stl" scale="0.001 0.001 0.001"/>
      </geometry>
      <material name="grey"/>
    </visual>
    <inertial>
      <origin rpy="0 0 0" xyz="0.000 0.000 0.032"/>
      <mass value="0.236"/>
      <!--<inertia ixx="0.00017" ixy="0.0" ixz="0.0" iyy="0.00011" iyz="0.0" izz="0.00017" />-->
      <inertia ixx="1.0" ixy="0.0" ixz="0.0" iyy="1.0" iyz="0.0" izz="1.0"/>
    </inertial>
  </link>
  <gazebo reference="robot3/gripper_main_link">
    <kp>1000000.0</kp>
    <kd>100.0</kd>
    <mu1>30.0</mu1>
    <mu2>30.0</mu2>
    <maxVel>1.0</maxVel>
    <minDepth>0.001</minDepth>
    <material>Gazebo/White</material>
    <selfCollide>1</selfCollide>
    <dampingFactor>0.01</dampingFactor>
  </gazebo>
  <!-- gripper joint -->
  <joint name="robot3/gripper" type="revolute">
    <parent link="robot3/gripper_main_link"/>
    <child link="robot3/gripper_link"/>
    <origin rpy="0 0 0" xyz="0.0 0.008 0.048"/>
    <axis xyz="1 0 0"/>
    <limit effort="1000" lower="0.0" upper="1.1" velocity="6.5"/>
    <dynamics damping="0.7"/>
  </joint>
  <transmission name="robot3/trangripper">
    <type>transmission_interface/SimpleTransmission</type>
    <joint name="robot3/gripper">
      <hardwareInterface>hardware_interface/EffortJointInterface</hardwareInterface>
    </joint>
    <actuator name="robot3/motorgripper">
      <mechanicalReduction>1</mechanicalReduction>
    </actuator>
  </transmission>
  <!-- gripper link -->
  <link name="robot3/gripper_link">
    <collision>
      <origin rpy="0 0 0" xyz="0 0 0"/>
      <geometry>
        <mesh filename="assets/robotis_hand_rh-p12-rn/rh_p12_rn_r1.stl" scale="0.001 0.001 0.001"/>
      </geometry>
    </collision>
    <visual>
      <origin rpy="0 0 0" xyz="0 0 0"/>
      <geometry>
        <mesh filename="assets/robotis_hand_rh-p12-rn/rh_p12_rn_r1.stl" scale="0.001 0.001 0.001"/>
      </geometry>
      <material name="grey"/>
    </visual>
    <inertial>
      <origin rpy="0 0 0" xyz="0.000 0.034 0.004"/>
      <mass value="0.068"/>
      <!--<inertia ixx="0.00004" ixy="0.0" ixz="0.0" iyy="0.00002" iyz="-0.00001" izz="0.00002" />-->
      <inertia ixx="1.0" ixy="0.0" ixz="0.0" iyy="1.0" iyz="0.0" izz="1.0"/>
    </inertial>
  </link>
  <gazebo reference="robot3/gripper_link">
    <kp>1000000.0</kp>
    <kd>100.0</kd>
    <mu1>30.0</mu1>
    <mu2>30.0</mu2>
    <maxVel>1.0</maxVel>
    <minDepth>0.001</minDepth>
    <material>Gazebo/White</material>
    <selfCollide>1</selfCollide>
    <dampingFactor>0.01</dampingFactor>
  </gazebo>
  <joint name="robot3/gripper_r2" type="revolute">
    <parent link="robot3/gripper_link"/>
    <child link="robot3/gripper_link_r2"/>
    <origin rpy="0 0 0" xyz="0.0 0.0493634 0.0285"/>
    <axis xyz="-1 0 0"/>
    <limit effort="1000" lower="0.0" upper="1.0" velocity="6.5"/>
    <dynamics damping="0.7"/>
    <mimic joint="robot3/gripper" multiplier="0.9090909090909091"/>
  </joint>
  <transmission name="robot3/trangripper_r2">
    <type>transmission_interface/SimpleTransmission</type>
    <joint name="robot3/gripper_r2">
      <hardwareInterface>hardware_interface/EffortJointInterface</hardwareInterface>
    </joint>
    <actuator name="robot3/motorgripper_r2">
      <mechanicalReduction>1</mechanicalReduction>
    </actuator>
  </transmission>
  <!-- rh_p12_rn_r2 -->
  <link name="robot3/gripper_link_r2">
    <collision>
      <origin rpy="0 0 0" xyz="0 0 0"/>
      <geometry>
        <mesh filename="assets/robotis_hand_rh-p12-rn/rh_p12_rn_r2.stl" scale="0.001 0.001 0.001"/>
      </geometry>
    </collision>
    <visual>
      <origin rpy="0 0 0" xyz="0 0 0"/>
      <geometry>
        <mesh filename="assets/robotis_hand_rh-p12-rn/rh_p12_rn_r2.stl" scale="0.001 0.001 0.001"/>
      </geometry>
      <material name="grey"/>
    </visual>
    <inertial>
      <origin rpy="0 0 0" xyz="0.000 0.006 0.011"/>
      <mass value="0.022"/>
      <!--<inertia ixx="0.0" ixy="0.0" ixz="0.0" iyy="0.00001" iyz="0.0" izz="0.0" />-->
      <inertia ixx="1.0" ixy="0.0" ixz="0.0" iyy="1.0" iyz="0.0" izz="1.0"/>
    </inertial>
  </link>
  <gazebo reference="robot3/gripper_link_r2">
    <kp>1000000.0</kp>
    <kd>100.0</kd>
    <mu1>30.0</mu1>
    <mu2>30.0</mu2>
    <maxVel>1.0</maxVel>
    <minDepth>0.001</minDepth>
    <material>Gazebo/White</material>
    <selfCollide>1</selfCollide>
    <dampingFactor>0.01</dampingFactor>
  </gazebo>
  <!-- Left Joint 1 -->
  <joint name="robot3/gripper_l1" type="revolute">
    <parent link="robot3/gripper_main_link"/>
    <child link="robot3/gripper_link_l1"/>
    <origin rpy="0 0 0" xyz="0.0 -0.008 0.048"/>
    <axis xyz="-1 0 0"/>
    <limit effort="1000" lower="0.0" upper="1.1" velocity="6.5"/>
    <dynamics damping="0.7"/>
    <mimic joint="robot3/gripper" multiplier="1.0"/>
  </joint>
  <transmission name="robot3/trangripper_l1">
    <type>transmission_interface/SimpleTransmission</type>
    <joint name="robot3/gripper_l1">
      <hardwareInterface>hardware_interface/EffortJointInterface</hardwareInterface>
    </joint>
    <actuator name="robot3/motorgripper_l1">
      <mechanicalReduction>1</mechanicalReduction>
    </actuator>
  </transmission>
  <!-- rh_p12_rn_l1 -->
  <link name="robot3/gripper_link_l1">
    <collision>
      <origin rpy="0 0 0" xyz="0 0 0"/>
      <geometry>
        <mesh filename="assets/robotis_hand_rh-p12-rn/rh_p12_rn_l1.stl" scale="0.001 0.001 0.001"/>
      </geometry>
    </collision>
    <visual>
      <origin rpy="0 0 0" xyz="0 0 0"/>
      <geometry>
        <mesh filename="assets/robotis_hand_rh-p12-rn/rh_p12_rn_l1.stl" scale="0.001 0.001 0.001"/>
      </geometry>
      <material name="grey"/>
    </visual>
    <inertial>
      <origin rpy="0 0 0" xyz="0.000 -0.034 0.004"/>
      <mass value="0.068"/>
      <!--<inertia ixx="0.00004" ixy="0.0" ixz="0.0" iyy="0.00002" iyz="0.00001" izz="0.00002" />-->
      <inertia ixx="1.0" ixy="0.0" ixz="0.0" iyy="1.0" iyz="0.0" izz="1.0"/>
    </inertial>
  </link>
  <gazebo reference="robot3/gripper_link_l1">
    <kp>1000000.0</kp>
    <kd>100.0</kd>
    <mu1>30.0</mu1>
    <mu2>30.0</mu2>
    <maxVel>1.0</maxVel>
    <minDepth>0.001</minDepth>
    <material>Gazebo/White</material>
    <selfCollide>1</selfCollide>
    <dampingFactor>0.01</dampingFactor>
  </gazebo>
  <!-- Left Joint 2 -->
  <joint name="robot3/gripper_l2" type="revolute">
    <parent link="robot3/gripper_link_l1"/>
    <child link="robot3/gripper_link_l2"/>
    <origin rpy="0 0 0" xyz="0.0 -0.0493634 0.0285"/>
    <axis xyz="1 0 0"/>
    <limit effort="1000" lower="0.0" upper="1.0" velocity="6.5"/>
    <dynamics damping="0.7"/>
    <mimic joint="robot3/gripper" multiplier="0.9090909090909091"/>
  </joint>
  <transmission name="robot3/trangripper_l2">
    <type>transmission_interface/SimpleTransmission</type>
    <joint name="robot3/gripper_l2">
      <hardwareInterface>hardware_interface/EffortJointInterface</hardwareInterface>
    </joint>
    <actuator name="robot3/motorgripper_l2">
      <mechanicalReduction>1</mechanicalReduction>
    </actuator>
  </transmission>
  <link name="robot3/gripper_link_l2">
    <collision>
      <origin rpy="0 0 0" xyz="0 0 0"/>
      <geometry>
        <mesh filename="assets/robotis_hand_rh-p12-rn/rh_p12_rn_l2.stl" scale="0.001 0.001 0.001"/>
      </geometry>
    </collision>
    <visual>
      <origin rpy="0 0 0" xyz="0 0 0"/>
      <geometry>
        <mesh filename="assets/robotis_hand_rh-p12-rn/rh_p12_rn_l2.stl" scale="0.001 0.001 0.001"/>
      </geometry>
      <material name="grey"/>
    </visual>
    <inertial>
      <origin rpy="0 0 0" xyz="0.000 -0.006 0.011"/>
      <mass value="0.022"/>
      <!--<inertia ixx="0.0" ixy="0.0" ixz="0.0" iyy="0.00001" iyz="0.0" izz="0.0" />-->
      <inertia ixx="1.0" ixy="0.0" ixz="0.0" iyy="1.0" iyz="0.0" izz="1.0"/>
    </inertial>
  </link>
  <!-- gripper main fixed joint-->
  <joint name="robot3/end_effector_joint" type="fixed">
    <parent link="robot3/gripper_main_link"/>
    <child link="robot3/end_effector_link"/>
    <origin rpy="3.141592653589793 -1.5707963267948966 0" xyz="0.0 0.0 0.135"/>
  </joint>
  <!-- End Effector -->
  <link name="robot3/end_effector_link">
    <visual>
      <origin rpy="0 0 0" xyz="0.0 0.0 0.0"/>
      <geometry>
        <box size="0.01 0.01 0.01"/>
      </geometry>
      <material name="red"/>
    </visual>
    <!-- <collision>
        <origin xyz="0.0 0.0 0.0" rpy="0 0 0" />
        <geometry>
          <box size = "0.01 0.01 0.01"/>
        </geometry>
        <material name="red"/>
      </collision> -->
    <inertial>
      <origin rpy="0 0 0" xyz="0.0 0.0 0.0"/>
      <mass value="0.001"/>
      <inertia ixx="1.0" ixy="0.0" ixz="0.0" iyy="1.0" iyz="0.0" izz="1.0"/>
    </inertial>
  </link>
  <gazebo reference="robot3/end_effector_link">
    <material>Gazebo/Red</material>
  </gazebo>
  <gazebo>
    <!-- loading plugin: mimic joints works in gazebo now -->
    <plugin filename="libroboticsgroup_upatras_gazebo_mimic_joint_plugin.so" name="gazebo_gripper3_ros_control">
      <joint>robot3/gripper</joint>
      <mimicJoint>robot3/gripper_sub</mimicJoint>
      <multiplier>1.0</multiplier>
      <offset>0.0</offset>
    </plugin>
  </gazebo>

  <joint name="robot3/hand_joint" type="fixed">
    <parent link="robot3/gripper_main_link"/>
    <child link="robot3/hand_link"/>
    <origin rpy="3.141592653589793 -1.5707963267948966 0" xyz="0.0 0.0 0.10"/>
  </joint>
  <!-- End Effector -->
  <link name="robot3/hand_link">
  </link>

  <!-- camera link fixed joint -->
  <joint name="robot3/camera_fixed_joint" type="fixed">
    <parent link="robot3/gripper_main_link"/>
    <child link="robot3/camera_mount"/>
    <origin xyz="0.04452 -0.0167 0.049" rpy="0 0 1.5707963267948966" />
  </joint>
  <!-- Camera Mount -->
  <link name="robot3/camera_mount">
     <visual>
      <origin rpy="1.5707963267948966 -1.5707963267948966 0" xyz="0 0 0"/>
      <geometry>
        <mesh filename="assets/papras/camera_mount.stl"/>
      </geometry>
      <material name="grey"/>
    </visual>
    <collision>
      <origin rpy="1.5707963267948966 -1.5707963267948966 0" xyz="0 0 0"/>
      <geometry>
        <mesh filename="assets/papras/camera_mount_simple.stl"/>
      </geometry>
    </collision>
    <inertial>
      <origin rpy="1.5707963267948966 -1.5707963267948966 0" xyz="0 0 0"/>
      <mass value="0.088"/>
      <inertia ixx="1.0" ixy="0.0" ixz="0.0" iyy="1.0" iyz="0.0" izz="1.0"/>
    </inertial>
  </link>
  <gazebo reference="robot3/camera_mount">
    <kp>1000000.0</kp>
    <kd>100.0</kd>
    <mu1>30.0</mu1>
    <mu2>30.0</mu2>
    <maxVel>1.0</maxVel>
    <minDepth>0.001</minDepth>
    <material>Gazebo/White</material>
    <selfCollide>1</selfCollide>
    <dampingFactor>0.01</dampingFactor>
  </gazebo>

  <joint name="robot3/camera_fixed_plugin_joint" type="fixed">
    <parent link="robot3/camera_mount"/>
    <child link="robot3/camera_plugin_link"/>
    <origin rpy="1.5707963267948966 -1.5707963267948966 0" xyz="0 0 0"/>
  </joint>
  <link name="robot3/camera_plugin_link"/>
  <!-- link 1 -->
  <link name="robot4/link1">
    <visual>
      <origin rpy="0 0 0" xyz="0 0 0"/>
      <geometry>
        <mesh filename="assets/papras/link1.stl" scale="0.001 0.001 0.001"/>
      </geometry>
      <material name="grey"/>
    </visual>
    <collision>
      <origin rpy="0 0 0" xyz="0 0 0"/>
      <geometry>
        <mesh filename="assets/papras/link1.stl" scale="0.001 0.001 0.001"/>
      </geometry>
    </collision>
    <inertial>
      <origin rpy="0 0 0" xyz="0.00023 0.00000 0.06223"/>
      <mass value="0.85644"/>
      <!-- <inertia ixx="1.0" ixy="0.0" ixz="0.0" iyy="1.0" iyz="0.0" izz="1.0" /> -->
      <inertia ixx="0.00121064" ixy="0.0" ixz="0.00001100" iyy="0.00120886" iyz="0.0" izz="0.00038103"/>
    </inertial>
  </link>
  <gazebo reference="robot4/link1">
    <kp>1000000.0</kp>
    <kd>100.0</kd>
    <mu1>30.0</mu1>
    <mu2>30.0</mu2>
    <maxVel>1.0</maxVel>
    <minDepth>0.001</minDepth>
    <material>Gazebo/White</material>
    <selfCollide>1</selfCollide>
    <dampingFactor>0.01</dampingFactor>
  </gazebo>
  <!-- Joint 1 -->
  <joint name="robot4/joint1" type="revolute">
    <parent link="robot4/link1"/>
    <child link="robot4/link2"/>
    <origin rpy="0 0 0" xyz="0.0 0.0 0.126"/>
    <axis xyz="0 0 1"/>
    <limit effort="100" lower="-3.141592653589793" upper="3.141592653589793" velocity="3.03687"/>
    <dynamics damping="0.7"/>
  </joint>
  <transmission name="robot4/tran1">
    <type>transmission_interface/SimpleTransmission</type>
    <joint name="robot4/joint1">
      <hardwareInterface>hardware_interface/PositionJointInterface</hardwareInterface>
    </joint>
    <actuator name="robot4/motor1">
      <mechanicalReduction>1</mechanicalReduction>
    </actuator>
  </transmission>
  <!-- link 2 -->
  <link name="robot4/link2">
    <visual>
      <origin rpy="0 0 0" xyz="0 0 0"/>
      <geometry>
        <mesh filename="assets/papras/link2.stl" scale="0.001 0.001 0.001"/>
      </geometry>
      <material name="grey"/>
    </visual>
    <collision>
      <origin rpy="0 0 0" xyz="0 0 0"/>
      <geometry>
        <mesh filename="assets/papras/link2.stl" scale="0.001 0.001 0.001"/>
      </geometry>
    </collision>
    <inertial>
      <origin rpy="0 0 0" xyz="0.00000 0.00080 0.03183"/>
      <!--<origin xyz="0.00000 -0.06820 -0.00117" rpy="0 0 0"/>-->
      <mass value="0.94658"/>
      <inertia ixx="1.0" ixy="0.0" ixz="0.0" iyy="1.0" iyz="0.0" izz="1.0"/>
      <!--<inertia ixx="0.00152547" ixy="0.0" ixz="0.0" iyy="0.00045954" iyz="-0.00001086" izz="0.00151740" />-->
    </inertial>
  </link>
  <gazebo reference="robot4/link2">
    <kp>1000000.0</kp>
    <kd>100.0</kd>
    <mu1>30.0</mu1>
    <mu2>30.0</mu2>
    <maxVel>1.0</maxVel>
    <minDepth>0.001</minDepth>
    <material>Gazebo/White</material>
    <selfCollide>1</selfCollide>
    <dampingFactor>0.01</dampingFactor>
  </gazebo>
  <!-- Joint 2 -->
  <joint name="robot4/joint2" type="revolute">
    <parent link="robot4/link2"/>
    <child link="robot4/link3"/>
    <origin rpy="1.5707963267948966 -1.5707963267948966 0" xyz="0.0 0.00 0.033"/>
    <axis xyz="0 0 1"/>
    <limit effort="100" lower="-2.0" upper="2.0" velocity="3.03687"/>
    <dynamics damping="0.7"/>
  </joint>
  <transmission name="robot4/tran2">
    <type>transmission_interface/SimpleTransmission</type>
    <joint name="robot4/joint2">
      <hardwareInterface>hardware_interface/PositionJointInterface</hardwareInterface>
    </joint>
    <actuator name="robot4/motor2">
      <mechanicalReduction>1</mechanicalReduction>
    </actuator>
  </transmission>
  <!-- link 2 -->
  <link name="robot4/link3">
    <visual>
      <origin rpy="0 0 0" xyz="0.0 0.0 0.0"/>
      <geometry>
        <mesh filename="assets/papras/7dof/link3.stl"/>
      </geometry>
      <material name="grey"/>
    </visual>
    <collision>
      <origin rpy="0 0 0" xyz="0 0 0"/>
      <geometry>
        <mesh filename="assets/papras/7dof/link3.stl"/>
      </geometry>
    </collision>
    <inertial>
      <origin rpy="0 0 0" xyz="0.00000 0.00080 0.03183"/>
      <!--<origin xyz="0.00000 -0.06820 -0.00117" rpy="0 0 0"/>-->
      <mass value="0.49982"/>
      <!-- <inertia ixx="1.0" ixy="0.0" ixz="0.0" iyy="1.0" iyz="0.0" izz="1.0" /> -->
      <inertia ixx="0.00078817" ixy="6.3729E-09" ixz="-1.0998E-05" iyy="0.0012133" iyz="-7.0637E-09" izz="0.00073746"/>
    </inertial>
  </link>
  <gazebo reference="robot4/link3">
    <kp>1000000.0</kp>
    <kd>100.0</kd>
    <mu1>30.0</mu1>
    <mu2>30.0</mu2>
    <maxVel>1.0</maxVel>
    <minDepth>0.001</minDepth>
    <material>Gazebo/White</material>
    <selfCollide>1</selfCollide>
    <dampingFactor>0.01</dampingFactor>
  </gazebo>
  <!-- Joint 2 -->
  <joint name="robot4/joint3" type="revolute">
    <parent link="robot4/link3"/>
    <child link="robot4/link4"/>
    <origin rpy="0 -1.5707963267948966 -1.5707963267948966" xyz="0.156382198147594 0 0.000400000000010851"/>
    <axis xyz="0 1 0"/>
    <limit effort="100" lower="-3.141592653589793" upper="3.141592653589793" velocity="3.03687"/>
    <dynamics damping="0.7"/>
  </joint>
  <transmission name="robot4/tran3">
    <type>transmission_interface/SimpleTransmission</type>
    <joint name="robot4/joint3">
      <hardwareInterface>hardware_interface/PositionJointInterface</hardwareInterface>
    </joint>
    <actuator name="robot4/motor3">
      <mechanicalReduction>1</mechanicalReduction>
    </actuator>
  </transmission>
  <!-- link 2 -->
  <link name="robot4/link4">
    <visual>
      <origin rpy="0 0 0" xyz="0.0 0.0 0.0"/>
      <geometry>
        <mesh filename="assets/papras/7dof/link4.stl"/>
      </geometry>
      <material name="grey"/>
    </visual>
    <collision>
      <origin rpy="0 0 0" xyz="0 0 0"/>
      <geometry>
        <mesh filename="assets/papras/7dof/link4.stl"/>
      </geometry>
    </collision>
    <inertial>
      <origin rpy="0 0 0" xyz="-4.86609203880829E-06 0.120506252053841 -0.0279123104678896"/>
      <mass value="0.597399042150493"/>
      <!-- <inertia ixx="1.0" ixy="0.0" ixz="0.0" iyy="1.0" iyz="0.0" izz="1.0" /> -->
      <inertia ixx="0.0015528567154149" ixy="1.16567414120262E-05" ixz="-2.90009974781987E-06" iyy="0.00077263780701987" iyz="9.95380938833158E-05" izz="0.0018580466481516"/>
    </inertial>
  </link>
  <gazebo reference="robot4/link4">
    <kp>1000000.0</kp>
    <kd>100.0</kd>
    <mu1>30.0</mu1>
    <mu2>30.0</mu2>
    <maxVel>1.0</maxVel>
    <minDepth>0.001</minDepth>
    <material>Gazebo/White</material>
    <selfCollide>1</selfCollide>
    <dampingFactor>0.01</dampingFactor>
  </gazebo>
  <!-- Joint 3 -->
  <joint name="robot4/joint4" type="revolute">
    <parent link="robot4/link4"/>
    <child link="robot4/link5"/>
    <origin rpy="3.141592653589793 -1.5707963267948966 1.5707963267948966" xyz="0.0575 0.10761780185239 0.0300000000000553"/>
    <axis xyz="0 1 0"/>
    <limit effort="100" lower="-3.141592653589793" upper="1.42" velocity="3.03687"/>
    <dynamics damping="0.7"/>
  </joint>
  <transmission name="robot4/tran4">
    <type>transmission_interface/SimpleTransmission</type>
    <joint name="robot4/joint4">
      <hardwareInterface>hardware_interface/PositionJointInterface</hardwareInterface>
    </joint>
    <actuator name="robot4/motor4">
      <mechanicalReduction>1</mechanicalReduction>
    </actuator>
  </transmission>
  <!-- link 5 -->
  <link name="robot4/link5">
    <visual>
      <origin rpy="0 0 3.14" xyz="0.227 0.0085 -0.024"/>
      <geometry>
        <mesh filename="assets/papras/link4_papras.stl" scale="0.001 0.001 0.001"/>
      </geometry>
      <material name="grey"/>
    </visual>
    <collision>
      <origin rpy="0 0 3.14" xyz="0.227 0.0085 -0.024"/>
      <geometry>
        <mesh filename="assets/papras/link4_papras_simple.stl" scale="0.001 0.001 0.001"/>
      </geometry>
    </collision>
    <inertial>
      <origin rpy="0 0 0" xyz="0.12475 -0.05716 0.02979"/>
      <!--<origin xyz="-0.07025 0.00034 -0.00021" rpy="0 0 0"/>-->
      <mass value="1.15977"/>
      <inertia ixx="1.0" ixy="0.0" ixz="0.0" iyy="1.0" iyz="0.0" izz="1.0"/>
      <!--<inertia ixx="0.00096726" ixy="0.00004383" ixz="-0.00002771" iyy="0.00318801" iyz="0.00000627" izz="0.00341484" />-->
    </inertial>
  </link>
  <gazebo reference="robot4/link5">
    <kp>1000000.0</kp>
    <kd>100.0</kd>
    <mu1>30.0</mu1>
    <mu2>30.0</mu2>
    <maxVel>1.0</maxVel>
    <minDepth>0.001</minDepth>
    <material>Gazebo/White</material>
    <selfCollide>1</selfCollide>
    <dampingFactor>0.01</dampingFactor>
  </gazebo>
  <!-- Joint 4 -->
  <joint name="robot4/joint5" type="revolute">
    <parent link="robot4/link5"/>
    <child link="robot4/link6"/>
    <origin rpy="0 0 0" xyz="0.19500 -0.05750 0.03000"/>
    <axis xyz="1 0 0"/>
    <limit effort="100" lower="-2.748893571891069" upper="2.748893571891069" velocity="3.03687"/>
    <dynamics damping="0.7"/>
  </joint>
  <transmission name="robot4/tran5">
    <type>transmission_interface/SimpleTransmission</type>
    <joint name="robot4/joint5">
      <hardwareInterface>hardware_interface/PositionJointInterface</hardwareInterface>
    </joint>
    <actuator name="robot4/motor5">
      <mechanicalReduction>1</mechanicalReduction>
    </actuator>
  </transmission>
  <!-- link 6 -->
  <link name="robot4/link6">
    <visual>
      <origin rpy="0 0 0" xyz="0 0 0"/>
      <geometry>
        <mesh filename="assets/papras/link5.stl" scale="0.001 0.001 0.001"/>
      </geometry>
      <material name="grey"/>
    </visual>
    <collision>
      <origin rpy="0 0 0" xyz="0 0 0"/>
      <geometry>
        <mesh filename="assets/papras/link5.stl" scale="0.001 0.001 0.001"/>
      </geometry>
    </collision>
    <inertial>
      <origin rpy="0 0 0" xyz="0.05642 -0.00217 0.00002"/>
      <!--<origin xyz="-0.00658 -0.04717 0.00002" rpy="0 0 0"/>-->
      <mass value="0.44688"/>
      <inertia ixx="1.0" ixy="0.0" ixz="0.0" iyy="1.0" iyz="0.0" izz="1.0"/>
      <!--<inertia ixx="0.00030285" ixy="0.00000761" ixz="0.00000031" iyy="0.00022339" iyz="-0.00000001" izz="0.00039766" />-->
    </inertial>
  </link>
  <gazebo reference="robot4/link6">
    <kp>1000000.0</kp>
    <kd>100.0</kd>
    <mu1>30.0</mu1>
    <mu2>30.0</mu2>
    <maxVel>1.0</maxVel>
    <minDepth>0.001</minDepth>
    <material>Gazebo/White</material>
    <selfCollide>1</selfCollide>
    <dampingFactor>0.01</dampingFactor>
  </gazebo>
  <!-- Joint 6 -->
  <joint name="robot4/joint6" type="revolute">
    <parent link="robot4/link6"/>
    <child link="robot4/link7"/>
    <origin rpy="0 0 0" xyz="0.06300 0.04500 0.00000"/>
    <axis xyz="0 1 0"/>
    <limit effort="100" lower="-1.5707963267948966" upper="1.5707963267948966" velocity="3.03687"/>
    <dynamics damping="0.7"/>
  </joint>
  <transmission name="robot4/tran6">
    <type>transmission_interface/SimpleTransmission</type>
    <joint name="robot4/joint6">
      <hardwareInterface>hardware_interface/PositionJointInterface</hardwareInterface>
    </joint>
    <actuator name="robot4/motor6">
      <mechanicalReduction>1</mechanicalReduction>
    </actuator>
  </transmission>
  <!-- link 6 -->
  <link name="robot4/link7">
    <visual>
      <origin rpy="0 0 0" xyz="-0.034 -0.098 -0.028"/>
      <geometry>
        <mesh filename="assets/papras/link6_papras.stl" scale="0.001 0.001 0.001"/>
      </geometry>
      <material name="grey"/>
    </visual>
    <collision>
      <origin rpy="0 0 0" xyz="-0.034 -0.098 -0.028"/>
      <geometry>
        <mesh filename="assets/papras/link6_papras_simple.stl" scale="0.001 0.001 0.001"/>
      </geometry>
    </collision>
    <inertial>
      <origin rpy="0 0 0" xyz="0.06831 -0.04457 0.00000"/>
      <!--<origin xyz="-0.05469 0.00043 0.00000" rpy="0 0 0"/>-->
      <mass value="0.43273"/>
      <inertia ixx="1.0" ixy="0.0" ixz="0.0" iyy="1.0" iyz="0.0" izz="1.0"/>
      <!--<inertia ixx="0.00021512" ixy="0.00001009" ixz="0.00000000" iyy="0.00042827" iyz="0.00000000" izz="0.00051436" />-->
    </inertial>
  </link>
  <gazebo reference="robot4/link7">
    <kp>1000000.0</kp>
    <kd>100.0</kd>
    <mu1>30.0</mu1>
    <mu2>30.0</mu2>
    <maxVel>1.0</maxVel>
    <minDepth>0.001</minDepth>
    <material>Gazebo/White</material>
    <selfCollide>1</selfCollide>
    <dampingFactor>0.01</dampingFactor>
  </gazebo>
  <!-- Joint 7 -->
  <joint name="robot4/joint7" type="revolute">
    <parent link="robot4/link7"/>
    <child link="robot4/end_link"/>
    <origin rpy="0 0 0" xyz="0.12300 -0.04500 0.00000"/>
    <axis xyz="1 0 0"/>
    <limit effort="100" lower="-3.141592653589793" upper="3.141592653589793" velocity="3.03687"/>
    <dynamics damping="0.7"/>
  </joint>
  <transmission name="robot4/tran7">
    <type>transmission_interface/SimpleTransmission</type>
    <joint name="robot4/joint7">
      <hardwareInterface>hardware_interface/PositionJointInterface</hardwareInterface>
    </joint>
    <actuator name="robot4/motor7">
      <mechanicalReduction>1</mechanicalReduction>
    </actuator>
  </transmission>
  <!-- end link -->
  <link name="robot4/end_link">
    <visual>
      <origin rpy="0 0 0" xyz="0.0 0.0 0.0"/>
      <geometry>
        <mesh filename="assets/papras/end_link.stl" scale="0.001 0.001 0.001"/>
      </geometry>
      <material name="grey"/>
    </visual>
    <collision>
      <origin rpy="0 0 0" xyz="0.0 0.0 0.0"/>
      <geometry>
        <mesh filename="assets/papras/end_link.stl" scale="0.001 0.001 0.001"/>
      </geometry>
    </collision>
    <inertial>
      <origin rpy="0 0 0" xyz="0.00337 0.00000 0.00000"/>
      <mass value="0.01919"/>
      <inertia ixx="1.0" ixy="0.0" ixz="0.0" iyy="1.0" iyz="0.0" izz="1.0"/>
      <!--<inertia ixx="0.00000938" ixy="0.0" ixz="0.0" iyy="0.00000338" iyz="0.0" izz="0.00000635" />-->
    </inertial>
  </link>
  <gazebo reference="robot4/end_link">
    <kp>1000000.0</kp>
    <kd>100.0</kd>
    <mu1>30.0</mu1>
    <mu2>30.0</mu2>
    <maxVel>1.0</maxVel>
    <minDepth>0.001</minDepth>
    <material>Gazebo/White</material>
    <selfCollide>1</selfCollide>
    <dampingFactor>0.01</dampingFactor>
  </gazebo>
  <link name="robot4/wrist_link">
  </link>
  <joint name="robot4/wrist_joint" type="fixed">
    <parent link="robot4/end_link"/>
    <child link="robot4/wrist_link"/>
    <origin rpy="0 0 0" xyz="0.006 0.0 0.0"/>
  </joint>
  <!-- gripper main fixed joint-->
  <joint name="robot4/end_link_fixed" type="fixed">
    <parent link="robot4/end_link"/>
    <child link="robot4/gripper_main_link"/>
    <origin rpy="0 -1.5707963267948966 3.141592653589793" xyz="0.006 0.0 0.0"/>
  </joint>
  <!-- gripper main link -->
    <link name="robot4/gripper_main_link">
    <collision>
      <origin rpy="0 0 0" xyz="0 0 0"/>
      <geometry>
        <mesh filename="assets/robotis_hand_rh-p12-rn/rh_p12_rn_base.stl" scale="0.001 0.001 0.001"/>
      </geometry>
    </collision>
    <visual>
      <origin rpy="0 0 0" xyz="0 0 0"/>
      <geometry>
        <mesh filename="assets/robotis_hand_rh-p12-rn/rh_p12_rn_base.stl" scale="0.001 0.001 0.001"/>
      </geometry>
      <material name="grey"/>
    </visual>
    <inertial>
      <origin rpy="0 0 0" xyz="0.000 0.000 0.032"/>
      <mass value="0.236"/>
      <!--<inertia ixx="0.00017" ixy="0.0" ixz="0.0" iyy="0.00011" iyz="0.0" izz="0.00017" />-->
      <inertia ixx="1.0" ixy="0.0" ixz="0.0" iyy="1.0" iyz="0.0" izz="1.0"/>
    </inertial>
  </link>
  <gazebo reference="robot4/gripper_main_link">
    <kp>1000000.0</kp>
    <kd>100.0</kd>
    <mu1>30.0</mu1>
    <mu2>30.0</mu2>
    <maxVel>1.0</maxVel>
    <minDepth>0.001</minDepth>
    <material>Gazebo/White</material>
    <selfCollide>1</selfCollide>
    <dampingFactor>0.01</dampingFactor>
  </gazebo>
  <!-- gripper joint -->
  <joint name="robot4/gripper" type="revolute">
    <parent link="robot4/gripper_main_link"/>
    <child link="robot4/gripper_link"/>
    <origin rpy="0 0 0" xyz="0.0 0.008 0.048"/>
    <axis xyz="1 0 0"/>
    <limit effort="1000" lower="0.0" upper="1.1" velocity="6.5"/>
    <dynamics damping="0.7"/>
  </joint>
  <transmission name="robot4/trangripper">
    <type>transmission_interface/SimpleTransmission</type>
    <joint name="robot4/gripper">
      <hardwareInterface>hardware_interface/EffortJointInterface</hardwareInterface>
    </joint>
    <actuator name="robot4/motorgripper">
      <mechanicalReduction>1</mechanicalReduction>
    </actuator>
  </transmission>
  <!-- gripper link -->
  <link name="robot4/gripper_link">
    <collision>
      <origin rpy="0 0 0" xyz="0 0 0"/>
      <geometry>
        <mesh filename="assets/robotis_hand_rh-p12-rn/rh_p12_rn_r1.stl" scale="0.001 0.001 0.001"/>
      </geometry>
    </collision>
    <visual>
      <origin rpy="0 0 0" xyz="0 0 0"/>
      <geometry>
        <mesh filename="assets/robotis_hand_rh-p12-rn/rh_p12_rn_r1.stl" scale="0.001 0.001 0.001"/>
      </geometry>
      <material name="grey"/>
    </visual>
    <inertial>
      <origin rpy="0 0 0" xyz="0.000 0.034 0.004"/>
      <mass value="0.068"/>
      <!--<inertia ixx="0.00004" ixy="0.0" ixz="0.0" iyy="0.00002" iyz="-0.00001" izz="0.00002" />-->
      <inertia ixx="1.0" ixy="0.0" ixz="0.0" iyy="1.0" iyz="0.0" izz="1.0"/>
    </inertial>
  </link>
  <gazebo reference="robot4/gripper_link">
    <kp>1000000.0</kp>
    <kd>100.0</kd>
    <mu1>30.0</mu1>
    <mu2>30.0</mu2>
    <maxVel>1.0</maxVel>
    <minDepth>0.001</minDepth>
    <material>Gazebo/White</material>
    <selfCollide>1</selfCollide>
    <dampingFactor>0.01</dampingFactor>
  </gazebo>
  <joint name="robot4/gripper_r2" type="revolute">
    <parent link="robot4/gripper_link"/>
    <child link="robot4/gripper_link_r2"/>
    <origin rpy="0 0 0" xyz="0.0 0.0493634 0.0285"/>
    <axis xyz="-1 0 0"/>
    <limit effort="1000" lower="0.0" upper="1.0" velocity="6.5"/>
    <dynamics damping="0.7"/>
    <mimic joint="robot4/gripper" multiplier="0.9090909090909091"/>
  </joint>
  <transmission name="robot4/trangripper_r2">
    <type>transmission_interface/SimpleTransmission</type>
    <joint name="robot4/gripper_r2">
      <hardwareInterface>hardware_interface/EffortJointInterface</hardwareInterface>
    </joint>
    <actuator name="robot4/motorgripper_r2">
      <mechanicalReduction>1</mechanicalReduction>
    </actuator>
  </transmission>
  <!-- rh_p12_rn_r2 -->
  <link name="robot4/gripper_link_r2">
    <collision>
      <origin rpy="0 0 0" xyz="0 0 0"/>
      <geometry>
        <mesh filename="assets/robotis_hand_rh-p12-rn/rh_p12_rn_r2.stl" scale="0.001 0.001 0.001"/>
      </geometry>
    </collision>
    <visual>
      <origin rpy="0 0 0" xyz="0 0 0"/>
      <geometry>
        <mesh filename="assets/robotis_hand_rh-p12-rn/rh_p12_rn_r2.stl" scale="0.001 0.001 0.001"/>
      </geometry>
      <material name="grey"/>
    </visual>
    <inertial>
      <origin rpy="0 0 0" xyz="0.000 0.006 0.011"/>
      <mass value="0.022"/>
      <!--<inertia ixx="0.0" ixy="0.0" ixz="0.0" iyy="0.00001" iyz="0.0" izz="0.0" />-->
      <inertia ixx="1.0" ixy="0.0" ixz="0.0" iyy="1.0" iyz="0.0" izz="1.0"/>
    </inertial>
  </link>
  <gazebo reference="robot4/gripper_link_r2">
    <kp>1000000.0</kp>
    <kd>100.0</kd>
    <mu1>30.0</mu1>
    <mu2>30.0</mu2>
    <maxVel>1.0</maxVel>
    <minDepth>0.001</minDepth>
    <material>Gazebo/White</material>
    <selfCollide>1</selfCollide>
    <dampingFactor>0.01</dampingFactor>
  </gazebo>
  <!-- Left Joint 1 -->
  <joint name="robot4/gripper_l1" type="revolute">
    <parent link="robot4/gripper_main_link"/>
    <child link="robot4/gripper_link_l1"/>
    <origin rpy="0 0 0" xyz="0.0 -0.008 0.048"/>
    <axis xyz="-1 0 0"/>
    <limit effort="1000" lower="0.0" upper="1.1" velocity="6.5"/>
    <dynamics damping="0.7"/>
    <mimic joint="robot4/gripper" multiplier="1.0"/>
  </joint>
  <transmission name="robot4/trangripper_l1">
    <type>transmission_interface/SimpleTransmission</type>
    <joint name="robot4/gripper_l1">
      <hardwareInterface>hardware_interface/EffortJointInterface</hardwareInterface>
    </joint>
    <actuator name="robot4/motorgripper_l1">
      <mechanicalReduction>1</mechanicalReduction>
    </actuator>
  </transmission>
  <!-- rh_p12_rn_l1 -->
  <link name="robot4/gripper_link_l1">
    <collision>
      <origin rpy="0 0 0" xyz="0 0 0"/>
      <geometry>
        <mesh filename="assets/robotis_hand_rh-p12-rn/rh_p12_rn_l1.stl" scale="0.001 0.001 0.001"/>
      </geometry>
    </collision>
    <visual>
      <origin rpy="0 0 0" xyz="0 0 0"/>
      <geometry>
        <mesh filename="assets/robotis_hand_rh-p12-rn/rh_p12_rn_l1.stl" scale="0.001 0.001 0.001"/>
      </geometry>
      <material name="grey"/>
    </visual>
    <inertial>
      <origin rpy="0 0 0" xyz="0.000 -0.034 0.004"/>
      <mass value="0.068"/>
      <!--<inertia ixx="0.00004" ixy="0.0" ixz="0.0" iyy="0.00002" iyz="0.00001" izz="0.00002" />-->
      <inertia ixx="1.0" ixy="0.0" ixz="0.0" iyy="1.0" iyz="0.0" izz="1.0"/>
    </inertial>
  </link>
  <gazebo reference="robot4/gripper_link_l1">
    <kp>1000000.0</kp>
    <kd>100.0</kd>
    <mu1>30.0</mu1>
    <mu2>30.0</mu2>
    <maxVel>1.0</maxVel>
    <minDepth>0.001</minDepth>
    <material>Gazebo/White</material>
    <selfCollide>1</selfCollide>
    <dampingFactor>0.01</dampingFactor>
  </gazebo>
  <!-- Left Joint 2 -->
  <joint name="robot4/gripper_l2" type="revolute">
    <parent link="robot4/gripper_link_l1"/>
    <child link="robot4/gripper_link_l2"/>
    <origin rpy="0 0 0" xyz="0.0 -0.0493634 0.0285"/>
    <axis xyz="1 0 0"/>
    <limit effort="1000" lower="0.0" upper="1.0" velocity="6.5"/>
    <dynamics damping="0.7"/>
    <mimic joint="robot4/gripper" multiplier="0.9090909090909091"/>
  </joint>
  <transmission name="robot4/trangripper_l2">
    <type>transmission_interface/SimpleTransmission</type>
    <joint name="robot4/gripper_l2">
      <hardwareInterface>hardware_interface/EffortJointInterface</hardwareInterface>
    </joint>
    <actuator name="robot4/motorgripper_l2">
      <mechanicalReduction>1</mechanicalReduction>
    </actuator>
  </transmission>
  <link name="robot4/gripper_link_l2">
    <collision>
      <origin rpy="0 0 0" xyz="0 0 0"/>
      <geometry>
        <mesh filename="assets/robotis_hand_rh-p12-rn/rh_p12_rn_l2.stl" scale="0.001 0.001 0.001"/>
      </geometry>
    </collision>
    <visual>
      <origin rpy="0 0 0" xyz="0 0 0"/>
      <geometry>
        <mesh filename="assets/robotis_hand_rh-p12-rn/rh_p12_rn_l2.stl" scale="0.001 0.001 0.001"/>
      </geometry>
      <material name="grey"/>
    </visual>
    <inertial>
      <origin rpy="0 0 0" xyz="0.000 -0.006 0.011"/>
      <mass value="0.022"/>
      <!--<inertia ixx="0.0" ixy="0.0" ixz="0.0" iyy="0.00001" iyz="0.0" izz="0.0" />-->
      <inertia ixx="1.0" ixy="0.0" ixz="0.0" iyy="1.0" iyz="0.0" izz="1.0"/>
    </inertial>
  </link>
  <!-- gripper main fixed joint-->
  <joint name="robot4/end_effector_joint" type="fixed">
    <parent link="robot4/gripper_main_link"/>
    <child link="robot4/end_effector_link"/>
    <origin rpy="3.141592653589793 -1.5707963267948966 0" xyz="0.0 0.0 0.135"/>
  </joint>
  <!-- End Effector -->
  <link name="robot4/end_effector_link">
    <visual>
      <origin rpy="0 0 0" xyz="0.0 0.0 0.0"/>
      <geometry>
        <box size="0.01 0.01 0.01"/>
      </geometry>
      <material name="red"/>
    </visual>
    <!-- <collision>
        <origin xyz="0.0 0.0 0.0" rpy="0 0 0" />
        <geometry>
          <box size = "0.01 0.01 0.01"/>
        </geometry>
        <material name="red"/>
      </collision> -->
    <inertial>
      <origin rpy="0 0 0" xyz="0.0 0.0 0.0"/>
      <mass value="0.001"/>
      <inertia ixx="1.0" ixy="0.0" ixz="0.0" iyy="1.0" iyz="0.0" izz="1.0"/>
    </inertial>
  </link>
  <gazebo reference="robot4/end_effector_link">
    <material>Gazebo/Red</material>
  </gazebo>
  <gazebo>
    <!-- loading plugin: mimic joints works in gazebo now -->
    <plugin filename="libroboticsgroup_upatras_gazebo_mimic_joint_plugin.so" name="gazebo_gripper4_ros_control">
      <joint>robot4/gripper</joint>
      <mimicJoint>robot4/gripper_sub</mimicJoint>
      <multiplier>1.0</multiplier>
      <offset>0.0</offset>
    </plugin>
  </gazebo>

  <joint name="robot4/hand_joint" type="fixed">
    <parent link="robot4/gripper_main_link"/>
    <child link="robot4/hand_link"/>
    <origin rpy="3.141592653589793 -1.5707963267948966 0" xyz="0.0 0.0 0.10"/>
  </joint>
  <!-- End Effector -->
  <link name="robot4/hand_link">
  </link>

  <!-- Camera Mount -->
  <link name="robot4/camera_mount">
     <visual>
      <origin rpy="1.5707963267948966 -1.5707963267948966 0" xyz="0 0 0"/>
      <geometry>
        <mesh filename="assets/papras/camera_mount.stl"/>
      </geometry>
      <material name="grey"/>
    </visual>
    <collision>
      <origin rpy="1.5707963267948966 -1.5707963267948966 0" xyz="0 0 0"/>
      <geometry>
        <mesh filename="assets/papras/camera_mount_simple.stl"/>
      </geometry>
    </collision>
    <inertial>
      <origin rpy="1.5707963267948966 -1.5707963267948966 0" xyz="0 0 0"/>
      <mass value="0.088"/>
      <inertia ixx="1.0" ixy="0.0" ixz="0.0" iyy="1.0" iyz="0.0" izz="1.0"/>
    </inertial>
  </link>
   <joint name="robot4/camera_fixed_joint" type="fixed">
    <parent link="robot4/gripper_main_link"/>
    <child link="robot4/camera_mount"/>
    <origin xyz="0.04452 -0.0167 0.049" rpy="0 0 1.5707963267948966" />
  </joint>

  <link name="robot4/camera_plugin_link"/>
   <joint name="robot4/camera_fixed_plugin_joint" type="fixed">
    <parent link="robot4/camera_mount"/>
    <child link="robot4/camera_plugin_link"/>
    <origin rpy="1.5707963267948966 -1.5707963267948966 0" xyz="0 0 0"/>
  </joint>
</robot>

