<?xml version="1.0" ?>
<!-- =================================================================================== -->
<!-- |    This document was autogenerated by xacro from g1_baby.xacro                  | -->
<!-- |    EDITING THIS FILE BY HAND IS NOT RECOMMENDED                                 | -->
<!-- =================================================================================== -->
<robot name="g1_Light_arm_leader">
	<mujoco>
		<compiler angle="radian" meshdir="../" autolimits="true" strippath="false" fusestatic="false" balanceinertia="true"/>
	</mujoco>	
  <!-- Link intertia values are incorrect for links 3 and 4 -->
  <link name="left_arm_base_link">
    <inertial>
      <origin rpy="0 0 0" xyz="0.00000000 -0.01230125 0.00718113"/>
      <mass value="0.01800000"/>
      <inertia ixx="0.00000626" ixy="0.00000000" ixz="0.00000000" iyy="0.00000323" iyz="-0.00000155" izz="0.00000412"/>
    </inertial>
    <visual>
      <origin rpy="0 0 0" xyz="0 0 0"/>
      <geometry>
        <mesh filename="assets/leaders/baby/base_link_L.STL"/>
      </geometry>
      <material name="">
        <color rgba="0.79216 0.81961 0.93333 1"/>
      </material>
    </visual>
    <collision>
      <origin rpy="0 0 0" xyz="0 0 0"/>
      <geometry>
        <mesh filename="assets/leaders/baby/base_link_L.STL"/>
      </geometry>
    </collision>
  </link>
  <link name="left_arm_link1">
    <inertial>
      <origin rpy="0 0 0" xyz="0.01387236 0.00000000 0.00000273"/>
      <mass value="0.00630282"/>
      <inertia ixx="1.16E-06" ixy="0" ixz="0" iyy="8.8E-06" iyz="0" izz="2.72E-06"/>
    </inertial>
    <visual>
      <origin rpy="0 0 0" xyz="0 0 0"/>
      <geometry>
        <mesh filename="assets/leaders/baby/g1_arm_link_1_L.STL"/>
      </geometry>
      <material name="">
        <color rgba="0.79216 0.81961 0.93333 1"/>
      </material>
    </visual>
    <collision>
      <origin rpy="0 0 0" xyz="0 0 0"/>
      <geometry>
        <mesh filename="assets/leaders/baby/g1_arm_link_1_L.STL"/>
      </geometry>
    </collision>
  </link>
  <link name="left_arm_link2">
    <inertial>
      <origin rpy="0 0 0" xyz="0 -0.00345697 -0.00992158"/>
      <mass value="0.02099123"/>
      <inertia ixx="0.00000622" ixy="0" ixz="0" iyy="0.00000544" iyz="0.00000087" izz="0.00000207"/>
    </inertial>
    <visual>
      <origin rpy="0 0 0" xyz="0 0 0"/>
      <geometry>
        <mesh filename="assets/leaders/baby/g1_arm_link_2_L.STL"/>
      </geometry>
      <material name="">
        <color rgba="0.79216 0.81961 0.93333 1"/>
      </material>
    </visual>
    <collision>
      <origin rpy="0 0 0" xyz="0 0 0"/>
      <geometry>
        <mesh filename="assets/leaders/baby/g1_arm_link_2_L.STL"/>
      </geometry>
    </collision>
  </link>
  <link name="left_arm_link3">

    <visual>
      <origin rpy="0 0 0" xyz="0 0 0"/>
      <geometry>
        <mesh filename="assets/leaders/baby/g1_arm_link_3_L.STL"/>
      </geometry>
      <material name="">
        <color rgba="0.79216 0.81961 0.93333 1"/>
      </material>
    </visual>
    <collision>
      <origin rpy="0 0 0" xyz="0 0 0"/>
      <geometry>
        <mesh filename="assets/leaders/baby/g1_arm_link_3_L.STL"/>
      </geometry>
    </collision>
  </link>
  <link name="left_arm_link4">

    <visual>
      <origin rpy="0 0 0" xyz="0 0 0"/>
      <geometry>
        <mesh filename="assets/leaders/baby/g1_arm_link_4_L.STL"/>
      </geometry>
      <material name="">
        <color rgba="0.79216 0.81961 0.93333 1"/>
      </material>
    </visual>
    <collision>
      <origin rpy="0 0 0" xyz="0 0 0"/>
      <geometry>
        <mesh filename="assets/leaders/baby/g1_arm_link_4_L.STL"/>
      </geometry>
    </collision>
  </link>
  <link name="left_arm_link5">
    <inertial>
      <origin rpy="0 0 0" xyz="0.04583889 -0.00415733 0.00000000"/>
      <mass value="0.05392167"/>
      <inertia ixx="0.00000769" ixy="-0.00000538" ixz="0.00000000" iyy="0.00017195" iyz="0.00000000" izz="0.00017659"/>
    </inertial>
    <visual>
      <origin rpy="0 0 0" xyz="0 0 0"/>
      <geometry>
        <mesh filename="assets/leaders/baby/g1_arm_link_5_L.STL"/>
      </geometry>
      <material name="">
        <color rgba="0.79216 0.81961 0.93333 1"/>
      </material>
    </visual>
    <collision>
      <origin rpy="0 0 0" xyz="0 0 0"/>
      <geometry>
        <mesh filename="assets/leaders/baby/g1_arm_link_5_L.STL"/>
      </geometry>
    </collision>
  </link>
  <link name="left_arm_link6">
    <inertial>
      <origin rpy="0 0 0" xyz="0.02038055 -0.00000138 -0.00000112"/>
      <mass value=" 0.01167564"/>
      <inertia ixx="0.00000248" ixy="0.00000000" ixz="0.00000000" iyy="0.00000737" iyz="0.00000000" izz="0.00000741"/>
    </inertial>
    <visual>
      <origin rpy="0 0 0" xyz="0 0 0"/>
      <geometry>
        <mesh filename="assets/leaders/baby/g1_arm_link_6_L.STL"/>
      </geometry>
      <material name="">
        <color rgba="0.79216 0.81961 0.93333 1"/>
      </material>
    </visual>
    <collision>
      <origin rpy="0 0 0" xyz="0 0 0"/>
      <geometry>
        <mesh filename="assets/leaders/baby/g1_arm_link_6_L.STL"/>
      </geometry>
    </collision>
  </link>
  <link name="left_arm_link7">
    <inertial>
      <origin rpy="0 0 0" xyz="0.06890215 0.00304461 -0.04175166"/>
      <mass value="0.1095606"/>
      <inertia ixx="0.00036318" ixy="0.00004247" ixz="-0.00033149" iyy="0.00105228" iyz="-0.00000788" izz="0.00072013"/>
    </inertial>
    <visual>
      <origin rpy="0 0 0" xyz="0 0 0"/>
      <geometry>
        <mesh filename="assets/leaders/baby/g1_arm_link_7_L.STL"/>
      </geometry>
      <material name="">
        <color rgba="0.79216 0.81961 0.93333 1"/>
      </material>
    </visual>
    <collision>
      <origin rpy="0 0 0" xyz="0 0 0"/>
      <geometry>
        <mesh filename="assets/leaders/baby/g1_arm_link_7_L.STL"/>
      </geometry>
    </collision>
  </link>
  
  <joint name="left_shoulder_pitch_joint" type="revolute">
    <origin rpy="0 0 -3.1415926535" xyz="0 0.026 0"/>
    <parent link="left_arm_base_link"/>
    <child link="left_arm_link1"/>
    <axis xyz="0 -1 0"/>
    <limit effort="0" lower="-3.0892" upper="2.6704" velocity="1.0"/>
  </joint>
  <joint name="left_shoulder_roll_joint" type="revolute">
    <origin rpy="0 0 3.1415926" xyz="-0.00415 -0.03339492 0"/>
    <parent link="left_arm_link1"/>
    <child link="left_arm_link2"/>
    <axis xyz="1 0 0"/>
    <limit effort="0" lower="-1.5882" upper="2.2515" velocity="1.0"/>
  </joint>
  <joint name="left_shoulder_yaw_joint" type="revolute">
    <origin rpy="0 0 0" xyz="-0.009766 0 -0.031"/>
    <parent link="left_arm_link2"/>
    <child link="left_arm_link3"/>
    <axis xyz="0 0 1"/>
    <limit effort="0" lower="-2.618" upper="2.618" velocity="1.0"/>
  </joint>
  <joint name="left_elbow_joint" type="revolute">
    <origin rpy="0 0 0" xyz="0.0142047 0 -0.1343462"/>
    <parent link="left_arm_link3"/>
    <child link="left_arm_link4"/>
    <axis xyz="0 1 0"/>
    <limit effort="0" lower="-1.0472" upper="2.0944" velocity="1.0"/>
  </joint>
  <joint name="left_wrist_roll_joint" type="revolute">
    <origin rpy="0 0 0" xyz="0.032 -0.001699119 -0.009"/>
    <parent link="left_arm_link4"/>
    <child link="left_arm_link5"/>
    <axis xyz="1 0 0"/>
    <limit effort="0" lower="-1.972222054" upper="1.972222054" velocity="1.0"/>
  </joint>
  <joint name="left_wrist_pitch_joint" type="revolute">
    <origin rpy="0 0 0" xyz="0.09205 -0.00185 0"/>
    <parent link="left_arm_link5"/>
    <child link="left_arm_link6"/>
    <axis xyz="0 1 0"/>
    <limit effort="0" lower="-1.614429558" upper="1.614429558" velocity="1.0"/>
  </joint>
  <joint name="left_wrist_yaw_joint" type="revolute">
    <origin rpy="0 0 0" xyz="0.0414 0 0.0043"/>
    <parent link="left_arm_link6"/>
    <child link="left_arm_link7"/>
    <axis xyz="0 0 1"/>
    <limit effort="0" lower="-1.614429558" upper="1.614429558" velocity="1.0"/>
  </joint>
  
  <joint name="left/gripper" type="revolute">
    <parent link="left_arm_link7"/>
    <child link="left_gripper_link"/>
    <origin rpy="0 0 -1.57" xyz="0.125 0 -0.03"/>
    <axis xyz="1 0 0"/>
    <limit effort="1" lower="-3.14159265359" upper="3.14159265359" velocity="4.8"/>
  </joint>
  <link name="left_gripper_link">
    <visual>
      <origin rpy="0 0 0" xyz="0 0 0"/>
      <geometry>
        <mesh filename="assets/leaders/baby/gripper.stl" scale="0.001 0.001 0.001"/>
      </geometry>
    </visual>
    <collision>
      <origin rpy="0 0 0" xyz="0 0 0"/>
      <geometry>
        <mesh filename="assets/leaders/baby/gripper.stl" scale="0.001 0.001 0.001"/>
      </geometry>
    </collision>
    <inertial>
      <origin xyz="-2.635467700e-04 -2.054786700e-03 -8.785326800e-03"/>
      <mass value="4.060915900e-03"/>
      <inertia ixx="7.509344100e-07" ixy="2.199112900e-09" ixz="9.402416300e-09" iyy="5.484008000e-07" iyz="-9.942781800e-08" izz="2.396226600e-07"/>
    </inertial>
  </link>
    <joint name="left_eef_joint" type="fixed">
    <parent link="left_arm_link7"/>
    <child link="left_end_effector_link"/>
    <origin rpy="0 0 0.0" xyz="0.025 0 0.00"/>
    <axis xyz="1 0 0"/>
  </joint>
  <link name="left_end_effector_link"/>
  <link name="right_arm_base_link">
    <inertial>
      <origin rpy="0 0 0" xyz="0.00000000 -0.01230125 0.00718113"/>
      <mass value="0.01800000"/>
      <inertia ixx="0.00000626" ixy="0.00000000" ixz="0.00000000" iyy="0.00000323" iyz="-0.00000155" izz="0.00000412"/>
    </inertial>
    <visual>
      <origin rpy="0 0 0" xyz="0 0 0"/>
      <geometry>
        <mesh filename="assets/leaders/baby/base_link_R.STL"/>
      </geometry>
      <material name="">
        <color rgba="0.79216 0.81961 0.93333 1"/>
      </material>
    </visual>
    <collision>
      <origin rpy="0 0 0" xyz="0 0 0"/>
      <geometry>
        <mesh filename="assets/leaders/baby/base_link_R.STL"/>
      </geometry>
    </collision>
  </link>
  <link name="right_arm_link1">
    <inertial>
      <origin rpy="0 0 0" xyz="0.01387236 0.00000000 0.00000273"/>
      <mass value="0.00630282"/>
      <inertia ixx="1.16E-06" ixy="0" ixz="0" iyy="8.8E-06" iyz="0" izz="2.72E-06"/>
    </inertial>
    <visual>
      <origin rpy="0 0 0" xyz="0 0 0"/>
      <geometry>
        <mesh filename="assets/leaders/baby/g1_arm_link_1_R.STL"/>
      </geometry>
      <material name="">
        <color rgba="0.79216 0.81961 0.93333 1"/>
      </material>
    </visual>
    <collision>
      <origin rpy="0 0 0" xyz="0 0 0"/>
      <geometry>
        <mesh filename="assets/leaders/baby/g1_arm_link_1_R.STL"/>
      </geometry>
    </collision>
  </link>
  <link name="right_arm_link2">
    <inertial>
      <origin rpy="0 0 0" xyz="0 -0.00345697 -0.00992158"/>
      <mass value="0.02099123"/>
      <inertia ixx="0.00000622" ixy="0" ixz="0" iyy="0.00000544" iyz="0.00000087" izz="0.00000207"/>
    </inertial>
    <visual>
      <origin rpy="0 0 0" xyz="0 0 0"/>
      <geometry>
        <mesh filename="assets/leaders/baby/g1_arm_link_2_R.STL"/>
      </geometry>
      <material name="">
        <color rgba="0.79216 0.81961 0.93333 1"/>
      </material>
    </visual>
    <collision>
      <origin rpy="0 0 0" xyz="0 0 0"/>
      <geometry>
        <mesh filename="assets/leaders/baby/g1_arm_link_2_R.STL"/>
      </geometry>
    </collision>
  </link>
  <link name="right_arm_link3">
    <inertial>
      <origin rpy="0 0 0" xyz="-0.00311665 0.00003705 -0.0729065"/>
      <mass value="0.06865114"/>
      <inertia ixx="0.00055336" ixy="0.00000013" ixz="0.00000199" iyy="0.00056033" iyz="0.0" izz="0.00001178"/>
    </inertial>
    <visual>
      <origin rpy="0 0 0" xyz="0 0 0"/>
      <geometry>
        <mesh filename="assets/leaders/baby/g1_arm_link_3_R.STL"/>
      </geometry>
      <material name="">
        <color rgba="0.79216 0.81961 0.93333 1"/>
      </material>
    </visual>
    <collision>
      <origin rpy="0 0 0" xyz="0 0 0"/>
      <geometry>
        <mesh filename="assets/leaders/baby/g1_arm_link_3_R.STL"/>
      </geometry>
    </collision>
  </link>
  <link name="right_arm_link4">
    <inertial>
      <origin rpy="0 0 0" xyz="0.01902443 0.00064065 -0.00588890"/>
      <mass value="0.00704644"/>
      <inertia ixx="0.00000188" ixy="0.00000012" ixz="-0.0000010" iyy="0.00000398" iyz="-0.0000000" izz="0.00000471"/>
    </inertial>
    <visual>
      <origin rpy="0 0 0" xyz="0 0 0"/>
      <geometry>
        <mesh filename="assets/leaders/baby/g1_arm_link_4_R.STL"/>
      </geometry>
      <material name="">
        <color rgba="0.79216 0.81961 0.93333 1"/>
      </material>
    </visual>
    <collision>
      <origin rpy="0 0 0" xyz="0 0 0"/>
      <geometry>
        <mesh filename="assets/leaders/baby/g1_arm_link_4_R.STL"/>
      </geometry>
    </collision>
  </link>
  <link name="right_arm_link5">
    <inertial>
      <origin rpy="0 0 0" xyz="0.04583889 -0.00415733 0.00000000"/>
      <mass value="0.05392167"/>
      <inertia ixx="0.00000769" ixy="-0.00000538" ixz="0.00000000" iyy="0.00017195" iyz="0.00000000" izz="0.00017659"/>
    </inertial>
    <visual>
      <origin rpy="0 0 0" xyz="0 0 0"/>
      <geometry>
        <mesh filename="assets/leaders/baby/g1_arm_link_5_R.STL"/>
      </geometry>
      <material name="">
        <color rgba="0.79216 0.81961 0.93333 1"/>
      </material>
    </visual>
    <collision>
      <origin rpy="0 0 0" xyz="0 0 0"/>
      <geometry>
        <mesh filename="assets/leaders/baby/g1_arm_link_5_R.STL"/>
      </geometry>
    </collision>
  </link>
  <link name="right_arm_link6">
    <inertial>
      <origin rpy="0 0 0" xyz="0.02038055 -0.00000138 -0.00000112"/>
      <mass value=" 0.01167564"/>
      <inertia ixx="0.00000248" ixy="0.00000000" ixz="0.00000000" iyy="0.00000737" iyz="0.00000000" izz="0.00000741"/>
    </inertial>
    <visual>
      <origin rpy="0 0 0" xyz="0 0 0"/>
      <geometry>
        <mesh filename="assets/leaders/baby/g1_arm_link_6_R.STL"/>
      </geometry>
      <material name="">
        <color rgba="0.79216 0.81961 0.93333 1"/>
      </material>
    </visual>
    <collision>
      <origin rpy="0 0 0" xyz="0 0 0"/>
      <geometry>
        <mesh filename="assets/leaders/baby/g1_arm_link_6_R.STL"/>
      </geometry>
    </collision>
  </link>
  <link name="right_arm_link7">
    <inertial>
      <origin rpy="0 0 0" xyz="0.06890215 0.00304461 -0.04175166"/>
      <mass value="0.1095606"/>
      <inertia ixx="0.00036318" ixy="0.00004247" ixz="-0.00033149" iyy="0.00105228" iyz="-0.00000788" izz="0.00072013"/>
    </inertial>
    <visual>
      <origin rpy="0 0 0" xyz="0 0 0"/>
      <geometry>
        <mesh filename="assets/leaders/baby/g1_arm_link_7_R.STL"/>
      </geometry>
      <material name="">
        <color rgba="0.79216 0.81961 0.93333 1"/>
      </material>
    </visual>
    <collision>
      <origin rpy="0 0 0" xyz="0 0 0"/>
      <geometry>
        <mesh filename="assets/leaders/baby/g1_arm_link_7_R.STL"/>
      </geometry>
    </collision>
  </link>
  <joint name="right_eef_joint" type="fixed">
    <parent link="right_arm_link7"/>
    <child link="right_end_effector_link"/>
    <origin rpy="0 0 0.0" xyz="0.025 0 0.00"/>
    <axis xyz="1 0 0"/>
  </joint>
  <link name="right_end_effector_link"/>
  
  <joint name="right/gripper" type="revolute">
    <parent link="right_arm_link7"/>
    <child link="right_gripper_link"/>
    <origin rpy="0 0 -1.57" xyz="0.125 0 -0.03"/>
    <axis xyz="1 0 0"/>
    <limit effort="1" lower="-3.14159265359" upper="3.14159265359" velocity="4.8"/>
  </joint>
  <link name="right_gripper_link">
    <visual>
      <origin rpy="0 0 0" xyz="0 0 0"/>
      <geometry>
        <mesh filename="assets/leaders/baby/gripper.stl" scale="0.001 0.001 0.001"/>
      </geometry>
    </visual>
    <collision>
      <origin rpy="0 0 0" xyz="0 0 0"/>
      <geometry>
        <mesh filename="assets/leaders/baby/gripper.stl" scale="0.001 0.001 0.001"/>
      </geometry>
    </collision>
    <inertial>
      <origin xyz="-2.635467700e-04 -2.054786700e-03 -8.785326800e-03"/>
      <mass value="4.060915900e-03"/>
      <inertia ixx="7.509344100e-07" ixy="2.199112900e-09" ixz="9.402416300e-09" iyy="5.484008000e-07" iyz="-9.942781800e-08" izz="2.396226600e-07"/>
    </inertial>
  </link>
 
  <joint name="right_shoulder_pitch_joint" type="revolute">
    <origin rpy="0 0 0" xyz="0 -0.026 0"/>
    <parent link="right_arm_base_link"/>
    <child link="right_arm_link1"/>
    <axis xyz="0 1 0"/>
    <limit effort="0" lower="-3.0892" upper="2.6704" velocity="1.0"/>
  </joint>
  <joint name="right_shoulder_roll_joint" type="revolute">
    <origin rpy="0 0 0" xyz="0.00415 -0.03339492 0"/>
    <parent link="right_arm_link1"/>
    <child link="right_arm_link2"/>
    <axis xyz="1 0 0"/>
    <limit effort="0" lower="-2.2515" upper="1.5882" velocity="1.0"/>
  </joint>
  <joint name="right_shoulder_yaw_joint" type="revolute">
    <origin rpy="0 0 0" xyz="-0.009766 0 -0.031"/>
    <parent link="right_arm_link2"/>
    <child link="right_arm_link3"/>
    <axis xyz="0 0 1"/>
    <limit effort="0" lower="-2.618" upper="2.618" velocity="1.0"/>
  </joint>
  <joint name="right_elbow_joint" type="revolute">
    <origin rpy="0 0 0" xyz="0.0142047 0 -0.1343462"/>
    <parent link="right_arm_link3"/>
    <child link="right_arm_link4"/>
    <axis xyz="0 1 0"/>
    <limit effort="0" lower="-1.0472" upper="2.0944" velocity="1.0"/>
  </joint>
  <joint name="right_wrist_roll_joint" type="revolute">
    <origin rpy="0 0 0" xyz="0.032 -0.001699119 -0.009"/>
    <parent link="right_arm_link4"/>
    <child link="right_arm_link5"/>
    <axis xyz="1 0 0"/>
    <limit effort="0" lower="-1.972222054" upper="1.972222054" velocity="1.0"/>
  </joint>
  <joint name="right_wrist_pitch_joint" type="revolute">
    <origin rpy="0 0 0" xyz="0.09205 -0.00185 0"/>
    <parent link="right_arm_link5"/>
    <child link="right_arm_link6"/>
    <axis xyz="0 1 0"/>
    <limit effort="0" lower="-1.614429558" upper="1.614429558" velocity="1.0"/>
  </joint>
  <joint name="right_wrist_yaw_joint" type="revolute">
    <origin rpy="0 0 0" xyz="0.0414 0 0.0043"/>
    <parent link="right_arm_link6"/>
    <child link="right_arm_link7"/>
    <axis xyz="0 0 1"/>
    <limit effort="0" lower="-1.614429558" upper="1.614429558" velocity="1.0"/>
  </joint>
  <link name="left_leg_base_link">
    <inertial>
      <origin rpy="0 0 0" xyz="0.00000000 0.00319875 0.00118113"/>
      <mass value="0.01800000"/>
      <inertia ixx="0.00000281" ixy="0.00000000" ixz="0.00000000" iyy="0.00000233" iyz="0.00000011" izz="0.00000158"/>
    </inertial>
    <visual>
      <origin rpy="0 0 0" xyz="0 0 0"/>
      <geometry>
        <mesh filename="assets/leaders/baby/g1_leg_base_link_L.STL"/>
      </geometry>
      <material name="">
        <color rgba="0.79216 0.81961 0.93333 1"/>
      </material>
    </visual>
    <collision>
      <origin rpy="0 0 0" xyz="0 0 0"/>
      <geometry>
        <mesh filename="assets/leaders/baby/g1_leg_base_link_L.STL"/>
      </geometry>
    </collision>
  </link>
  <link name="left_leg_link1">
    <inertial>
      <origin rpy="0 0 0" xyz="0.01016296 0.00000000 -0.00475105"/>
      <mass value="0.00543603"/>
      <inertia ixx="0.00000145" ixy="0.00000000" ixz="-0.00000050" iyy="0.00000142" iyz="0.00000000" izz="0.00000201"/>
    </inertial>
    <visual>
      <origin rpy="0 0 0" xyz="0 0 0"/>
      <geometry>
        <mesh filename="assets/leaders/baby/g1_leg_link_1_L.STL"/>
      </geometry>
      <material name="">
        <color rgba="0.79216 0.81961 0.93333 1"/>
      </material>
    </visual>
    <collision>
      <origin rpy="0 0 0" xyz="0 0 0"/>
      <geometry>
        <mesh filename="assets/leaders/baby/g1_leg_link_1_L.STL"/>
      </geometry>
    </collision>
  </link>
  <link name="left_leg_link2">
    <inertial>
      <origin rpy="0 0 0" xyz="-0.00272858 0.00000000 -0.02683543"/>
      <mass value=" 0.04516848"/>
      <inertia ixx="0.00004938" ixy="0.00000000" ixz="0.00000294" iyy="0.00005307" iyz="0.00000000" izz="0.00000644"/>
    </inertial>
    <visual>
      <origin rpy="0 0 0" xyz="0 0 0"/>
      <geometry>
        <mesh filename="assets/leaders/baby/g1_leg_link_2.STL"/>
      </geometry>
      <material name="">
        <color rgba="0.79216 0.81961 0.93333 1"/>
      </material>
    </visual>
    <collision>
      <origin rpy="0 0 0" xyz="0 0 0"/>
      <geometry>
        <mesh filename="assets/leaders/baby/g1_leg_link_2.STL"/>
      </geometry>
    </collision>
  </link>
  <link name="left_leg_link3">
    <inertial>
      <origin rpy="0 0 0" xyz="-0.01621315 0.00022419 -0.04019605"/>
      <mass value=" 0.06431956"/>
      <inertia ixx="0.00014459" ixy="-0.00000042" ixz="0.00005475" iyy="0.00016734" iyz="-0.00000097" izz="0.00002911"/>
    </inertial>
    <visual>
      <origin rpy="0 0 0" xyz="0 0 0"/>
      <geometry>
        <mesh filename="assets/leaders/baby/g1_leg_link_3.STL"/>
      </geometry>
      <material name="">
        <color rgba="0.79216 0.81961 0.93333 1"/>
      </material>
    </visual>
    <collision>
      <origin rpy="0 0 0" xyz="0 0 0"/>
      <geometry>
        <mesh filename="assets/leaders/baby/g1_leg_link_3.STL"/>
      </geometry>
    </collision>
  </link>
  <link name="left_leg_link4">
    <inertial>
      <origin rpy="0 0 0" xyz="0.00853367 0.00001551 -0.11066266"/>
      <mass value="0.12585466"/>
      <inertia ixx="0.00178709" ixy="0.00000002" ixz="-0.00015479" iyy="0.00184613" iyz="-0.00000026" izz="0.00007683"/>
    </inertial>
    <visual>
      <origin rpy="0 0 0" xyz="0 0 0"/>
      <geometry>
        <mesh filename="assets/leaders/baby/g1_leg_link_4.STL"/>
      </geometry>
      <material name="">
        <color rgba="0.79216 0.81961 0.93333 1"/>
      </material>
    </visual>
    <collision>
      <origin rpy="0 0 0" xyz="0 0 0"/>
      <geometry>
        <mesh filename="assets/leaders/baby/g1_leg_link_4.STL"/>
      </geometry>
    </collision>
  </link>
  <joint name="left_hip_pitch_joint" type="revolute">
    <origin rpy="0 0 0" xyz="0 0.0105 0"/>
    <parent link="left_leg_base_link"/>
    <child link="left_leg_link1"/>
    <axis xyz="0 1 0"/>
    <limit effort="0" lower="-2.5307" upper="2.8798" velocity="1.0"/>
  </joint>
  <joint name="left_hip_roll_joint" type="revolute">
    <origin rpy="0 -0.1749 0" xyz="0.00845606 0.0234 -0.01150819"/>
    <parent link="left_leg_link1"/>
    <child link="left_leg_link2"/>
    <axis xyz="1 0 0"/>
    <limit effort="0" lower="-0.5236" upper="2.9671" velocity="1.0"/>
  </joint>
  <joint name="left_hip_yaw_joint" type="revolute">
    <origin rpy="0 0 0" xyz="0.00486790801 0 -0.055854"/>
    <parent link="left_leg_link2"/>
    <child link="left_leg_link3"/>
    <axis xyz="0 0 1"/>
    <limit effort="0" lower="-2.7576" upper="2.7576" velocity="1.0"/>
  </joint>
  <joint name="left_knee_joint" type="revolute">
    <origin rpy="0 0.1749 0" xyz="-0.0313092 0 -0.070936"/>
    <parent link="left_leg_link3"/>
    <child link="left_leg_link4"/>
    <axis xyz="0 1 0"/>
    <limit effort="0" lower="-0.087267" upper="2.8798" velocity="1.0"/>
  </joint>
  
  <joint name="left_ankle_joint" type="fixed">
    <origin rpy="0 0 0" xyz="0.0 0 -0.120"/>
    <parent link="left_leg_link4"/>
    <child link="left_ankle_link"/>
    <axis xyz="0 1 0"/>
  </joint>
  <link name="left_ankle_link"/>
  
  <link name="right_leg_base_link">
    <inertial>
      <origin rpy="0 0 0" xyz="0.00000000 0.00319875 0.00118113"/>
      <mass value="0.01800000"/>
      <inertia ixx="0.00000281" ixy="0.00000000" ixz="0.00000000" iyy="0.00000233" iyz="0.00000011" izz="0.00000158"/>
    </inertial>
    <visual>
      <origin rpy="0 0 0" xyz="0 0 0"/>
      <geometry>
        <mesh filename="assets/leaders/baby/g1_leg_base_link.STL"/>
      </geometry>
      <material name="">
        <color rgba="0.79216 0.81961 0.93333 1"/>
      </material>
    </visual>
    <collision>
      <origin rpy="0 0 0" xyz="0 0 0"/>
      <geometry>
        <mesh filename="assets/leaders/baby/g1_leg_base_link.STL"/>
      </geometry>
    </collision>
  </link>
  <link name="right_leg_link1">
    <inertial>
      <origin rpy="0 0 0" xyz="0.01016296 0.00000000 -0.00475105"/>
      <mass value="0.00543603"/>
      <inertia ixx="0.00000145" ixy="0.00000000" ixz="-0.00000050" iyy="0.00000142" iyz="0.00000000" izz="0.00000201"/>
    </inertial>
    <visual>
      <origin rpy="0 0 0" xyz="0 0 0"/>
      <geometry>
        <mesh filename="assets/leaders/baby/g1_leg_link_1.STL"/>
      </geometry>
      <material name="">
        <color rgba="0.79216 0.81961 0.93333 1"/>
      </material>
    </visual>
    <collision>
      <origin rpy="0 0 0" xyz="0 0 0"/>
      <geometry>
        <mesh filename="assets/leaders/baby/g1_leg_link_1.STL"/>
      </geometry>
    </collision>
  </link>
  <link name="right_leg_link2">
    <inertial>
      <origin rpy="0 0 0" xyz="-0.00272858 0.00000000 -0.02683543"/>
      <mass value=" 0.04516848"/>
      <inertia ixx="0.00004938" ixy="0.00000000" ixz="0.00000294" iyy="0.00005307" iyz="0.00000000" izz="0.00000644"/>
    </inertial>
    <visual>
      <origin rpy="0 0 0" xyz="0 0 0"/>
      <geometry>
        <mesh filename="assets/leaders/baby/g1_leg_link_2.STL"/>
      </geometry>
      <material name="">
        <color rgba="0.79216 0.81961 0.93333 1"/>
      </material>
    </visual>
    <collision>
      <origin rpy="0 0 0" xyz="0 0 0"/>
      <geometry>
        <mesh filename="assets/leaders/baby/g1_leg_link_2.STL"/>
      </geometry>
    </collision>
  </link>
  <link name="right_leg_link3">
    <inertial>
      <origin rpy="0 0 0" xyz="-0.01621315 0.00022419 -0.04019605"/>
      <mass value=" 0.06431956"/>
      <inertia ixx="0.00014459" ixy="-0.00000042" ixz="0.00005475" iyy="0.00016734" iyz="-0.00000097" izz="0.00002911"/>
    </inertial>
    <visual>
      <origin rpy="0 0 0" xyz="0 0 0"/>
      <geometry>
        <mesh filename="assets/leaders/baby/g1_leg_link_3.STL"/>
      </geometry>
      <material name="">
        <color rgba="0.79216 0.81961 0.93333 1"/>
      </material>
    </visual>
    <collision>
      <origin rpy="0 0 0" xyz="0 0 0"/>
      <geometry>
        <mesh filename="assets/leaders/baby/g1_leg_link_3.STL"/>
      </geometry>
    </collision>
  </link>
  <link name="right_leg_link4">
    <inertial>
      <origin rpy="0 0 0" xyz="0.00853367 0.00001551 -0.11066266"/>
      <mass value="0.12585466"/>
      <inertia ixx="0.00178709" ixy="0.00000002" ixz="-0.00015479" iyy="0.00184613" iyz="-0.00000026" izz="0.00007683"/>
    </inertial>
    <visual>
      <origin rpy="0 0 0" xyz="0 0 0"/>
      <geometry>
        <mesh filename="assets/leaders/baby/g1_leg_link_4.STL"/>
      </geometry>
      <material name="">
        <color rgba="0.79216 0.81961 0.93333 1"/>
      </material>
    </visual>
    <collision>
      <origin rpy="0 0 0" xyz="0 0 0"/>
      <geometry>
        <mesh filename="assets/leaders/baby/g1_leg_link_4.STL"/>
      </geometry>
    </collision>
  </link>
  <joint name="right_hip_pitch_joint" type="revolute">
    <origin rpy="0 0 0" xyz="0 -0.0106 0"/>
    <parent link="right_leg_base_link"/>
    <child link="right_leg_link1"/>
    <axis xyz="0 1 0"/>
    <limit effort="0" lower="-2.5307" upper="2.8798" velocity="1.0"/>
  </joint>
  <joint name="right_hip_roll_joint" type="revolute">
    <origin rpy="0 -0.1749 0" xyz="0.006324517 -0.0234 -0.01280406227"/>
    <parent link="right_leg_link1"/>
    <child link="right_leg_link2"/>
    <axis xyz="1 0 0"/>
    <limit effort="0" lower="-2.9671" upper="0.5236" velocity="1.0"/>
  </joint>
  <joint name="right_hip_yaw_joint" type="revolute">
    <origin rpy="0 0 0" xyz="0.00486790801 0 -0.055854"/>
    <parent link="right_leg_link2"/>
    <child link="right_leg_link3"/>
    <axis xyz="0 0 1"/>
    <limit effort="0" lower="-2.7576" upper="2.7576" velocity="1.0"/>
  </joint>
  <joint name="right_knee_joint" type="revolute">
    <origin rpy="0 0.1749 0" xyz="-0.0313092 0 -0.070936"/>
    <parent link="right_leg_link3"/>
    <child link="right_leg_link4"/>
    <axis xyz="0 1 0"/>
    <limit effort="0" lower="-0.087267" upper="2.8798" velocity="1.0"/>
  </joint>
  
  <joint name="right_ankle_joint" type="fixed">
    <origin rpy="0 0 0" xyz="0.0 0 -0.120"/>
    <parent link="right_leg_link4"/>
    <child link="right_ankle_link"/>
    <axis xyz="0 1 0"/>
  </joint>
  <link name="right_ankle_link"/>
  
  
  <!-- Link intertia values are incorrect for links 3 and 4 -->
  <link name="torso_link">
    <inertial>
      <origin rpy="0 0 0" xyz="-0.00000241 0.00000895 0.00679686"/>
      <mass value="0.69622769"/>
      <inertia ixx="0.00785059" ixy="0.00000220" ixz="0.00001212" iyy="0.00639537" iyz="-0.00002276" izz="0.00283396"/>
    </inertial>
    <visual>
      <origin rpy="0 0 0" xyz="0 0 0"/>
      <geometry>
        <mesh filename="assets/leaders/baby/torso.stl"/>
      </geometry>
      <material name="">
        <color rgba="0.79216 0.81961 0.93333 1"/>
      </material>
    </visual>
    <collision>
      <origin rpy="0 0 0" xyz="0 0 0"/>
      <geometry>
        <mesh filename="assets/leaders/baby/torso_simple.stl"/>
      </geometry>
    </collision>
  </link>
  <joint name="joint1" type="fixed">
    <origin rpy="0 0 0" xyz="0.000125 -0.067 0.0308"/>
    <parent link="torso_link"/>
    <child link="right_arm_base_link"/>
  </joint>
  <joint name="joint2" type="fixed">
    <origin rpy="0 0 0" xyz="0.000125 0.067 0.0306"/>
    <parent link="torso_link"/>
    <child link="left_arm_base_link"/>
  </joint>
  <joint name="joint3" type="fixed">
    <origin rpy="0 0 0" xyz="0.000125 -0.050 -0.1164"/>
    <parent link="torso_link"/>
    <child link="right_leg_base_link"/>
  </joint>
  <joint name="joint4" type="fixed">
    <origin rpy="0 0 0" xyz="0.000125 0.050 -0.1226"/>
    <parent link="torso_link"/>
    <child link="left_leg_base_link"/>
  </joint>
</robot>
