<?xml version="1.0" ?>
<!-- =================================================================================== -->
<!-- |    This document was autogenerated by xacro from papras_7dof_leaders.urdf.xacro | -->
<!-- |    EDITING THIS FILE BY HAND IS NOT RECOMMENDED                                 | -->
<!-- =================================================================================== -->
<robot name="papras_7dof_leaders_table">
	<mujoco>
		<compiler angle="radian" meshdir="../" autolimits="true" strippath="false" fusestatic="false"/>
	</mujoco>	
  <!-- PAPRAS URDF Macros -->
  <!-- Main URDF File should contain:
        - world link
        - world-env joint
        - env link
        - env-robotn/link1 joint for each mount -->
  <!-- This file contains URDF geometry, transmission data and Gazebo references -->
  <material name="black">
    <color rgba="0.0 0.0 0.0 1.0"/>
  </material>
  <material name="blue">
    <color rgba="0.0 0.0 0.8 1.0"/>
  </material>
  <material name="green">
    <color rgba="0.0 0.8 0.0 1.0"/>
  </material>
  <material name="grey">
    <color rgba="0.5 0.5 0.5 1.0"/>
  </material>
  <material name="orange">
    <color rgba="1.0 0.4235294117647059 0.0392156862745098 1.0"/>
  </material>
  <material name="brown">
    <color rgba="0.8705882352941177 0.8117647058823529 0.7647058823529411 1.0"/>
  </material>
  <material name="red">
    <color rgba="0.8 0.0 0.0 1.0"/>
  </material>
  <material name="white">
    <color rgba="1.0 1.0 1.0 1.0"/>
  </material>
  <!-- Import all Gazebo-customization elements, including Gazebo colors -->
  <!-- World -->
  <gazebo reference="world"/>
  <!-- Evn Link -->
  <gazebo reference="env"/>
  <!-- ros_control plugin -->
  <gazebo>
    <plugin filename="libgazebo_ros_control.so" name="gazebo_ros_control">
      <robotSimType>gazebo_ros_control/DefaultRobotHWSim</robotSimType>
    </plugin>
  </gazebo>
  <link name="world"/>
  <joint name="robot1/world_joint" type="fixed">
    <origin rpy="0 0 0" xyz="0.2599 0.33455 -0.05189"/>
    <parent link="world"/>
    <child link="robot1/base_link"/>
    <axis xyz="0 0 0"/>
  </joint>
  <joint name="robot2/world_joint" type="fixed">
    <origin rpy="0 0 0" xyz="0.2601 -0.33435 -0.05189"/>
    <parent link="world"/>
    <child link="robot2/base_link"/>
    <axis xyz="0 0 0"/>
  </joint>
  <!-- <joint name="robot1/world_joint" type="fixed">
    <origin xyz="0.5 0.33455 -0.05189" rpy="0 0 0" />
    <parent link="world" />
    <child link="robot1/base_link" />
    <axis xyz="0 0 0" />
  </joint>

  <joint name="robot2/world_joint" type="fixed">
    <origin xyz="0.5 -0.33435 -0.05189" rpy="0 0 0" />
    <parent link="world" />
    <child link="robot2/base_link" />
    <axis xyz="0 0 0" />
  </joint>

 -->
  <link name="robot1/base_link">
    <inertial>
      <origin rpy="0 0 0" xyz="-1.88052088812657E-05 -0.00215271082064172 0.0441443392060522"/>
      <mass value="0.218376911489293"/>
      <inertia ixx="0.000160297084827002" ixy="1.06759566549485E-08" ixz="-4.82637621739845E-08" iyy="0.000190111291063554" iyz="-5.70875681133123E-06" izz="9.3344618631843E-05"/>
    </inertial>
    <visual>
      <origin rpy="0 0 0" xyz="0 0 0"/>
      <geometry>
        <mesh filename="assets/leaders/base_link.stl"/>
      </geometry>
      <material name="">
        <color rgba="0.752941176470588 0.752941176470588 0.752941176470588 1"/>
      </material>
    </visual>
    <collision>
      <origin rpy="0 0 0" xyz="0 0 0"/>
      <geometry>
        <mesh filename="assets/leaders/base_link.stl"/>
      </geometry>
    </collision>
  </link>
  <link name="robot1/link1">
    <inertial>
      <origin rpy="0 0 0" xyz="8.03381307583049E-16 0.0183891548632449 -0.00065273513210628"/>
      <mass value="0.0184621083060345"/>
      <inertia ixx="2.40713355161292E-06" ixy="-2.72793224052933E-21" ixz="1.89321316204573E-15" iyy="1.52798370468232E-06" iyz="-1.482953424559E-08" izz="2.03767449056785E-06"/>
    </inertial>
    <visual>
      <origin rpy="0 0 0" xyz="0 0 0"/>
      <geometry>
        <mesh filename="assets/leaders/papras_7dof/link1.stl"/>
      </geometry>
      <material name="">
        <color rgba="0.627450980392157 0.627450980392157 0.627450980392157 1"/>
      </material>
    </visual>
    <collision>
      <origin rpy="0 0 0" xyz="0 0 0"/>
      <geometry>
        <mesh filename="assets/leaders/papras_7dof/link1.stl"/>
      </geometry>
    </collision>
  </link>
  <joint name="robot1/joint1" type="revolute">
    <origin rpy="1.5708 0 0" xyz="-0.000125 0.0022 0.099"/>
    <parent link="robot1/base_link"/>
    <child link="robot1/link1"/>
    <axis xyz="0 1 0"/>
    <limit effort="1" lower="-3.141592653589793" upper="3.141592653589793" velocity="3.15"/>
  </joint>
  <transmission name="robot1/tran1">
    <type>transmission_interface/SimpleTransmission</type>
    <joint name="robot1/joint1">
      <hardwareInterface>hardware_interface/EffortJointInterface</hardwareInterface>
    </joint>
    <actuator name="robot1/motor1">
      <mechanicalReduction>1</mechanicalReduction>
    </actuator>
  </transmission>
  <transmission name="robot1/tran1">
    <type>transmission_interface/SimpleTransmission</type>
    <joint name="robot1/joint1">
      <hardwareInterface>hardware_interface/PositionJointInterface</hardwareInterface>
    </joint>
    <actuator name="robot1/motor1">
      <mechanicalReduction>1</mechanicalReduction>
    </actuator>
  </transmission>
  <link name="robot1/link2">
    <inertial>
      <origin rpy="0 0 0" xyz="0.000147982716840395 0.00451319547209069 -0.097270560393635"/>
      <mass value="0.0814342847713924"/>
      <inertia ixx="0.000131496864514129" ixy="1.51737391008811E-18" ixz="-1.48295342475051E-08" iyy="0.00013588019621793" iyz="1.45299795458879E-05" izz="2.43781225621918E-05"/>
    </inertial>
    <visual>
      <origin rpy="0 0 0" xyz="0 0 0"/>
      <geometry>
        <mesh filename="assets/leaders/papras_7dof/link2.stl"/>
      </geometry>
      <material name="">
        <color rgba="0.792156862745098 0.819607843137255 0.933333333333333 1"/>
      </material>
    </visual>
    <collision>
      <origin rpy="0 0 0" xyz="0 0 0"/>
      <geometry>
        <mesh filename="assets/leaders/papras_7dof/link2.stl"/>
      </geometry>
    </collision>
  </link>
  <joint name="robot1/joint2" type="revolute">
    <origin rpy="3.1416 0 3.1416" xyz="0 0.029 0"/>
    <parent link="robot1/link1"/>
    <child link="robot1/link2"/>
    <axis xyz="0 0 -1"/>
    <limit effort="1" lower="-3.141592653589793" upper="3.141592653589793" velocity="3.15"/>
  </joint>
  <transmission name="robot1/tran2">
    <type>transmission_interface/SimpleTransmission</type>
    <joint name="robot1/joint2">
      <hardwareInterface>hardware_interface/EffortJointInterface</hardwareInterface>
    </joint>
    <actuator name="robot1/motor2">
      <mechanicalReduction>1</mechanicalReduction>
    </actuator>
  </transmission>
  <transmission name="robot1/tran2">
    <type>transmission_interface/SimpleTransmission</type>
    <joint name="robot1/joint2">
      <hardwareInterface>hardware_interface/PositionJointInterface</hardwareInterface>
    </joint>
    <actuator name="robot1/motor2">
      <mechanicalReduction>1</mechanicalReduction>
    </actuator>
  </transmission>
  <link name="robot1/link3">
    <inertial>
      <origin rpy="0 0 0" xyz="-0.0180594814950693 -1.63627658705211E-08 -0.0722877425230301"/>
      <mass value="0.0654267493288997"/>
      <inertia ixx="7.49414046149126E-05" ixy="3.98289349653685E-11" ixz="3.50441605989892E-06" iyy="7.99497837595888E-05" iyz="-5.50559303414792E-11" izz="1.63780078786181E-05"/>
    </inertial>
    <visual>
      <origin rpy="0 0 0" xyz="0 0 0"/>
      <geometry>
        <mesh filename="assets/leaders/papras_7dof/link3.stl"/>
      </geometry>
      <material name="">
        <color rgba="0.792156862745098 0.819607843137255 0.933333333333333 1"/>
      </material>
    </visual>
    <collision>
      <origin rpy="0 0 0" xyz="0 0 0"/>
      <geometry>
        <mesh filename="assets/leaders/papras_7dof/link3.stl"/>
      </geometry>
    </collision>
  </link>
  <joint name="robot1/joint3" type="revolute">
    <origin rpy="1.5708 1.5708 0" xyz="-0.0001 0.10079 0"/>
    <parent link="robot1/link2"/>
    <child link="robot1/link3"/>
    <axis xyz="0 0 -1"/>
    <limit effort="1" lower="-3.141592653589793" upper="3.141592653589793" velocity="3.15"/>
  </joint>
  <transmission name="robot1/tran3">
    <type>transmission_interface/SimpleTransmission</type>
    <joint name="robot1/joint3">
      <hardwareInterface>hardware_interface/EffortJointInterface</hardwareInterface>
    </joint>
    <actuator name="robot1/motor3">
      <mechanicalReduction>1</mechanicalReduction>
    </actuator>
  </transmission>
  <transmission name="robot1/tran3">
    <type>transmission_interface/SimpleTransmission</type>
    <joint name="robot1/joint3">
      <hardwareInterface>hardware_interface/PositionJointInterface</hardwareInterface>
    </joint>
    <actuator name="robot1/motor3">
      <mechanicalReduction>1</mechanicalReduction>
    </actuator>
  </transmission>
  <link name="robot1/link4">
    <inertial>
      <origin rpy="0 0 0" xyz="0.000447858160341448 -0.00117107937366287 -0.0280375991206876"/>
      <mass value="0.0269077999710614"/>
      <inertia ixx="3.93965337255511E-06" ixy="2.33053708688373E-15" ixz="-1.48295276394878E-08" iyy="4.44540833990355E-06" iyz="-1.58545336317713E-07" izz="3.49024355481955E-06"/>
    </inertial>
    <visual>
      <origin rpy="0 0 0" xyz="0 0 0"/>
      <geometry>
        <mesh filename="assets/leaders/papras_7dof/link4.stl"/>
      </geometry>
      <material name="">
        <color rgba="0.792156862745098 0.819607843137255 0.933333333333333 1"/>
      </material>
    </visual>
    <collision>
      <origin rpy="0 0 0" xyz="0 0 0"/>
      <geometry>
        <mesh filename="assets/leaders/papras_7dof/link4.stl"/>
      </geometry>
    </collision>
  </link>
  <joint name="robot1/joint4" type="revolute">
    <origin rpy="1.5708 -1.5708 0" xyz="0 0.01952 -0.070988"/>
    <parent link="robot1/link3"/>
    <child link="robot1/link4"/>
    <axis xyz="0 -1 0"/>
    <limit effort="1" lower="-3.141592653589793" upper="3.141592653589793" velocity="3.15"/>
  </joint>
  <transmission name="robot1/tran4">
    <type>transmission_interface/SimpleTransmission</type>
    <joint name="robot1/joint4">
      <hardwareInterface>hardware_interface/EffortJointInterface</hardwareInterface>
    </joint>
    <actuator name="robot1/motor4">
      <mechanicalReduction>1</mechanicalReduction>
    </actuator>
  </transmission>
  <transmission name="robot1/tran4">
    <type>transmission_interface/SimpleTransmission</type>
    <joint name="robot1/joint4">
      <hardwareInterface>hardware_interface/PositionJointInterface</hardwareInterface>
    </joint>
    <actuator name="robot1/motor4">
      <mechanicalReduction>1</mechanicalReduction>
    </actuator>
  </transmission>
  <link name="robot1/link5">
    <inertial>
      <origin rpy="0 0 0" xyz="-1.93174924667527E-09 0.0359667259162841 -0.00685952331822111"/>
      <mass value="0.0354352330271564"/>
      <inertia ixx="1.046584774501E-05" ixy="-8.1705364395442E-13" ixz="-2.6487940954783E-11" iyy="8.94432356070269E-06" iyz="3.1177092144739E-09" izz="4.68872581327118E-06"/>
    </inertial>
    <visual>
      <origin rpy="0 0 0" xyz="0 0 0"/>
      <geometry>
        <mesh filename="assets/leaders/papras_7dof/link5.stl"/>
      </geometry>
      <material name="">
        <color rgba="0.627450980392157 0.627450980392157 0.627450980392157 1"/>
      </material>
    </visual>
    <collision>
      <origin rpy="0 0 0" xyz="0 0 0"/>
      <geometry>
        <mesh filename="assets/leaders/papras_7dof/link5.stl"/>
      </geometry>
    </collision>
  </link>
  <joint name="robot1/joint5" type="revolute">
    <origin rpy="0 0 -1.5708" xyz="-0.01952 0 -0.12037"/>
    <parent link="robot1/link4"/>
    <child link="robot1/link5"/>
    <axis xyz="0 0 -1"/>
    <limit effort="1" lower="-3.141592653589793" upper="3.141592653589793" velocity="3.15"/>
  </joint>
  <transmission name="robot1/tran5">
    <type>transmission_interface/SimpleTransmission</type>
    <joint name="robot1/joint5">
      <hardwareInterface>hardware_interface/EffortJointInterface</hardwareInterface>
    </joint>
    <actuator name="robot1/motor5">
      <mechanicalReduction>1</mechanicalReduction>
    </actuator>
  </transmission>
  <transmission name="robot1/tran5">
    <type>transmission_interface/SimpleTransmission</type>
    <joint name="robot1/joint5">
      <hardwareInterface>hardware_interface/PositionJointInterface</hardwareInterface>
    </joint>
    <actuator name="robot1/motor5">
      <mechanicalReduction>1</mechanicalReduction>
    </actuator>
  </transmission>
  <link name="robot1/link6">
    <inertial>
      <origin rpy="0 0 0" xyz="-1.2083725686729E-08 -0.00604745156102854 -0.0534802275374367"/>
      <mass value="0.0465686690697251"/>
      <inertia ixx="1.046584774501E-05" ixy="-8.1705364395442E-13" ixz="-2.6487940954783E-11" iyy="8.94432356070269E-06" iyz="3.1177092144739E-09" izz="4.68872581327118E-06"/>
    </inertial>
    <visual>
      <origin rpy="0 0 0" xyz="0 0 0"/>
      <geometry>
        <mesh filename="assets/leaders/papras_7dof/link6.stl"/>
      </geometry>
      <material name="">
        <color rgba="0.627450980392157 0.627450980392157 0.627450980392157 1"/>
      </material>
    </visual>
    <collision>
      <origin rpy="0 0 0" xyz="0 0 0"/>
      <geometry>
        <mesh filename="assets/leaders/papras_7dof/link6.stl"/>
      </geometry>
    </collision>
  </link>
  <joint name="robot1/joint6" type="revolute">
    <origin rpy="0 0 1.5708" xyz="0 0 -0.0475000000000001"/>
    <parent link="robot1/link5"/>
    <child link="robot1/link6"/>
    <axis xyz="0 -1 0"/>
    <limit effort="1" lower="-3.141592653589793" upper="3.141592653589793" velocity="3.15"/>
  </joint>
  <transmission name="robot1/tran6">
    <type>transmission_interface/SimpleTransmission</type>
    <joint name="robot1/joint6">
      <hardwareInterface>hardware_interface/EffortJointInterface</hardwareInterface>
    </joint>
    <actuator name="robot1/motor6">
      <mechanicalReduction>1</mechanicalReduction>
    </actuator>
  </transmission>
  <transmission name="robot1/tran6">
    <type>transmission_interface/SimpleTransmission</type>
    <joint name="robot1/joint6">
      <hardwareInterface>hardware_interface/PositionJointInterface</hardwareInterface>
    </joint>
    <actuator name="robot1/motor6">
      <mechanicalReduction>1</mechanicalReduction>
    </actuator>
  </transmission>
  <link name="robot1/handle">
    <inertial>
      <origin rpy="0 0 0" xyz="-0.0269504648321372 -0.000444552753820911 0.00944823169908937"/>
      <mass value="0.0792318961261061"/>
      <inertia ixx="3.30813970525119E-05" ixy="1.1856468521745E-05" ixz="8.98678207145682E-07" iyy="3.49786415297126E-05" iyz="-5.09722128514016E-07" izz="5.60466661401102E-05"/>
    </inertial>
    <visual>
      <origin rpy="0 0 0" xyz="0 0 0"/>
      <geometry>
        <mesh filename="assets/leaders/handle.stl"/>
      </geometry>
      <material name="">
        <color rgba="0.792156862745098 0.819607843137255 0.933333333333333 1"/>
      </material>
    </visual>
    <collision>
      <origin rpy="0 0 0" xyz="0.01 0 0"/>
      <geometry>
        <mesh filename="assets/leaders/handle.stl"/>
      </geometry>
    </collision>
  </link>
  <joint name="robot1/joint7" type="revolute">
    <origin rpy="3.141592653589793 0.05236 1.576" xyz="0 1E-05 -0.076464"/>
    <parent link="robot1/link6"/>
    <child link="robot1/handle"/>
    <axis xyz="0.052336 0 0.99863"/>
    <limit effort="1" lower="-3.141592653589793" upper="3.141592653589793" velocity="3.15"/>
  </joint>
  <transmission name="robot1/tran7">
    <type>transmission_interface/SimpleTransmission</type>
    <joint name="robot1/joint7">
      <hardwareInterface>hardware_interface/EffortJointInterface</hardwareInterface>
    </joint>
    <actuator name="robot1/motor7">
      <mechanicalReduction>1</mechanicalReduction>
    </actuator>
  </transmission>
  <transmission name="robot1/tran7">
    <type>transmission_interface/SimpleTransmission</type>
    <joint name="robot1/joint7">
      <hardwareInterface>hardware_interface/PositionJointInterface</hardwareInterface>
    </joint>
    <actuator name="robot1/motor7">
      <mechanicalReduction>1</mechanicalReduction>
    </actuator>
  </transmission>
  
  <joint name="robot1/end_effector_joint" type="fixed">
    <parent link="robot1/handle"/>
    <child link="robot1/end_effector_link"/>
    <origin rpy="0 -1.57 1.57" xyz="0.0 0.0 0.0" />
  </joint>
  <link name="robot1/end_effector_link">
    <visual>
      <origin rpy="0 0 0" xyz="0.0 0.0 0.0"/>
      <geometry>
        <box size="0.01 0.01 0.01"/>
      </geometry>
      <material name="red"/>
    </visual>
    <!-- <collision>
        <origin xyz="0.0 0.0 0.0" rpy="0 0 0" />
        <geometry>
          <box size = "0.01 0.01 0.01"/>
        </geometry>
        <material name="red"/>
      </collision> -->
    <inertial>
      <origin rpy="0 0 0" xyz="0.0 0.0 0.0"/>
      <mass value="0.001"/>
      <inertia ixx="1.0" ixy="0.0" ixz="0.0" iyy="1.0" iyz="0.0" izz="1.0"/>
    </inertial>
  </link>
  <link name="robot1/trigger">
    <inertial>
      <origin rpy="0 0 0" xyz="0.0050484710643748 0.00657608716575382 0.0232192535585892"/>
      <mass value="0.0113373798119285"/>
      <inertia ixx="2.72836346546105E-06" ixy="7.0874539112887E-08" ixz="-2.27358946603912E-07" iyy="2.534724795085E-06" iyz="3.84763852522776E-07" izz="8.0196735325128E-07"/>
    </inertial>
    <visual>
      <origin rpy="0 0 0" xyz="0 0 0"/>
      <geometry>
        <mesh filename="assets/leaders/trigger.stl"/>
      </geometry>
      <material name="">
        <color rgba="0.792156862745098 0.819607843137255 0.933333333333333 1"/>
      </material>
    </visual>
    <collision>
      <origin rpy="0 0 0" xyz="0 0 0"/>
      <geometry>
        <mesh filename="assets/leaders/trigger.stl"/>
      </geometry>
    </collision>
  </link>
  <joint name="robot1/gripper" type="revolute">
    <origin rpy="0.0 0 0.000" xyz="0.0154268 0 0.0226837"/>
    <parent link="robot1/handle"/>
    <child link="robot1/trigger"/>
    <axis xyz="0 -1 0"/>
    <limit effort="1" lower="0" upper="1.2" velocity="3.15"/>
  </joint>
  
  <transmission name="robot1/trangripper">
    <type>transmission_interface/SimpleTransmission</type>
    <joint name="robot1/gripper">
      <hardwareInterface>hardware_interface/EffortJointInterface</hardwareInterface>
    </joint>
    <actuator name="robot1/motorgripper">
      <mechanicalReduction>1</mechanicalReduction>
    </actuator>
  </transmission>
  <transmission name="robot1/trangripper">
    <type>transmission_interface/SimpleTransmission</type>
    <joint name="robot1/gripper">
      <hardwareInterface>hardware_interface/PositionJointInterface</hardwareInterface>
    </joint>
    <actuator name="robot1/motorgripper">
      <mechanicalReduction>1</mechanicalReduction>
    </actuator>
  </transmission>
  <link name="robot2/base_link">
    <inertial>
      <origin rpy="0 0 0" xyz="-1.88052088812657E-05 -0.00215271082064172 0.0441443392060522"/>
      <mass value="0.218376911489293"/>
      <inertia ixx="0.000160297084827002" ixy="1.06759566549485E-08" ixz="-4.82637621739845E-08" iyy="0.000190111291063554" iyz="-5.70875681133123E-06" izz="9.3344618631843E-05"/>
    </inertial>
    <visual>
      <origin rpy="0 0 0" xyz="0 0 0"/>
      <geometry>
        <mesh filename="assets/leaders/base_link.stl"/>
      </geometry>
      <material name="">
        <color rgba="0.752941176470588 0.752941176470588 0.752941176470588 1"/>
      </material>
    </visual>
    <collision>
      <origin rpy="0 0 0" xyz="0 0 0"/>
      <geometry>
        <mesh filename="assets/leaders/base_link.stl"/>
      </geometry>
    </collision>
  </link>
  <link name="robot2/link1">
    <inertial>
      <origin rpy="0 0 0" xyz="8.03381307583049E-16 0.0183891548632449 -0.00065273513210628"/>
      <mass value="0.0184621083060345"/>
      <inertia ixx="2.40713355161292E-06" ixy="-2.72793224052933E-21" ixz="1.89321316204573E-15" iyy="1.52798370468232E-06" iyz="-1.482953424559E-08" izz="2.03767449056785E-06"/>
    </inertial>
    <visual>
      <origin rpy="0 0 0" xyz="0 0 0"/>
      <geometry>
        <mesh filename="assets/leaders/papras_7dof/link1.stl"/>
      </geometry>
      <material name="">
        <color rgba="0.627450980392157 0.627450980392157 0.627450980392157 1"/>
      </material>
    </visual>
    <collision>
      <origin rpy="0 0 0" xyz="0 0 0"/>
      <geometry>
        <mesh filename="assets/leaders/papras_7dof/link1.stl"/>
      </geometry>
    </collision>
  </link>
  <joint name="robot2/joint1" type="revolute">
    <origin rpy="1.5708 0 0" xyz="-0.000125 0.0022 0.099"/>
    <parent link="robot2/base_link"/>
    <child link="robot2/link1"/>
    <axis xyz="0 1 0"/>
    <limit effort="1" lower="-3.141592653589793" upper="3.141592653589793" velocity="3.15"/>
  </joint>
  <transmission name="robot2/tran1">
    <type>transmission_interface/SimpleTransmission</type>
    <joint name="robot2/joint1">
      <hardwareInterface>hardware_interface/EffortJointInterface</hardwareInterface>
    </joint>
    <actuator name="robot2/motor1">
      <mechanicalReduction>1</mechanicalReduction>
    </actuator>
  </transmission>
  <transmission name="robot2/tran1">
    <type>transmission_interface/SimpleTransmission</type>
    <joint name="robot2/joint1">
      <hardwareInterface>hardware_interface/PositionJointInterface</hardwareInterface>
    </joint>
    <actuator name="robot2/motor1">
      <mechanicalReduction>1</mechanicalReduction>
    </actuator>
  </transmission>
  <link name="robot2/link2">
    <inertial>
      <origin rpy="0 0 0" xyz="0.000147982716840395 0.00451319547209069 -0.097270560393635"/>
      <mass value="0.0814342847713924"/>
      <inertia ixx="0.000131496864514129" ixy="1.51737391008811E-18" ixz="-1.48295342475051E-08" iyy="0.00013588019621793" iyz="1.45299795458879E-05" izz="2.43781225621918E-05"/>
    </inertial>
    <visual>
      <origin rpy="0 0 0" xyz="0 0 0"/>
      <geometry>
        <mesh filename="assets/leaders/papras_7dof/link2.stl"/>
      </geometry>
      <material name="">
        <color rgba="0.792156862745098 0.819607843137255 0.933333333333333 1"/>
      </material>
    </visual>
    <collision>
      <origin rpy="0 0 0" xyz="0 0 0"/>
      <geometry>
        <mesh filename="assets/leaders/papras_7dof/link2.stl"/>
      </geometry>
    </collision>
  </link>
  <joint name="robot2/joint2" type="revolute">
    <origin rpy="3.1416 0 3.1416" xyz="0 0.029 0"/>
    <parent link="robot2/link1"/>
    <child link="robot2/link2"/>
    <axis xyz="0 0 -1"/>
    <limit effort="1" lower="-3.141592653589793" upper="3.141592653589793" velocity="3.15"/>
  </joint>
  <transmission name="robot2/tran2">
    <type>transmission_interface/SimpleTransmission</type>
    <joint name="robot2/joint2">
      <hardwareInterface>hardware_interface/EffortJointInterface</hardwareInterface>
    </joint>
    <actuator name="robot2/motor2">
      <mechanicalReduction>1</mechanicalReduction>
    </actuator>
  </transmission>
  <transmission name="robot2/tran2">
    <type>transmission_interface/SimpleTransmission</type>
    <joint name="robot2/joint2">
      <hardwareInterface>hardware_interface/PositionJointInterface</hardwareInterface>
    </joint>
    <actuator name="robot2/motor2">
      <mechanicalReduction>1</mechanicalReduction>
    </actuator>
  </transmission>
  <link name="robot2/link3">
    <inertial>
      <origin rpy="0 0 0" xyz="-0.0180594814950693 -1.63627658705211E-08 -0.0722877425230301"/>
      <mass value="0.0654267493288997"/>
      <inertia ixx="7.49414046149126E-05" ixy="3.98289349653685E-11" ixz="3.50441605989892E-06" iyy="7.99497837595888E-05" iyz="-5.50559303414792E-11" izz="1.63780078786181E-05"/>
    </inertial>
    <visual>
      <origin rpy="0 0 0" xyz="0 0 0"/>
      <geometry>
        <mesh filename="assets/leaders/papras_7dof/link3.stl"/>
      </geometry>
      <material name="">
        <color rgba="0.792156862745098 0.819607843137255 0.933333333333333 1"/>
      </material>
    </visual>
    <collision>
      <origin rpy="0 0 0" xyz="0 0 0"/>
      <geometry>
        <mesh filename="assets/leaders/papras_7dof/link3.stl"/>
      </geometry>
    </collision>
  </link>
  <joint name="robot2/joint3" type="revolute">
    <origin rpy="1.5708 1.5708 0" xyz="-0.0001 0.10079 0"/>
    <parent link="robot2/link2"/>
    <child link="robot2/link3"/>
    <axis xyz="0 0 -1"/>
    <limit effort="1" lower="-3.141592653589793" upper="3.141592653589793" velocity="3.15"/>
  </joint>
  <transmission name="robot2/tran3">
    <type>transmission_interface/SimpleTransmission</type>
    <joint name="robot2/joint3">
      <hardwareInterface>hardware_interface/EffortJointInterface</hardwareInterface>
    </joint>
    <actuator name="robot2/motor3">
      <mechanicalReduction>1</mechanicalReduction>
    </actuator>
  </transmission>
  <transmission name="robot2/tran3">
    <type>transmission_interface/SimpleTransmission</type>
    <joint name="robot2/joint3">
      <hardwareInterface>hardware_interface/PositionJointInterface</hardwareInterface>
    </joint>
    <actuator name="robot2/motor3">
      <mechanicalReduction>1</mechanicalReduction>
    </actuator>
  </transmission>
  <link name="robot2/link4">
    <inertial>
      <origin rpy="0 0 0" xyz="0.000447858160341448 -0.00117107937366287 -0.0280375991206876"/>
      <mass value="0.0269077999710614"/>
      <inertia ixx="3.93965337255511E-06" ixy="2.33053708688373E-15" ixz="-1.48295276394878E-08" iyy="4.44540833990355E-06" iyz="-1.58545336317713E-07" izz="3.49024355481955E-06"/>
    </inertial>
    <visual>
      <origin rpy="0 0 0" xyz="0 0 0"/>
      <geometry>
        <mesh filename="assets/leaders/papras_7dof/link4.stl"/>
      </geometry>
      <material name="">
        <color rgba="0.792156862745098 0.819607843137255 0.933333333333333 1"/>
      </material>
    </visual>
    <collision>
      <origin rpy="0 0 0" xyz="0 0 0"/>
      <geometry>
        <mesh filename="assets/leaders/papras_7dof/link4.stl"/>
      </geometry>
    </collision>
  </link>
  <joint name="robot2/joint4" type="revolute">
    <origin rpy="1.5708 -1.5708 0" xyz="0 0.01952 -0.070988"/>
    <parent link="robot2/link3"/>
    <child link="robot2/link4"/>
    <axis xyz="0 -1 0"/>
    <limit effort="1" lower="-3.141592653589793" upper="3.141592653589793" velocity="3.15"/>
  </joint>
  <transmission name="robot2/tran4">
    <type>transmission_interface/SimpleTransmission</type>
    <joint name="robot2/joint4">
      <hardwareInterface>hardware_interface/EffortJointInterface</hardwareInterface>
    </joint>
    <actuator name="robot2/motor4">
      <mechanicalReduction>1</mechanicalReduction>
    </actuator>
  </transmission>
  <transmission name="robot2/tran4">
    <type>transmission_interface/SimpleTransmission</type>
    <joint name="robot2/joint4">
      <hardwareInterface>hardware_interface/PositionJointInterface</hardwareInterface>
    </joint>
    <actuator name="robot2/motor4">
      <mechanicalReduction>1</mechanicalReduction>
    </actuator>
  </transmission>
  <link name="robot2/link5">
    <inertial>
      <origin rpy="0 0 0" xyz="-1.93174924667527E-09 0.0359667259162841 -0.00685952331822111"/>
      <mass value="0.0354352330271564"/>
      <inertia ixx="1.046584774501E-05" ixy="-8.1705364395442E-13" ixz="-2.6487940954783E-11" iyy="8.94432356070269E-06" iyz="3.1177092144739E-09" izz="4.68872581327118E-06"/>
    </inertial>
    <visual>
      <origin rpy="0 0 0" xyz="0 0 0"/>
      <geometry>
        <mesh filename="assets/leaders/papras_7dof/link5.stl"/>
      </geometry>
      <material name="">
        <color rgba="0.627450980392157 0.627450980392157 0.627450980392157 1"/>
      </material>
    </visual>
    <collision>
      <origin rpy="0 0 0" xyz="0 0 0"/>
      <geometry>
        <mesh filename="assets/leaders/papras_7dof/link5.stl"/>
      </geometry>
    </collision>
  </link>
  <joint name="robot2/joint5" type="revolute">
    <origin rpy="0 0 -1.5708" xyz="-0.01952 0 -0.12037"/>
    <parent link="robot2/link4"/>
    <child link="robot2/link5"/>
    <axis xyz="0 0 -1"/>
    <limit effort="1" lower="-3.141592653589793" upper="3.141592653589793" velocity="3.15"/>
  </joint>
  <transmission name="robot2/tran5">
    <type>transmission_interface/SimpleTransmission</type>
    <joint name="robot2/joint5">
      <hardwareInterface>hardware_interface/EffortJointInterface</hardwareInterface>
    </joint>
    <actuator name="robot2/motor5">
      <mechanicalReduction>1</mechanicalReduction>
    </actuator>
  </transmission>
  <transmission name="robot2/tran5">
    <type>transmission_interface/SimpleTransmission</type>
    <joint name="robot2/joint5">
      <hardwareInterface>hardware_interface/PositionJointInterface</hardwareInterface>
    </joint>
    <actuator name="robot2/motor5">
      <mechanicalReduction>1</mechanicalReduction>
    </actuator>
  </transmission>
  <link name="robot2/link6">
    <inertial>
      <origin rpy="0 0 0" xyz="-1.2083725686729E-08 -0.00604745156102854 -0.0534802275374367"/>
      <mass value="0.0465686690697251"/>
      <inertia ixx="1.046584774501E-05" ixy="-8.1705364395442E-13" ixz="-2.6487940954783E-11" iyy="8.94432356070269E-06" iyz="3.1177092144739E-09" izz="4.68872581327118E-06"/>
    </inertial>
    <visual>
      <origin rpy="0 0 0" xyz="0 0 0"/>
      <geometry>
        <mesh filename="assets/leaders/papras_7dof/link6.stl"/>
      </geometry>
      <material name="">
        <color rgba="0.627450980392157 0.627450980392157 0.627450980392157 1"/>
      </material>
    </visual>
    <collision>
      <origin rpy="0 0 0" xyz="0 0 0"/>
      <geometry>
        <mesh filename="assets/leaders/papras_7dof/link6.stl"/>
      </geometry>
    </collision>
  </link>
  <joint name="robot2/joint6" type="revolute">
    <origin rpy="0 0 1.5708" xyz="0 0 -0.0475000000000001"/>
    <parent link="robot2/link5"/>
    <child link="robot2/link6"/>
    <axis xyz="0 -1 0"/>
    <limit effort="1" lower="-3.141592653589793" upper="3.141592653589793" velocity="3.15"/>
  </joint>
  <transmission name="robot2/tran6">
    <type>transmission_interface/SimpleTransmission</type>
    <joint name="robot2/joint6">
      <hardwareInterface>hardware_interface/EffortJointInterface</hardwareInterface>
    </joint>
    <actuator name="robot2/motor6">
      <mechanicalReduction>1</mechanicalReduction>
    </actuator>
  </transmission>
  <transmission name="robot2/tran6">
    <type>transmission_interface/SimpleTransmission</type>
    <joint name="robot2/joint6">
      <hardwareInterface>hardware_interface/PositionJointInterface</hardwareInterface>
    </joint>
    <actuator name="robot2/motor6">
      <mechanicalReduction>1</mechanicalReduction>
    </actuator>
  </transmission>
  <link name="robot2/handle">
    <inertial>
      <origin rpy="0 0 0" xyz="-0.0269504648321372 -0.000444552753820911 0.00944823169908937"/>
      <mass value="0.0792318961261061"/>
      <inertia ixx="3.30813970525119E-05" ixy="1.1856468521745E-05" ixz="8.98678207145682E-07" iyy="3.49786415297126E-05" iyz="-5.09722128514016E-07" izz="5.60466661401102E-05"/>
    </inertial>
    <visual>
      <origin rpy="0 0 0" xyz="0 0 0"/>
      <geometry>
        <mesh filename="assets/leaders/handle.stl"/>
      </geometry>
      <material name="">
        <color rgba="0.792156862745098 0.819607843137255 0.933333333333333 1"/>
      </material>
    </visual>
    <collision>
      <origin rpy="0 0 0" xyz="0.01 0 0"/>
      <geometry>
        <mesh filename="assets/leaders/handle.stl"/>
      </geometry>
    </collision>
  </link>
  <joint name="robot2/joint7" type="revolute">
    <origin rpy="3.141592653589793 0.05236 1.576" xyz="0 1E-05 -0.076464"/>
    <parent link="robot2/link6"/>
    <child link="robot2/handle"/>
    <axis xyz="0.052336 0 0.99863"/>
    <limit effort="1" lower="-3.141592653589793" upper="3.141592653589793" velocity="3.15"/>
  </joint>
  <transmission name="robot2/tran7">
    <type>transmission_interface/SimpleTransmission</type>
    <joint name="robot2/joint7">
      <hardwareInterface>hardware_interface/EffortJointInterface</hardwareInterface>
    </joint>
    <actuator name="robot2/motor7">
      <mechanicalReduction>1</mechanicalReduction>
    </actuator>
  </transmission>
  <transmission name="robot2/tran7">
    <type>transmission_interface/SimpleTransmission</type>
    <joint name="robot2/joint7">
      <hardwareInterface>hardware_interface/PositionJointInterface</hardwareInterface>
    </joint>
    <actuator name="robot2/motor7">
      <mechanicalReduction>1</mechanicalReduction>
    </actuator>
  </transmission>
  
    <joint name="robot2/end_effector_joint" type="fixed">
    <parent link="robot2/handle"/>
    <child link="robot2/end_effector_link"/>
    <origin rpy="0 -1.57 1.57" xyz="0.0 0.0 0.0" />
  </joint>
  <link name="robot2/end_effector_link">
    <visual>
      <origin rpy="0 0 0" xyz="0.0 0.0 0.0"/>
      <geometry>
        <box size="0.01 0.01 0.01"/>
      </geometry>
      <material name="red"/>
    </visual>
    <!-- <collision>
        <origin xyz="0.0 0.0 0.0" rpy="0 0 0" />
        <geometry>
          <box size = "0.01 0.01 0.01"/>
        </geometry>
        <material name="red"/>
      </collision> -->
    <inertial>
      <origin rpy="0 0 0" xyz="0.0 0.0 0.0"/>
      <mass value="0.001"/>
      <inertia ixx="1.0" ixy="0.0" ixz="0.0" iyy="1.0" iyz="0.0" izz="1.0"/>
    </inertial>
  </link>
  
  <link name="robot2/trigger">
    <inertial>
      <origin rpy="0 0 0" xyz="0.0050484710643748 0.00657608716575382 0.0232192535585892"/>
      <mass value="0.0113373798119285"/>
      <inertia ixx="2.72836346546105E-06" ixy="7.0874539112887E-08" ixz="-2.27358946603912E-07" iyy="2.534724795085E-06" iyz="3.84763852522776E-07" izz="8.0196735325128E-07"/>
    </inertial>
    <visual>
      <origin rpy="0 0 0" xyz="0 0 0"/>
      <geometry>
        <mesh filename="assets/leaders/trigger.stl"/>
      </geometry>
      <material name="">
        <color rgba="0.792156862745098 0.819607843137255 0.933333333333333 1"/>
      </material>
    </visual>
    <collision>
      <origin rpy="0 0 0" xyz="0 0 0"/>
      <geometry>
        <mesh filename="assets/leaders/trigger.stl"/>
      </geometry>
    </collision>
  </link>
  <joint name="robot2/gripper" type="revolute">
    <origin rpy="0.0 0 0.000" xyz="0.0154268 0 0.0226837"/>
    <parent link="robot2/handle"/>
    <child link="robot2/trigger"/>
    <axis xyz="0 -1 0"/>
    <limit effort="1" lower="0" upper="1.2" velocity="3.15"/>
  </joint>
  <transmission name="robot2/trangripper">
    <type>transmission_interface/SimpleTransmission</type>
    <joint name="robot2/gripper">
      <hardwareInterface>hardware_interface/EffortJointInterface</hardwareInterface>
    </joint>
    <actuator name="robot2/motorgripper">
      <mechanicalReduction>1</mechanicalReduction>
    </actuator>
  </transmission>
  <transmission name="robot2/trangripper">
    <type>transmission_interface/SimpleTransmission</type>
    <joint name="robot2/gripper">
      <hardwareInterface>hardware_interface/PositionJointInterface</hardwareInterface>
    </joint>
    <actuator name="robot2/motorgripper">
      <mechanicalReduction>1</mechanicalReduction>
    </actuator>
  </transmission>
  <!-- <xacro:ur5_leader id="1"/> -->
</robot>


