<?xml version="1.0" ?>
<!-- =================================================================================== -->
<!-- |    This document was autogenerated by xacro from leader_ur5.urdf.xacro          | -->
<!-- |    EDITING THIS FILE BY HAND IS NOT RECOMMENDED                                 | -->
<!-- =================================================================================== -->
<robot name="papras_leaders">
    <mujoco>
       <compiler angle="radian" meshdir="../" autolimits="true" strippath="false" fusestatic="false"/>
       <include file="scene/floor_sky.xml" />
    </mujoco>
  <!-- PAPRAS URDF Macros -->
  <!-- Main URDF File should contain
        - world link
        - world-env joint
        - env link
        - env-robotn/link1 joint for each mount -->
  <!-- This file contains URDF geometry, transmission data and Gazebo references -->
  <material name="black">
    <color rgba="0.0 0.0 0.0 1.0"/>
  </material>
  <material name="blue">
    <color rgba="0.0 0.0 0.8 1.0"/>
  </material>
  <material name="green">
    <color rgba="0.0 0.8 0.0 1.0"/>
  </material>
  <material name="grey">
    <color rgba="0.5 0.5 0.5 1.0"/>
  </material>
  <material name="orange">
    <color rgba="1.0 0.4235294117647059 0.0392156862745098 1.0"/>
  </material>
  <material name="brown">
    <color rgba="0.8705882352941177 0.8117647058823529 0.7647058823529411 1.0"/>
  </material>
  <material name="red">
    <color rgba="0.8 0.0 0.0 1.0"/>
  </material>
  <material name="white">
    <color rgba="1.0 1.0 1.0 1.0"/>
  </material>
  <!-- Import all Gazebo-customization elements, including Gazebo colors -->
  <!-- World -->
  <gazebo reference="world"/>
  <!-- Evn Link -->
  <gazebo reference="env"/>
  <!-- ros_control plugin -->
  <link name="world"/>
  <joint name="robot1/world_joint" type="fixed">
    <origin rpy="0 0 0" xyz="0.2599 0.33455 -0.05189"/>
    <parent link="world"/>
    <child link="robot1/base_link"/>
    <axis xyz="0 0 0"/>
  </joint>
  <link name="robot1/base_link">
    <inertial>
      <origin rpy="0 0 0" xyz="-1.88052088812657E-05 -0.00215271082064172 0.0441443392060522"/>
      <mass value="0.218376911489293"/>
      <inertia ixx="0.000160297084827002" ixy="1.06759566549485E-08" ixz="-4.82637621739845E-08" iyy="0.000190111291063554" iyz="-5.70875681133123E-06" izz="9.3344618631843E-05"/>
    </inertial>
    <visual>
      <origin rpy="0 0 0" xyz="0 0 0"/>
      <geometry>
        <mesh filename="assets/leaders/base_link.stl"/>
      </geometry>
      <material name="">
        <color rgba="0.752941176470588 0.752941176470588 0.752941176470588 1"/>
      </material>
    </visual>
    <collision>
      <origin rpy="0 0 0" xyz="0 0 0"/>
      <geometry>
        <mesh filename="assets/leaders/base_link.stl"/>
      </geometry>
    </collision>
  </link>
  <link name="robot1/link1">
    <inertial>
      <origin rpy="0 0 0" xyz="0.0148795119058397 -0.0192918546044606 -5.81797288082275E-07"/>
      <mass value="0.041336"/>
      <inertia ixx="7.1216E-06" ixy="-2.4776E-06" ixz="-1.4797E-10" iyy="1.2151E-05" iyz="7.5415E-11" izz="1.4757E-05"/>
    </inertial>
    <visual>
      <origin rpy="0 0 0" xyz="0 0 0"/>
      <geometry>
        <mesh filename="assets/leaders/ur5/link1.stl"/>
      </geometry>
      <material name="">
        <color rgba="0.79216 0.81961 0.93333 1"/>
      </material>
    </visual>
    <collision>
      <origin rpy="0 0 0" xyz="0 0 0"/>
      <geometry>
        <mesh filename="assets/leaders/ur5/link1.stl"/>
      </geometry>
    </collision>
  </link>
  <joint name="robot1/joint1" type="revolute">
    <origin rpy="-1.5707963267949 0 -1.5707963267949" xyz="-0.000125 0.0 0.099"/>
    <parent link="robot1/base_link"/>
    <child link="robot1/link1"/>
    <axis xyz="0 1 0"/>
    <limit effort="1" lower="-3.141592653589793" upper="3.141592653589793" velocity="3.15"/>
  </joint>
  <transmission name="robot1/tran1">
    <type>transmission_interface/SimpleTransmission</type>
    <joint name="robot1/joint1">
      <hardwareInterface>hardware_interface/EffortJointInterface</hardwareInterface>
    </joint>
    <actuator name="robot1/motor1">
      <mechanicalReduction>1</mechanicalReduction>
    </actuator>
  </transmission>
  <transmission name="robot1/tran1">
    <type>transmission_interface/SimpleTransmission</type>
    <joint name="robot1/joint1">
      <hardwareInterface>hardware_interface/PositionJointInterface</hardwareInterface>
    </joint>
    <actuator name="robot1/motor1">
      <mechanicalReduction>1</mechanicalReduction>
    </actuator>
  </transmission>
  <link name="robot1/link2">
    <inertial>
      <origin rpy="0 0 0" xyz="0.108251385472162 -1.58317230034011E-07 -0.0202158550740865"/>
      <mass value="0.160618812979298"/>
      <inertia ixx="1.76671350322107E-05" ixy="4.87568646451885E-10" ixz="-5.51581332832345E-09" iyy="0.000472063875264355" iyz="-1.98620293993225E-11" izz="0.000475235516433241"/>
    </inertial>
    <visual>
      <origin rpy="0 0 0" xyz="0 0 0"/>
      <geometry>
        <mesh filename="assets/leaders/ur5/link2.stl"/>
      </geometry>
      <material name="">
        <color rgba="0.792156862745098 0.819607843137255 0.933333333333333 1"/>
      </material>
    </visual>
    <collision>
      <origin rpy="0 0 0" xyz="0 0 0"/>
      <geometry>
        <mesh filename="assets/leaders/ur5/link2.stl"/>
      </geometry>
    </collision>
  </link>
  <joint name="robot1/joint2" type="revolute">
    <origin rpy="1.5707963267949 0 -1.5707963267949" xyz="0.0414999985951312 -0.0215795005865017 0"/>
    <parent link="robot1/link1"/>
    <child link="robot1/link2"/>
    <axis xyz="0 0 1"/>
    <limit effort="1" lower="-3.141592653589793" upper="3.141592653589793" velocity="3.15"/>
  </joint>
  
        SimpleTransmissionPosition
        
  <transmission name="robot1/tran2">
    <type>transmission_interface/SimpleTransmission</type>
    <joint name="robot1/joint2">
      <hardwareInterface>hardware_interface/EffortJointInterface</hardwareInterface>
    </joint>
    <actuator name="robot1/motor2">
      <mechanicalReduction>1</mechanicalReduction>
    </actuator>
  </transmission>
  <transmission name="robot1/tran2">
    <type>transmission_interface/SimpleTransmission</type>
    <joint name="robot1/joint2">
      <hardwareInterface>hardware_interface/PositionJointInterface</hardwareInterface>
    </joint>
    <actuator name="robot1/motor2">
      <mechanicalReduction>1</mechanicalReduction>
    </actuator>
  </transmission>
  <link name="robot1/link3">
    <inertial>
      <origin rpy="0 0 0" xyz="-0.0316552462456164 -9.12590103555044E-07 -0.0848518601257323"/>
      <mass value="0.198785091752452"/>
      <inertia ixx="0.000635320734986975" ixy="8.4703815473395E-12" ixz="-3.95444251161434E-05" iyy="0.000644635318996104" iyz="-1.13198040132376E-09" izz="3.89817699987472E-05"/>
    </inertial>
    <visual>
      <origin rpy="0 0 0" xyz="0 0 0"/>
      <geometry>
        <mesh filename="assets/leaders/ur5/link3.stl"/>
      </geometry>
      <material name="">
        <color rgba="0.792156862745098 0.819607843137255 0.933333333333333 1"/>
      </material>
    </visual>
    <collision>
      <origin rpy="0 0 0" xyz="0 0 0"/>
      <geometry>
        <mesh filename="assets/leaders/ur5/link3.stl"/>
      </geometry>
    </collision>
  </link>
  <joint name="robot1/joint3" type="revolute">
    <origin rpy="3.14159238166912 1.5707963267949 0" xyz="0.216500001566666 0 0"/>
    <parent link="robot1/link2"/>
    <child link="robot1/link3"/>
    <axis xyz="1 0 0"/>
    <limit effort="1" lower="-3.141592653589793" upper="3.141592653589793" velocity="3.15"/>
  </joint>
  <transmission name="robot1/tran3">
    <type>transmission_interface/SimpleTransmission</type>
    <joint name="robot1/joint3">
      <hardwareInterface>hardware_interface/EffortJointInterface</hardwareInterface>
    </joint>
    <actuator name="robot1/motor3">
      <mechanicalReduction>1</mechanicalReduction>
    </actuator>
  </transmission>
  <transmission name="robot1/tran3">
    <type>transmission_interface/SimpleTransmission</type>
    <joint name="robot1/joint3">
      <hardwareInterface>hardware_interface/PositionJointInterface</hardwareInterface>
    </joint>
    <actuator name="robot1/motor3">
      <mechanicalReduction>1</mechanicalReduction>
    </actuator>
  </transmission>
  <link name="robot1/link4">
    <inertial>
      <origin rpy="0 0 0" xyz="0 0 0"/>
      <mass value="0.0355248600002842"/>
      <inertia ixx="4.47169794900115E-06" ixy="-1.20265785212545E-06" ixz="6.31952197550041E-11" iyy="6.92482483714141E-06" iyz="1.44458901552048E-11" izz="7.58542259681121E-06"/>
    </inertial>
    <visual>
      <origin rpy="0 0 0" xyz="0 0 0"/>
      <geometry>
        <mesh filename="assets/leaders/ur5/link4.stl"/>
      </geometry>
      <material name="">
        <color rgba="0.792156862745098 0.819607843137255 0.933333333333333 1"/>
      </material>
    </visual>
    <collision>
      <origin rpy="0 0 0" xyz="0 0 0"/>
      <geometry>
        <mesh filename="assets/leaders/ur5/link4.stl"/>
      </geometry>
    </collision>
  </link>
  <joint name="robot1/joint4" type="revolute">
    <origin rpy="-1.5708 0 0" xyz="0.003 0 -0.196500001566666"/>
    <parent link="robot1/link3"/>
    <child link="robot1/link4"/>
    <axis xyz="1 0 0"/>
    <limit effort="1" lower="-3.141592653589793" upper="3.141592653589793" velocity="3.15"/>
  </joint>
  <transmission name="robot1/tran4">
    <type>transmission_interface/SimpleTransmission</type>
    <joint name="robot1/joint4">
      <hardwareInterface>hardware_interface/EffortJointInterface</hardwareInterface>
    </joint>
    <actuator name="robot1/motor4">
      <mechanicalReduction>1</mechanicalReduction>
    </actuator>
  </transmission>
  <transmission name="robot1/tran4">
    <type>transmission_interface/SimpleTransmission</type>
    <joint name="robot1/joint4">
      <hardwareInterface>hardware_interface/PositionJointInterface</hardwareInterface>
    </joint>
    <actuator name="robot1/motor4">
      <mechanicalReduction>1</mechanicalReduction>
    </actuator>
  </transmission>
  <link name="robot1/link5">
    <inertial>
      <origin rpy="0 0 0" xyz="0.0102587015573597 8.51173093480151E-07 -0.00137103417583417"/>
      <mass value="0.0293815071396338"/>
      <inertia ixx="3.57750484672151E-06" ixy="8.59800621237349E-11" ixz="-8.13508959894672E-07" iyy="5.51370306313873E-06" iyz="-8.45800360650432E-12" izz="5.1907065270068E-06"/>
    </inertial>
    <visual>
      <origin rpy="0 0 0" xyz="0 0 0"/>
      <geometry>
        <mesh filename="assets/leaders/ur5/link5.stl"/>
      </geometry>
      <material name="">
        <color rgba="0.79216 0.81961 0.93333 1"/>
      </material>
    </visual>
    <collision>
      <origin rpy="0 0 0" xyz="0 0 0"/>
      <geometry>
        <mesh filename="assets/leaders/ur5/link5.stl"/>
      </geometry>
    </collision>
  </link>
  <joint name="robot1/joint5" type="revolute">
    <origin rpy="0 0 1.5707963267949" xyz="0.017 -0.045 0.0"/>
    <parent link="robot1/link4"/>
    <child link="robot1/link5"/>
    <axis xyz="1 0 0"/>
    <limit effort="1" lower="-3.141592653589793" upper="3.141592653589793" velocity="3.15"/>
  </joint>
  <transmission name="robot1/tran5">
    <type>transmission_interface/SimpleTransmission</type>
    <joint name="robot1/joint5">
      <hardwareInterface>hardware_interface/EffortJointInterface</hardwareInterface>
    </joint>
    <actuator name="robot1/motor5">
      <mechanicalReduction>1</mechanicalReduction>
    </actuator>
  </transmission>
  <transmission name="robot1/tran5">
    <type>transmission_interface/SimpleTransmission</type>
    <joint name="robot1/joint5">
      <hardwareInterface>hardware_interface/PositionJointInterface</hardwareInterface>
    </joint>
    <actuator name="robot1/motor5">
      <mechanicalReduction>1</mechanicalReduction>
    </actuator>
  </transmission>
  <link name="robot1/handle">
    <inertial>
      <origin rpy="0 0 0" xyz="-0.0269504648321372 -0.000444552753820911 0.00944823169908937"/>
      <mass value="0.0792318961261061"/>
      <inertia ixx="3.30813970525119E-05" ixy="1.1856468521745E-05" ixz="8.98678207145682E-07" iyy="3.49786415297126E-05" iyz="-5.09722128514016E-07" izz="5.60466661401102E-05"/>
    </inertial>
    <visual>
      <origin rpy="0 0 0" xyz="0 0 0"/>
      <geometry>
        <mesh filename="assets/leaders/handle.stl"/>
      </geometry>
      <material name="">
        <color rgba="0.792156862745098 0.819607843137255 0.933333333333333 1"/>
      </material>
    </visual>
    <collision>
      <origin rpy="0 0 0" xyz="0.0 0 0"/>
      <geometry>
        <mesh filename="assets/leaders/handle.stl"/>
      </geometry>
    </collision>
  </link>
  <joint name="robot1/joint6" type="revolute">
    <origin rpy="0 0 0" xyz="-0.001 0.0 0.015"/>
    <parent link="robot1/link5"/>
    <child link="robot1/handle"/>
    <axis xyz="0.052336 0 0.99863"/>
    <limit effort="1" lower="-3.141592653589793" upper="3.141592653589793" velocity="3.15"/>
  </joint>
  <transmission name="robot1/tran6">
    <type>transmission_interface/SimpleTransmission</type>
    <joint name="robot1/joint6">
      <hardwareInterface>hardware_interface/EffortJointInterface</hardwareInterface>
    </joint>
    <actuator name="robot1/motor6">
      <mechanicalReduction>1</mechanicalReduction>
    </actuator>
  </transmission>
  <transmission name="robot1/tran6">
    <type>transmission_interface/SimpleTransmission</type>
    <joint name="robot1/joint6">
      <hardwareInterface>hardware_interface/PositionJointInterface</hardwareInterface>
    </joint>
    <actuator name="robot1/motor6">
      <mechanicalReduction>1</mechanicalReduction>
    </actuator>
  </transmission>
  <link name="robot1/trigger">
    <inertial>
      <origin rpy="0 0 0" xyz="0.0050484710643748 0.00657608716575382 0.0232192535585892"/>
      <mass value="0.0113373798119285"/>
      <inertia ixx="2.72836346546105E-06" ixy="7.0874539112887E-08" ixz="-2.27358946603912E-07" iyy="2.534724795085E-06" iyz="3.84763852522776E-07" izz="8.0196735325128E-07"/>
    </inertial>
    <visual>
      <origin rpy="0 0 0" xyz="0 0 0"/>
      <geometry>
        <mesh filename="assets/leaders/trigger.stl"/>
      </geometry>
      <material name="">
        <color rgba="0.792156862745098 0.819607843137255 0.933333333333333 1"/>
      </material>
    </visual>
    <collision>
      <origin rpy="0 0 0" xyz="0 0 0"/>
      <geometry>
        <mesh filename="assets/leaders/trigger.stl"/>
      </geometry>
    </collision>
  </link>
  <joint name="robot1/gripper" type="revolute">
    <origin rpy="0.0 0.8 0.000" xyz="0.0154268 0 0.0226837"/>
    <parent link="robot1/handle"/>
    <child link="robot1/trigger"/>
    <axis xyz="0 -1 0"/>
    <limit effort="1" lower="0" upper="1.2" velocity="3.15"/>
  </joint>
  <transmission name="robot1/trangripper">
    <type>transmission_interface/SimpleTransmission</type>
    <joint name="robot1/gripper">
      <hardwareInterface>hardware_interface/EffortJointInterface</hardwareInterface>
    </joint>
    <actuator name="robot1/motorgripper">
      <mechanicalReduction>1</mechanicalReduction>
    </actuator>
  </transmission>
  <transmission name="robot1/trangripper">
    <type>transmission_interface/SimpleTransmission</type>
    <joint name="robot1/gripper">
      <hardwareInterface>hardware_interface/PositionJointInterface</hardwareInterface>
    </joint>
    <actuator name="robot1/motorgripper">
      <mechanicalReduction>1</mechanicalReduction>
    </actuator>
  </transmission>
      <joint name="robot1/end_effector_joint" type="fixed">
    <parent link="robot1/handle"/>
    <child link="robot1/end_effector_link"/>
    <origin rpy="1.57 -1.57 0.0" xyz="0.0 0.0 0.0" />
  </joint>
  <link name="robot1/end_effector_link">
    <visual>
      <origin rpy="0 0 0" xyz="0.0 0.0 0.0"/>
      <geometry>
        <box size="0.01 0.01 0.01"/>
      </geometry>
      <material name="red"/>
    </visual>
    <!-- <collision>
        <origin xyz="0.0 0.0 0.0" rpy="0 0 0" />
        <geometry>
          <box size = "0.01 0.01 0.01"/>
        </geometry>
        <material name="red"/>
      </collision> -->
    <inertial>
      <origin rpy="0 0 0" xyz="0.0 0.0 0.0"/>
      <mass value="0.001"/>
      <inertia ixx="1.0" ixy="0.0" ixz="0.0" iyy="1.0" iyz="0.0" izz="1.0"/>
    </inertial>
  </link>

  <ros2_control name="papras_hw_controller" type="system">
    <hardware>
      <plugin>papras_hardware_interface/DynamixelHardware</plugin>
      <param name="port_name">/dev/ttyUSB0</param>
      <param name="baud_rate">1000000</param>
      <param name="yaml_file">/home/obin/ws_papras/install/teleop_leaders/share/teleop_leaders/config/single_ur5_leader.yaml</param>
      <param name="error_timeout_sec">0.2</param>
      <param name="dynamixel_model_folder">/param/dxl_model</param>
      <param name="ros_update_freq">200</param>
      <param name="dynamixel_state_pub_msg_name">papras_hardware_interface/dxl_state</param>
      <param name="get_dynamixel_data_srv_name">papras_hardware_interface/get_dxl_data</param>
      <param name="set_dynamixel_data_srv_name">papras_hardware_interface/set_dxl_data</param>
      <param name="reboot_dxl_srv_name">papras_hardware_interface/reboot_dxl</param>
      <param name="set_dxl_torque_srv_name">papras_hardware_interface/set_dxl_torque</param>
    </hardware>
    <joint name="robot1/joint1">
      <!-- <param name="id">${arm_id + joint_id}</param> -->
      <param name="id">1</param>
      <!--This will be overwritten by yaml file-->
      <command_interface name="position">
        <param name="min">-3.14159265</param>
        <param name="max">3.14159265</param>
      </command_interface>
      <command_interface name="effort"/>
      <state_interface name="position"/>
      <state_interface name="velocity"/>
      <state_interface name="effort"/>
    </joint>
    <gpio name="robot1/joint1">
      <param name="type">dxl</param>
      <!-- <param name="ID">${arm_id + joint_id}</param> -->
      <param name="ID">1</param>
      <command_interface name="Goal Position"/>
      <command_interface name="Goal Current"/>
      <state_interface name="Present Position"/>
      <state_interface name="Present Velocity"/>
      <state_interface name="Present Current"/>
      <state_interface name="Torque Enable"/>
      <state_interface name="Present Input Voltage"/>
      <!-- <param name="Drive Mode">0</param>
          <param name="Operating Mode">0</param> -->
    </gpio>
    <joint name="robot1/joint2">
      <!-- <param name="id">${arm_id + joint_id}</param> -->
      <param name="id">2</param>
      <!--This will be overwritten by yaml file-->
      <command_interface name="position">
        <param name="min">-3.14159265</param>
        <param name="max">3.14159265</param>
      </command_interface>
      <command_interface name="effort"/>
      <state_interface name="position"/>
      <state_interface name="velocity"/>
      <state_interface name="effort"/>
    </joint>
    <gpio name="robot1/joint2">
      <param name="type">dxl</param>
      <!-- <param name="ID">${arm_id + joint_id}</param> -->
      <param name="ID">2</param>
      <command_interface name="Goal Position"/>
      <command_interface name="Goal Current"/>
      <state_interface name="Present Position"/>
      <state_interface name="Present Velocity"/>
      <state_interface name="Present Current"/>
      <state_interface name="Torque Enable"/>
      <state_interface name="Present Input Voltage"/>
      <!-- <param name="Drive Mode">0</param>
          <param name="Operating Mode">0</param> -->
    </gpio>
    <joint name="robot1/joint3">
      <!-- <param name="id">${arm_id + joint_id}</param> -->
      <param name="id">3</param>
      <!--This will be overwritten by yaml file-->
      <command_interface name="position">
        <param name="min">-3.14159265</param>
        <param name="max">3.14159265</param>
      </command_interface>
      <command_interface name="effort"/>
      <state_interface name="position"/>
      <state_interface name="velocity"/>
      <state_interface name="effort"/>
    </joint>
    <gpio name="robot1/joint3">
      <param name="type">dxl</param>
      <!-- <param name="ID">${arm_id + joint_id}</param> -->
      <param name="ID">3</param>
      <command_interface name="Goal Position"/>
      <command_interface name="Goal Current"/>
      <state_interface name="Present Position"/>
      <state_interface name="Present Velocity"/>
      <state_interface name="Present Current"/>
      <state_interface name="Torque Enable"/>
      <state_interface name="Present Input Voltage"/>
      <!-- <param name="Drive Mode">0</param>
          <param name="Operating Mode">0</param> -->
    </gpio>
    <joint name="robot1/joint4">
      <!-- <param name="id">${arm_id + joint_id}</param> -->
      <param name="id">4</param>
      <!--This will be overwritten by yaml file-->
      <command_interface name="position">
        <param name="min">-3.14159265</param>
        <param name="max">3.14159265</param>
      </command_interface>
      <command_interface name="effort"/>
      <state_interface name="position"/>
      <state_interface name="velocity"/>
      <state_interface name="effort"/>
    </joint>
    <gpio name="robot1/joint4">
      <param name="type">dxl</param>
      <!-- <param name="ID">${arm_id + joint_id}</param> -->
      <param name="ID">4</param>
      <command_interface name="Goal Position"/>
      <command_interface name="Goal Current"/>
      <state_interface name="Present Position"/>
      <state_interface name="Present Velocity"/>
      <state_interface name="Present Current"/>
      <state_interface name="Torque Enable"/>
      <state_interface name="Present Input Voltage"/>
      <!-- <param name="Drive Mode">0</param>
          <param name="Operating Mode">0</param> -->
    </gpio>
    <joint name="robot1/joint5">
      <!-- <param name="id">${arm_id + joint_id}</param> -->
      <param name="id">5</param>
      <!--This will be overwritten by yaml file-->
      <command_interface name="position">
        <param name="min">-3.14159265</param>
        <param name="max">3.14159265</param>
      </command_interface>
      <command_interface name="effort"/>
      <state_interface name="position"/>
      <state_interface name="velocity"/>
      <state_interface name="effort"/>
    </joint>
    <gpio name="robot1/joint5">
      <param name="type">dxl</param>
      <!-- <param name="ID">${arm_id + joint_id}</param> -->
      <param name="ID">5</param>
      <command_interface name="Goal Position"/>
      <command_interface name="Goal Current"/>
      <state_interface name="Present Position"/>
      <state_interface name="Present Velocity"/>
      <state_interface name="Present Current"/>
      <state_interface name="Torque Enable"/>
      <state_interface name="Present Input Voltage"/>
      <!-- <param name="Drive Mode">0</param>
          <param name="Operating Mode">0</param> -->
    </gpio>
    <joint name="robot1/joint6">
      <!-- <param name="id">${arm_id + joint_id}</param> -->
      <param name="id">6</param>
      <!--This will be overwritten by yaml file-->
      <command_interface name="position">
        <param name="min">-3.14159265</param>
        <param name="max">3.14159265</param>
      </command_interface>
      <command_interface name="effort"/>
      <state_interface name="position"/>
      <state_interface name="velocity"/>
      <state_interface name="effort"/>
    </joint>
    <gpio name="robot1/joint6">
      <param name="type">dxl</param>
      <!-- <param name="ID">${arm_id + joint_id}</param> -->
      <param name="ID">6</param>
      <command_interface name="Goal Position"/>
      <command_interface name="Goal Current"/>
      <state_interface name="Present Position"/>
      <state_interface name="Present Velocity"/>
      <state_interface name="Present Current"/>
      <state_interface name="Torque Enable"/>
      <state_interface name="Present Input Voltage"/>
      <!-- <param name="Drive Mode">0</param>
          <param name="Operating Mode">0</param> -->
    </gpio>
    <joint name="robot1/gripper">
      <param name="id">111</param>
      <!-- <param name="id">162</param> -->
      <command_interface name="position"/>
      <command_interface name="effort"/>
      <state_interface name="position"/>
      <state_interface name="velocity"/>
      <state_interface name="effort"/>
    </joint>
    <gpio name="robot1/gripper">
      <param name="type">dxl</param>
      <!-- <param name="ID">162</param> -->
      <param name="ID">111</param>
      <command_interface name="Goal Position"/>
      <command_interface name="Goal Current"/>
      <state_interface name="Present Position"/>
      <state_interface name="Present Velocity"/>
      <state_interface name="Present Current"/>
      <state_interface name="Torque Enable"/>
      <state_interface name="Present Input Voltage"/>
      <!-- <param name="Drive Mode">0</param>
          <param name="Operating Mode">0</param> -->
    </gpio>
  </ros2_control>
</robot>
