<mujoco model="open_manipulator_y">
  <compiler angle="radian" meshdir="../"/>
  <include file="../assets/scene/floor_sky.xml" />
  <asset>
    <mesh name="base_unit" file="assets/om_y/base_unit.stl" scale="0.001 0.001 0.001"/>
    <mesh name="link1" file="assets/om_y/link1.stl" scale="0.001 0.001 0.001"/>
    <mesh name="link2" file="assets/om_y/link2.stl" scale="0.001 0.001 0.001"/>
    <mesh name="link3" file="assets/om_y/link3.stl" scale="0.001 0.001 0.001"/>
    <mesh name="link4" file="assets/om_y/link4.stl" scale="0.001 0.001 0.001"/>
    <mesh name="link5" file="assets/om_y/link5.stl" scale="0.001 0.001 0.001"/>
    <mesh name="link6" file="assets/om_y/link6.stl" scale="0.001 0.001 0.001"/>
    <mesh name="flange" file="assets/om_y/flange.stl" scale="0.001 0.001 0.001"/>
    <mesh name="rh_p12_rn_base" file="assets/robotis_hand_rh-p12-rn/rh_p12_rn_base.stl" scale="0.001 0.001 0.001"/>
    <mesh name="rh_p12_rn_r1" file="assets/robotis_hand_rh-p12-rn/rh_p12_rn_r1.stl" scale="0.001 0.001 0.001"/>
    <mesh name="rh_p12_rn_r2" file="assets/robotis_hand_rh-p12-rn/rh_p12_rn_r2.stl" scale="0.001 0.001 0.001"/>
    <mesh name="rh_p12_rn_l1" file="assets/robotis_hand_rh-p12-rn/rh_p12_rn_l1.stl" scale="0.001 0.001 0.001"/>
    <mesh name="rh_p12_rn_l2" file="assets/robotis_hand_rh-p12-rn/rh_p12_rn_l2.stl" scale="0.001 0.001 0.001"/>
  </asset>
  <worldbody>
    <body name="link0">
      <inertial pos="-0.00402158 0.0013084 0.0550735" quat="0.0485506 0.674996 -0.0441829 0.734895" mass="1.52875" diaginertia="0.00642077 0.00497955 0.00462403"/>
      <geom type="mesh" rgba="0.2 0.2 0.2 1" mesh="base_unit"/>
      <body name="link1" pos="0 0 0.1715">
        <inertial pos="-0.000110636 -0.00547113 -0.0158977" quat="0.98558 0.168758 -0.00294757 0.0120358" mass="2.06488" diaginertia="0.00303337 0.00279081 0.00221937"/>
        <joint name="joint1" pos="0 0 0" axis="0 0 1" range="-6.28319 6.28319" actuatorfrcrange="-1000 1000" damping="0.1"/>
        <geom type="mesh" rgba="0.2 0.2 0.2 1" mesh="link1"/>
        <body name="link2" pos="0 -0.1215 0">
          <inertial pos="1.14054e-05 0.0161842 0.103606" quat="0.999988 -0.00477885 -0.000609836 0.00067321" mass="3.67954" diaginertia="0.051732 0.0503576 0.00449718"/>
          <joint name="joint2" pos="0 0 0" axis="0 1 0" range="-6.28319 6.28319" actuatorfrcrange="-1000 1000" damping="0.1"/>
          <geom type="mesh" rgba="0.2 0.2 0.2 1" mesh="link2"/>
          <body name="link3" pos="0 0 0.247">
            <inertial pos="7.81487e-05 0.107185 0.141173" quat="0.999987 0.00500823 0.000469041 -0.00072733" mass="2.38659" diaginertia="0.0226944 0.021922 0.00277422"/>
            <joint name="joint3" pos="0 0 0" axis="0 1 0" range="-6.28319 6.28319" actuatorfrcrange="-1000 1000" damping="0.1"/>
            <geom type="mesh" rgba="0.2 0.2 0.2 1" mesh="link3"/>
            <body name="link4" pos="0 0.1215 0.2195">
              <inertial pos="-0.000133183 -0.107467 0.0190907" quat="0.983636 0.179196 0.00338061 -0.0183488" mass="1.40023" diaginertia="0.00175475 0.00162284 0.00115817"/>
              <joint name="joint4" pos="0 0 0" axis="0 1 0" range="-6.28319 6.28319" actuatorfrcrange="-1000 1000" damping="0.1"/>
              <geom type="mesh" rgba="0.2 0.2 0.2 1" mesh="link4"/>
              <body name="link5" pos="0 -0.113 0">
                <inertial pos="0.000133183 -0.0190907 0.109967" quat="0.822247 0.568825 0.0105841 -0.015365" mass="1.40023" diaginertia="0.00175475 0.00162284 0.00115817"/>
                <joint name="joint5" pos="0 0 0" axis="0 0 1" range="-6.28319 6.28319" actuatorfrcrange="-1000 1000" damping="0.1"/>
                <geom type="mesh" rgba="0.2 0.2 0.2 1" mesh="link5"/>
                <body name="link6" pos="0 0 0.1155">
                  <inertial pos="1.10801e-05 -0.0805941 0.00930293" quat="0.707541 -0.0441733 0.0461929 0.703776" mass="0.400155" diaginertia="0.00063691 0.000567415 0.00019166"/>
                  <joint name="joint6" pos="0 0 0" axis="0 1 0" range="-6.28319 6.28319" actuatorfrcrange="-1000 1000" damping="0.1"/>
                  <geom type="mesh" rgba="0.2 0.2 0.2 1" mesh="link6"/>
                  <body name="end_effector_flange_link" pos="0 -0.103 0">
                    <inertial pos="0 -0.00319031 0" quat="0.5 0.5 0.5 0.5" mass="0.0166188" diaginertia="8.12543e-06 5.49262e-06 2.90758e-06"/>
                    <geom type="mesh" rgba="0.2 0.2 0.2 1" mesh="flange"/>
                    <body name="rh_p12_rn_base" pos="0 -0.006 0" quat="0.500398 0.5 0.5 -0.499602">
                      <inertial pos="0 0 0.032" mass="0.236" diaginertia="1e-06 1e-06 1e-06"/>
                      <geom type="mesh" mesh="rh_p12_rn_base"/>
                      <body name="rh_p12_rn_r1" pos="0 0.008 0.048">
                        <inertial pos="0 0.034 0.004" mass="0.068" diaginertia="1e-06 1e-06 1e-06"/>
                        <joint name="rh_r1_joint" pos="0 0 0" axis="1 0 0" range="0 1.1" actuatorfrcrange="-1000 1000" damping="0.7"/>
                        <geom type="mesh" mesh="rh_p12_rn_r1"/>
                        <body name="rh_p12_rn_r2" pos="0 0.0493634 0.0285">
                          <inertial pos="0 0.006 0.011" mass="0.022" diaginertia="1e-06 1e-06 1e-06"/>
                          <joint name="rh_r2" pos="0 0 0" axis="-1 0 0" range="0 1" actuatorfrcrange="-1000 1000" damping="0.7"/>
                          <geom type="mesh" mesh="rh_p12_rn_r2"/>
                        </body>
                      </body>
                      <body name="rh_p12_rn_l1" pos="0 -0.008 0.048">
                        <inertial pos="0 -0.034 0.004" mass="0.068" diaginertia="1e-06 1e-06 1e-06"/>
                        <joint name="rh_l1" pos="0 0 0" axis="-1 0 0" range="0 1.1" actuatorfrcrange="-1000 1000" damping="0.7"/>
                        <geom type="mesh" mesh="rh_p12_rn_l1"/>
                        <body name="rh_p12_rn_l2" pos="0 -0.0493634 0.0285">
                          <inertial pos="0 -0.006 0.011" mass="0.022" diaginertia="1e-06 1e-06 1e-06"/>
                          <joint name="rh_l2" pos="0 0 0" axis="1 0 0" range="0 1" actuatorfrcrange="-1000 1000" damping="0.7"/>
                          <geom type="mesh" mesh="rh_p12_rn_l2"/>
                        </body>
                      </body>
                    </body>
                    <body name="end_effector_link" pos="0 -0.135 0" quat="0.707388 0 0 -0.706825">
                      <inertial pos="0 0 0" mass="0.001" diaginertia="1 1 1"/>
                    </body>
                  </body>
                </body>
              </body>
            </body>
          </body>
        </body>
      </body>
    </body>
  </worldbody>
  <contact>
    <exclude body1="link0" body2="link1"/>
  </contact>
</mujoco>
