<?xml version="1.0" ?>
<!-- =================================================================================== -->
<!-- |    This document was autogenerated by xacro from simple_7dof.urdf.xacro         | -->
<!-- |    EDITING THIS FILE BY HAND IS NOT RECOMMENDED                                 | -->
<!-- =================================================================================== -->
<robot name="simple_robot">
<mujoco>
   <compiler angle="radian" meshdir="../../" autolimits="true" strippath="false" fusestatic="false"/>
</mujoco>
  <material name="black">
    <color rgba="0.0 0.0 0.0 1.0"/>
  </material>
  <material name="blue">
    <color rgba="0.0 0.0 0.8 1.0"/>
  </material>
  <material name="green">
    <color rgba="0.0 0.8 0.0 1.0"/>
  </material>
  <material name="grey">
    <color rgba="0.5 0.5 0.5 1.0"/>
  </material>
  <material name="orange">
    <color rgba="1.0 0.4235294117647059 0.0392156862745098 1.0"/>
  </material>
  <material name="brown">
    <color rgba="0.8705882352941177 0.8117647058823529 0.7647058823529411 1.0"/>
  </material>
  <material name="red">
    <color rgba="0.8 0.0 0.0 1.0"/>
  </material>
  <material name="white">
    <color rgba="1.0 1.0 1.0 1.0"/>
  </material>
  <!-- Import all Gazebo-customization elements, including Gazebo colors -->
  <!-- World -->
  <gazebo reference="world"/>
  <!-- Evn Link -->
  <gazebo reference="env"/>
  <!-- ros_control plugin -->
  <gazebo>
    <plugin filename="libgazebo_ros_control.so" name="gazebo_ros_control">
      <robotSimType>gazebo_ros_control/DefaultRobotHWSim</robotSimType>
    </plugin>
  </gazebo>
  <link name="world"/>
  <joint name="robot1/env_arm_fixed" type="fixed">
    <parent link="world"/>
    <child link="robot1/link1"/>
    <origin rpy="0 0 0" xyz="0 0 0"/>
  </joint>
  <!-- link 1 -->
  <link name="robot1/link1">
    <visual>
      <origin rpy="0 0 0" xyz="0 0 0"/>
      <geometry>
        <mesh filename="assets/papras/link1.stl" scale="0.001 0.001 0.001"/>
      </geometry>
      <material name="grey"/>
    </visual>
    <collision>
      <origin rpy="0 0 0" xyz="0 0 0"/>
      <geometry>
        <mesh filename="assets/papras/link1.stl" scale="0.001 0.001 0.001"/>
      </geometry>
    </collision>
    <inertial>
      <origin rpy="0 0 0" xyz="0.00023 0.00000 0.06223"/>
      <mass value="0.85644"/>
      <!-- <inertia ixx="1.0" ixy="0.0" ixz="0.0" iyy="1.0" iyz="0.0" izz="1.0" /> -->
      <inertia ixx="0.00121064" ixy="0.0" ixz="0.00001100" iyy="0.00120886" iyz="0.0" izz="0.00038103"/>
    </inertial>
  </link>
  <gazebo reference="robot1/link1">
    <kp>1000000.0</kp>
    <kd>100.0</kd>
    <mu1>30.0</mu1>
    <mu2>30.0</mu2>
    <maxVel>1.0</maxVel>
    <minDepth>0.001</minDepth>
    <material>Gazebo/White</material>
    <selfCollide>1</selfCollide>
    <dampingFactor>0.01</dampingFactor>
  </gazebo>
  <!-- Joint 1 -->
  <joint name="robot1/joint1" type="revolute">
    <parent link="robot1/link1"/>
    <child link="robot1/link2"/>
    <origin rpy="0 0 0" xyz="0.0 0.0 0.126"/>
    <axis xyz="0 0 1"/>
    <limit effort="100" lower="-3.141592653589793" upper="3.141592653589793" velocity="3.03687"/>
    <dynamics damping="0.7"/>
  </joint>
  <transmission name="robot1/tran1">
    <type>transmission_interface/SimpleTransmission</type>
    <joint name="robot1/joint1">
      <hardwareInterface>hardware_interface/PositionJointInterface</hardwareInterface>
    </joint>
    <actuator name="robot1/motor1">
      <mechanicalReduction>1</mechanicalReduction>
    </actuator>
  </transmission>
  <!-- link 2 -->
  <link name="robot1/link2">
    <visual>
      <origin rpy="0 0 0" xyz="0 0 0"/>
      <geometry>
        <mesh filename="assets/papras/link2.stl" scale="0.001 0.001 0.001"/>
      </geometry>
      <material name="grey"/>
    </visual>
    <collision>
      <origin rpy="0 0 0" xyz="0 0 0"/>
      <geometry>
        <mesh filename="assets/papras/link2.stl" scale="0.001 0.001 0.001"/>
      </geometry>
    </collision>
    <inertial>
      <origin rpy="0 0 0" xyz="0.00000 0.00080 0.03183"/>
      <!--<origin xyz="0.00000 -0.06820 -0.00117" rpy="0 0 0"/>-->
      <mass value="0.94658"/>
      <inertia ixx="1.0" ixy="0.0" ixz="0.0" iyy="1.0" iyz="0.0" izz="1.0"/>
      <!--<inertia ixx="0.00152547" ixy="0.0" ixz="0.0" iyy="0.00045954" iyz="-0.00001086" izz="0.00151740" />-->
    </inertial>
  </link>
  <gazebo reference="robot1/link2">
    <kp>1000000.0</kp>
    <kd>100.0</kd>
    <mu1>30.0</mu1>
    <mu2>30.0</mu2>
    <maxVel>1.0</maxVel>
    <minDepth>0.001</minDepth>
    <material>Gazebo/White</material>
    <selfCollide>1</selfCollide>
    <dampingFactor>0.01</dampingFactor>
  </gazebo>
  <!-- Joint 2 -->
  <joint name="robot1/joint2" type="revolute">
    <parent link="robot1/link2"/>
    <child link="robot1/link3"/>
    <origin rpy="1.5707963267948966 -1.5707963267948966 0" xyz="0.0 0.00 0.033"/>
    <axis xyz="0 0 1"/>
    <limit effort="100" lower="-2.0" upper="2.0" velocity="3.03687"/>
    <dynamics damping="0.7"/>
  </joint>
  <transmission name="robot1/tran2">
    <type>transmission_interface/SimpleTransmission</type>
    <joint name="robot1/joint2">
      <hardwareInterface>hardware_interface/PositionJointInterface</hardwareInterface>
    </joint>
    <actuator name="robot1/motor2">
      <mechanicalReduction>1</mechanicalReduction>
    </actuator>
  </transmission>
  <!-- link 2 -->
  <link name="robot1/link3">
    <visual>
      <origin rpy="0 0 0" xyz="0.0 0.0 0.0"/>
      <geometry>
        <mesh filename="assets/papras/7dof/link3.stl"/>
      </geometry>
      <material name="grey"/>
    </visual>
    <collision>
      <origin rpy="0 0 0" xyz="0 0 0"/>
      <geometry>
        <mesh filename="assets/papras/7dof/link3.stl"/>
      </geometry>
    </collision>
    <inertial>
      <origin rpy="0 0 0" xyz="0.00000 0.00080 0.03183"/>
      <!--<origin xyz="0.00000 -0.06820 -0.00117" rpy="0 0 0"/>-->
      <mass value="0.49982"/>
      <!-- <inertia ixx="1.0" ixy="0.0" ixz="0.0" iyy="1.0" iyz="0.0" izz="1.0" /> -->
      <inertia ixx="0.00078817" ixy="6.3729E-09" ixz="-1.0998E-05" iyy="0.0012133" iyz="-7.0637E-09" izz="0.00073746"/>
    </inertial>
  </link>
  <gazebo reference="robot1/link3">
    <kp>1000000.0</kp>
    <kd>100.0</kd>
    <mu1>30.0</mu1>
    <mu2>30.0</mu2>
    <maxVel>1.0</maxVel>
    <minDepth>0.001</minDepth>
    <material>Gazebo/White</material>
    <selfCollide>1</selfCollide>
    <dampingFactor>0.01</dampingFactor>
  </gazebo>
  <!-- Joint 2 -->
  <joint name="robot1/joint3" type="revolute">
    <parent link="robot1/link3"/>
    <child link="robot1/link4"/>
    <origin rpy="0 -1.5707963267948966 -1.5707963267948966" xyz="0.156382198147594 0 0.000400000000010851"/>
    <axis xyz="0 1 0"/>
    <limit effort="100" lower="-3.141592653589793" upper="3.141592653589793" velocity="3.03687"/>
    <dynamics damping="0.7"/>
  </joint>
  <transmission name="robot1/tran3">
    <type>transmission_interface/SimpleTransmission</type>
    <joint name="robot1/joint3">
      <hardwareInterface>hardware_interface/PositionJointInterface</hardwareInterface>
    </joint>
    <actuator name="robot1/motor3">
      <mechanicalReduction>1</mechanicalReduction>
    </actuator>
  </transmission>
  <!-- link 2 -->
  <link name="robot1/link4">
    <visual>
      <origin rpy="0 0 0" xyz="0.0 0.0 0.0"/>
      <geometry>
        <mesh filename="assets/papras/7dof/link4.stl"/>
      </geometry>
      <material name="grey"/>
    </visual>
    <collision>
      <origin rpy="0 0 0" xyz="0 0 0"/>
      <geometry>
        <mesh filename="assets/papras/7dof/link4.stl"/>
      </geometry>
    </collision>
    <inertial>
      <origin rpy="0 0 0" xyz="-4.86609203880829E-06 0.120506252053841 -0.0279123104678896"/>
      <mass value="0.597399042150493"/>
      <!-- <inertia ixx="1.0" ixy="0.0" ixz="0.0" iyy="1.0" iyz="0.0" izz="1.0" /> -->
      <inertia ixx="0.0015528567154149" ixy="1.16567414120262E-05" ixz="-2.90009974781987E-06" iyy="0.00077263780701987" iyz="9.95380938833158E-05" izz="0.0018580466481516"/>
    </inertial>
  </link>
  <gazebo reference="robot1/link4">
    <kp>1000000.0</kp>
    <kd>100.0</kd>
    <mu1>30.0</mu1>
    <mu2>30.0</mu2>
    <maxVel>1.0</maxVel>
    <minDepth>0.001</minDepth>
    <material>Gazebo/White</material>
    <selfCollide>1</selfCollide>
    <dampingFactor>0.01</dampingFactor>
  </gazebo>
  <!-- Joint 3 -->
  <joint name="robot1/joint4" type="revolute">
    <parent link="robot1/link4"/>
    <child link="robot1/link5"/>
    <origin rpy="3.141592653589793 -1.5707963267948966 1.5707963267948966" xyz="0.0575 0.10761780185239 0.0300000000000553"/>
    <axis xyz="0 1 0"/>
    <limit effort="100" lower="-3.141592653589793" upper="1.42" velocity="3.03687"/>
    <dynamics damping="0.7"/>
  </joint>
  <transmission name="robot1/tran4">
    <type>transmission_interface/SimpleTransmission</type>
    <joint name="robot1/joint4">
      <hardwareInterface>hardware_interface/PositionJointInterface</hardwareInterface>
    </joint>
    <actuator name="robot1/motor4">
      <mechanicalReduction>1</mechanicalReduction>
    </actuator>
  </transmission>
  <!-- link 5 -->
  <link name="robot1/link5">
    <visual>
      <origin rpy="0 0 3.14" xyz="0.227 0.0085 -0.024"/>
      <geometry>
        <mesh filename="assets/papras/link4_papras.stl" scale="0.001 0.001 0.001"/>
      </geometry>
      <material name="grey"/>
    </visual>
    <collision>
      <origin rpy="0 0 3.14" xyz="0.227 0.0085 -0.024"/>
      <geometry>
        <mesh filename="assets/papras/link4_papras_simple.stl" scale="0.001 0.001 0.001"/>
      </geometry>
    </collision>
    <inertial>
      <origin rpy="0 0 0" xyz="0.12475 -0.05716 0.02979"/>
      <!--<origin xyz="-0.07025 0.00034 -0.00021" rpy="0 0 0"/>-->
      <mass value="1.15977"/>
      <inertia ixx="1.0" ixy="0.0" ixz="0.0" iyy="1.0" iyz="0.0" izz="1.0"/>
      <!--<inertia ixx="0.00096726" ixy="0.00004383" ixz="-0.00002771" iyy="0.00318801" iyz="0.00000627" izz="0.00341484" />-->
    </inertial>
  </link>
  <gazebo reference="robot1/link5">
    <kp>1000000.0</kp>
    <kd>100.0</kd>
    <mu1>30.0</mu1>
    <mu2>30.0</mu2>
    <maxVel>1.0</maxVel>
    <minDepth>0.001</minDepth>
    <material>Gazebo/White</material>
    <selfCollide>1</selfCollide>
    <dampingFactor>0.01</dampingFactor>
  </gazebo>
  <!-- Joint 4 -->
  <joint name="robot1/joint5" type="revolute">
    <parent link="robot1/link5"/>
    <child link="robot1/link6"/>
    <origin rpy="0 0 0" xyz="0.19500 -0.05750 0.03000"/>
    <axis xyz="1 0 0"/>
    <limit effort="100" lower="-2.748893571891069" upper="2.748893571891069" velocity="3.03687"/>
    <dynamics damping="0.7"/>
  </joint>
  <transmission name="robot1/tran5">
    <type>transmission_interface/SimpleTransmission</type>
    <joint name="robot1/joint5">
      <hardwareInterface>hardware_interface/PositionJointInterface</hardwareInterface>
    </joint>
    <actuator name="robot1/motor5">
      <mechanicalReduction>1</mechanicalReduction>
    </actuator>
  </transmission>
  <!-- link 6 -->
  <link name="robot1/link6">
    <visual>
      <origin rpy="0 0 0" xyz="0 0 0"/>
      <geometry>
        <mesh filename="assets/papras/link5.stl" scale="0.001 0.001 0.001"/>
      </geometry>
      <material name="grey"/>
    </visual>
    <collision>
      <origin rpy="0 0 0" xyz="0 0 0"/>
      <geometry>
        <mesh filename="assets/papras/link5.stl" scale="0.001 0.001 0.001"/>
      </geometry>
    </collision>
    <inertial>
      <origin rpy="0 0 0" xyz="0.05642 -0.00217 0.00002"/>
      <!--<origin xyz="-0.00658 -0.04717 0.00002" rpy="0 0 0"/>-->
      <mass value="0.44688"/>
      <inertia ixx="1.0" ixy="0.0" ixz="0.0" iyy="1.0" iyz="0.0" izz="1.0"/>
      <!--<inertia ixx="0.00030285" ixy="0.00000761" ixz="0.00000031" iyy="0.00022339" iyz="-0.00000001" izz="0.00039766" />-->
    </inertial>
  </link>
  <gazebo reference="robot1/link6">
    <kp>1000000.0</kp>
    <kd>100.0</kd>
    <mu1>30.0</mu1>
    <mu2>30.0</mu2>
    <maxVel>1.0</maxVel>
    <minDepth>0.001</minDepth>
    <material>Gazebo/White</material>
    <selfCollide>1</selfCollide>
    <dampingFactor>0.01</dampingFactor>
  </gazebo>
  <!-- Joint 6 -->
  <joint name="robot1/joint6" type="revolute">
    <parent link="robot1/link6"/>
    <child link="robot1/link7"/>
    <origin rpy="0 0 0" xyz="0.06300 0.04500 0.00000"/>
    <axis xyz="0 1 0"/>
    <limit effort="100" lower="-1.5707963267948966" upper="1.5707963267948966" velocity="3.03687"/>
    <dynamics damping="0.7"/>
  </joint>
  <transmission name="robot1/tran6">
    <type>transmission_interface/SimpleTransmission</type>
    <joint name="robot1/joint6">
      <hardwareInterface>hardware_interface/PositionJointInterface</hardwareInterface>
    </joint>
    <actuator name="robot1/motor6">
      <mechanicalReduction>1</mechanicalReduction>
    </actuator>
  </transmission>
  <!-- link 6 -->
  <link name="robot1/link7">
    <visual>
      <origin rpy="0 0 0" xyz="-0.034 -0.098 -0.028"/>
      <geometry>
        <mesh filename="assets/papras/link6_papras.stl" scale="0.001 0.001 0.001"/>
      </geometry>
      <material name="grey"/>
    </visual>
    <collision>
      <origin rpy="0 0 0" xyz="-0.034 -0.098 -0.028"/>
      <geometry>
        <mesh filename="assets/papras/link6_papras_simple.stl" scale="0.001 0.001 0.001"/>
      </geometry>
    </collision>
    <inertial>
      <origin rpy="0 0 0" xyz="0.06831 -0.04457 0.00000"/>
      <!--<origin xyz="-0.05469 0.00043 0.00000" rpy="0 0 0"/>-->
      <mass value="0.43273"/>
      <inertia ixx="1.0" ixy="0.0" ixz="0.0" iyy="1.0" iyz="0.0" izz="1.0"/>
      <!--<inertia ixx="0.00021512" ixy="0.00001009" ixz="0.00000000" iyy="0.00042827" iyz="0.00000000" izz="0.00051436" />-->
    </inertial>
  </link>
  <gazebo reference="robot1/link7">
    <kp>1000000.0</kp>
    <kd>100.0</kd>
    <mu1>30.0</mu1>
    <mu2>30.0</mu2>
    <maxVel>1.0</maxVel>
    <minDepth>0.001</minDepth>
    <material>Gazebo/White</material>
    <selfCollide>1</selfCollide>
    <dampingFactor>0.01</dampingFactor>
  </gazebo>
  <!-- Joint 7 -->
  <joint name="robot1/joint7" type="revolute">
    <parent link="robot1/link7"/>
    <child link="robot1/end_link"/>
    <origin rpy="0 0 0" xyz="0.12300 -0.04500 0.00000"/>
    <axis xyz="1 0 0"/>
    <limit effort="100" lower="-3.141592653589793" upper="3.141592653589793" velocity="3.03687"/>
    <dynamics damping="0.7"/>
  </joint>
  <transmission name="robot1/tran7">
    <type>transmission_interface/SimpleTransmission</type>
    <joint name="robot1/joint7">
      <hardwareInterface>hardware_interface/PositionJointInterface</hardwareInterface>
    </joint>
    <actuator name="robot1/motor7">
      <mechanicalReduction>1</mechanicalReduction>
    </actuator>
  </transmission>
  <!-- end link -->
  <link name="robot1/end_link">
    <visual>
      <origin rpy="0 0 0" xyz="0.0 0.0 0.0"/>
      <geometry>
        <mesh filename="assets/papras/end_link.stl" scale="0.001 0.001 0.001"/>
      </geometry>
      <material name="grey"/>
    </visual>
    <collision>
      <origin rpy="0 0 0" xyz="0.0 0.0 0.0"/>
      <geometry>
        <mesh filename="assets/papras/end_link.stl" scale="0.001 0.001 0.001"/>
      </geometry>
    </collision>
    <inertial>
      <origin rpy="0 0 0" xyz="0.00337 0.00000 0.00000"/>
      <mass value="0.01919"/>
      <inertia ixx="1.0" ixy="0.0" ixz="0.0" iyy="1.0" iyz="0.0" izz="1.0"/>
      <!--<inertia ixx="0.00000938" ixy="0.0" ixz="0.0" iyy="0.00000338" iyz="0.0" izz="0.00000635" />-->
    </inertial>
  </link>
  <gazebo reference="robot1/end_link">
    <kp>1000000.0</kp>
    <kd>100.0</kd>
    <mu1>30.0</mu1>
    <mu2>30.0</mu2>
    <maxVel>1.0</maxVel>
    <minDepth>0.001</minDepth>
    <material>Gazebo/White</material>
    <selfCollide>1</selfCollide>
    <dampingFactor>0.01</dampingFactor>
  </gazebo>
    <!-- End Effector -->
  <link name="robot1/wrist_link">
  </link>
  <joint name="robot1/wrist_joint" type="fixed">
    <parent link="robot1/end_link"/>
    <child link="robot1/wrist_link"/>
    <origin rpy="0 0 0" xyz="0.006 0.0 0.0"/>
  </joint>
  <!-- gripper main fixed joint-->
  <joint name="robot1/end_link_fixed" type="fixed">
    <parent link="robot1/end_link"/>
    <child link="robot1/gripper_main_link"/>
    <origin rpy="0 -1.5707963267948966 3.141592653589793" xyz="0.006 0.0 0.0"/>
  </joint>
  <!-- gripper main link -->
    <link name="robot1/gripper_main_link">
    <collision>
      <origin rpy="0 0 0" xyz="0 0 0"/>
      <geometry>
        <mesh filename="assets/robotis_hand_rh-p12-rn/rh_p12_rn_base.stl" scale="0.001 0.001 0.001"/>
      </geometry>
    </collision>
    <visual>
      <origin rpy="0 0 0" xyz="0 0 0"/>
      <geometry>
        <mesh filename="assets/robotis_hand_rh-p12-rn/rh_p12_rn_base.stl" scale="0.001 0.001 0.001"/>
      </geometry>
      <material name="grey"/>
    </visual>
    <inertial>
      <origin rpy="0 0 0" xyz="0.000 0.000 0.032"/>
      <mass value="0.236"/>
      <!--<inertia ixx="0.00017" ixy="0.0" ixz="0.0" iyy="0.00011" iyz="0.0" izz="0.00017" />-->
      <inertia ixx="1.0" ixy="0.0" ixz="0.0" iyy="1.0" iyz="0.0" izz="1.0"/>
    </inertial>
  </link>
  <gazebo reference="robot1/gripper_main_link">
    <kp>1000000.0</kp>
    <kd>100.0</kd>
    <mu1>30.0</mu1>
    <mu2>30.0</mu2>
    <maxVel>1.0</maxVel>
    <minDepth>0.001</minDepth>
    <material>Gazebo/White</material>
    <selfCollide>1</selfCollide>
    <dampingFactor>0.01</dampingFactor>
  </gazebo>
  <!-- gripper joint -->
  <joint name="robot1/gripper" type="revolute">
    <parent link="robot1/gripper_main_link"/>
    <child link="robot1/gripper_link"/>
    <origin rpy="0 0 0" xyz="0.0 0.008 0.048"/>
    <axis xyz="1 0 0"/>
    <limit effort="1000" lower="0.0" upper="1.1" velocity="6.5"/>
    <dynamics damping="0.7"/>
  </joint>
  <transmission name="robot1/trangripper">
    <type>transmission_interface/SimpleTransmission</type>
    <joint name="robot1/gripper">
      <hardwareInterface>hardware_interface/EffortJointInterface</hardwareInterface>
    </joint>
    <actuator name="robot1/motorgripper">
      <mechanicalReduction>1</mechanicalReduction>
    </actuator>
  </transmission>
  <!-- gripper link -->
  <link name="robot1/gripper_link">
    <collision>
      <origin rpy="0 0 0" xyz="0 0 0"/>
      <geometry>
        <mesh filename="assets/robotis_hand_rh-p12-rn/rh_p12_rn_r1.stl" scale="0.001 0.001 0.001"/>
      </geometry>
    </collision>
    <visual>
      <origin rpy="0 0 0" xyz="0 0 0"/>
      <geometry>
        <mesh filename="assets/robotis_hand_rh-p12-rn/rh_p12_rn_r1.stl" scale="0.001 0.001 0.001"/>
      </geometry>
      <material name="grey"/>
    </visual>
    <inertial>
      <origin rpy="0 0 0" xyz="0.000 0.034 0.004"/>
      <mass value="0.068"/>
      <!--<inertia ixx="0.00004" ixy="0.0" ixz="0.0" iyy="0.00002" iyz="-0.00001" izz="0.00002" />-->
      <inertia ixx="1.0" ixy="0.0" ixz="0.0" iyy="1.0" iyz="0.0" izz="1.0"/>
    </inertial>
  </link>
  <gazebo reference="robot1/gripper_link">
    <kp>1000000.0</kp>
    <kd>100.0</kd>
    <mu1>30.0</mu1>
    <mu2>30.0</mu2>
    <maxVel>1.0</maxVel>
    <minDepth>0.001</minDepth>
    <material>Gazebo/White</material>
    <selfCollide>1</selfCollide>
    <dampingFactor>0.01</dampingFactor>
  </gazebo>
  <joint name="robot1/gripper_r2" type="revolute">
    <parent link="robot1/gripper_link"/>
    <child link="robot1/gripper_link_r2"/>
    <origin rpy="0 0 0" xyz="0.0 0.0493634 0.0285"/>
    <axis xyz="-1 0 0"/>
    <limit effort="1000" lower="0.0" upper="1.0" velocity="6.5"/>
    <dynamics damping="0.7"/>
    <mimic joint="robot1/gripper" multiplier="0.9090909090909091"/>
  </joint>
  <transmission name="robot1/trangripper_r2">
    <type>transmission_interface/SimpleTransmission</type>
    <joint name="robot1/gripper_r2">
      <hardwareInterface>hardware_interface/EffortJointInterface</hardwareInterface>
    </joint>
    <actuator name="robot1/motorgripper_r2">
      <mechanicalReduction>1</mechanicalReduction>
    </actuator>
  </transmission>
  <!-- rh_p12_rn_r2 -->
  <link name="robot1/gripper_link_r2">
    <collision>
      <origin rpy="0 0 0" xyz="0 0 0"/>
      <geometry>
        <mesh filename="assets/robotis_hand_rh-p12-rn/rh_p12_rn_r2.stl" scale="0.001 0.001 0.001"/>
      </geometry>
    </collision>
    <visual>
      <origin rpy="0 0 0" xyz="0 0 0"/>
      <geometry>
        <mesh filename="assets/robotis_hand_rh-p12-rn/rh_p12_rn_r2.stl" scale="0.001 0.001 0.001"/>
      </geometry>
      <material name="grey"/>
    </visual>
    <inertial>
      <origin rpy="0 0 0" xyz="0.000 0.006 0.011"/>
      <mass value="0.022"/>
      <!--<inertia ixx="0.0" ixy="0.0" ixz="0.0" iyy="0.00001" iyz="0.0" izz="0.0" />-->
      <inertia ixx="1.0" ixy="0.0" ixz="0.0" iyy="1.0" iyz="0.0" izz="1.0"/>
    </inertial>
  </link>
  <gazebo reference="robot1/gripper_link_r2">
    <kp>1000000.0</kp>
    <kd>100.0</kd>
    <mu1>30.0</mu1>
    <mu2>30.0</mu2>
    <maxVel>1.0</maxVel>
    <minDepth>0.001</minDepth>
    <material>Gazebo/White</material>
    <selfCollide>1</selfCollide>
    <dampingFactor>0.01</dampingFactor>
  </gazebo>
  <!-- Left Joint 1 -->
  <joint name="robot1/gripper_l1" type="revolute">
    <parent link="robot1/gripper_main_link"/>
    <child link="robot1/gripper_link_l1"/>
    <origin rpy="0 0 0" xyz="0.0 -0.008 0.048"/>
    <axis xyz="-1 0 0"/>
    <limit effort="1000" lower="0.0" upper="1.1" velocity="6.5"/>
    <dynamics damping="0.7"/>
    <mimic joint="robot1/gripper" multiplier="1.0"/>
  </joint>
  <transmission name="robot1/trangripper_l1">
    <type>transmission_interface/SimpleTransmission</type>
    <joint name="robot1/gripper_l1">
      <hardwareInterface>hardware_interface/EffortJointInterface</hardwareInterface>
    </joint>
    <actuator name="robot1/motorgripper_l1">
      <mechanicalReduction>1</mechanicalReduction>
    </actuator>
  </transmission>
  <!-- rh_p12_rn_l1 -->
  <link name="robot1/gripper_link_l1">
    <collision>
      <origin rpy="0 0 0" xyz="0 0 0"/>
      <geometry>
        <mesh filename="assets/robotis_hand_rh-p12-rn/rh_p12_rn_l1.stl" scale="0.001 0.001 0.001"/>
      </geometry>
    </collision>
    <visual>
      <origin rpy="0 0 0" xyz="0 0 0"/>
      <geometry>
        <mesh filename="assets/robotis_hand_rh-p12-rn/rh_p12_rn_l1.stl" scale="0.001 0.001 0.001"/>
      </geometry>
      <material name="grey"/>
    </visual>
    <inertial>
      <origin rpy="0 0 0" xyz="0.000 -0.034 0.004"/>
      <mass value="0.068"/>
      <!--<inertia ixx="0.00004" ixy="0.0" ixz="0.0" iyy="0.00002" iyz="0.00001" izz="0.00002" />-->
      <inertia ixx="1.0" ixy="0.0" ixz="0.0" iyy="1.0" iyz="0.0" izz="1.0"/>
    </inertial>
  </link>
  <gazebo reference="robot1/gripper_link_l1">
    <kp>1000000.0</kp>
    <kd>100.0</kd>
    <mu1>30.0</mu1>
    <mu2>30.0</mu2>
    <maxVel>1.0</maxVel>
    <minDepth>0.001</minDepth>
    <material>Gazebo/White</material>
    <selfCollide>1</selfCollide>
    <dampingFactor>0.01</dampingFactor>
  </gazebo>
  <!-- Left Joint 2 -->
  <joint name="robot1/gripper_l2" type="revolute">
    <parent link="robot1/gripper_link_l1"/>
    <child link="robot1/gripper_link_l2"/>
    <origin rpy="0 0 0" xyz="0.0 -0.0493634 0.0285"/>
    <axis xyz="1 0 0"/>
    <limit effort="1000" lower="0.0" upper="1.0" velocity="6.5"/>
    <dynamics damping="0.7"/>
    <mimic joint="robot1/gripper" multiplier="0.9090909090909091"/>
  </joint>
  <transmission name="robot1/trangripper_l2">
    <type>transmission_interface/SimpleTransmission</type>
    <joint name="robot1/gripper_l2">
      <hardwareInterface>hardware_interface/EffortJointInterface</hardwareInterface>
    </joint>
    <actuator name="robot1/motorgripper_l2">
      <mechanicalReduction>1</mechanicalReduction>
    </actuator>
  </transmission>
  <link name="robot1/gripper_link_l2">
    <collision>
      <origin rpy="0 0 0" xyz="0 0 0"/>
      <geometry>
        <mesh filename="assets/robotis_hand_rh-p12-rn/rh_p12_rn_l2.stl" scale="0.001 0.001 0.001"/>
      </geometry>
    </collision>
    <visual>
      <origin rpy="0 0 0" xyz="0 0 0"/>
      <geometry>
        <mesh filename="assets/robotis_hand_rh-p12-rn/rh_p12_rn_l2.stl" scale="0.001 0.001 0.001"/>
      </geometry>
      <material name="grey"/>
    </visual>
    <inertial>
      <origin rpy="0 0 0" xyz="0.000 -0.006 0.011"/>
      <mass value="0.022"/>
      <!--<inertia ixx="0.0" ixy="0.0" ixz="0.0" iyy="0.00001" iyz="0.0" izz="0.0" />-->
      <inertia ixx="1.0" ixy="0.0" ixz="0.0" iyy="1.0" iyz="0.0" izz="1.0"/>
    </inertial>
  </link>
  <!-- gripper main fixed joint-->
  <joint name="robot1/end_effector_joint" type="fixed">
    <parent link="robot1/gripper_main_link"/>
    <child link="robot1/end_effector_link"/>
    <origin rpy="3.141592653589793 -1.5707963267948966 0" xyz="0.0 0.0 0.135"/>
  </joint>
  <!-- End Effector -->
  <link name="robot1/end_effector_link">
    <visual>
      <origin rpy="0 0 0" xyz="0.0 0.0 0.0"/>
      <geometry>
        <box size="0.01 0.01 0.01"/>
      </geometry>
      <material name="red"/>
    </visual>
    <!-- <collision>
        <origin xyz="0.0 0.0 0.0" rpy="0 0 0" />
        <geometry>
          <box size = "0.01 0.01 0.01"/>
        </geometry>
        <material name="red"/>
      </collision> -->
    <inertial>
      <origin rpy="0 0 0" xyz="0.0 0.0 0.0"/>
      <mass value="0.001"/>
      <inertia ixx="1.0" ixy="0.0" ixz="0.0" iyy="1.0" iyz="0.0" izz="1.0"/>
    </inertial>
  </link>
  <joint name="robot1/hand_joint" type="fixed">
    <parent link="robot1/gripper_main_link"/>
    <child link="robot1/hand_link"/>
    <origin rpy="3.141592653589793 -1.5707963267948966 0" xyz="0.0 0.0 0.10"/>
  </joint>
  <!-- End Effector -->
  <link name="robot1/hand_link">
  </link>
  <gazebo reference="robot1/end_effector_link">
    <material>Gazebo/Red</material>
  </gazebo>
  <gazebo>
    <!-- loading plugin: mimic joints works in gazebo now -->
    <plugin filename="libroboticsgroup_upatras_gazebo_mimic_joint_plugin.so" name="gazebo_gripper1_ros_control">
      <joint>robot1/gripper</joint>
      <mimicJoint>robot1/gripper_sub</mimicJoint>
      <multiplier>1.0</multiplier>
      <offset>0.0</offset>
    </plugin>
  </gazebo>
  <!-- camera link fixed joint -->
  <joint name="robot1/camera_fixed_joint" type="fixed">
    <parent link="robot1/gripper_main_link"/>
    <child link="robot1/camera_mount"/>
    <origin xyz="0.04452 -0.0167 0.049" rpy="0 0 1.5707963267948966" />
  </joint>
  <!-- Camera Mount -->
  <link name="robot1/camera_mount">
    <visual>
      <origin rpy="1.5707963267948966 -1.5707963267948966 0" xyz="0 0 0"/>
      <geometry>
        <mesh filename="assets/papras/camera_mount.stl"/>
      </geometry>
      <material name="grey"/>
    </visual>
    <collision>
      <origin rpy="1.5707963267948966 -1.5707963267948966 0" xyz="0 0 0"/>
      <geometry>
        <mesh filename="assets/papras/camera_mount_simple.stl"/>
      </geometry>
    </collision>
    <inertial>
      <origin rpy="1.5707963267948966 -1.5707963267948966 0" xyz="0 0 0"/>
      <mass value="0.088"/>
      <inertia ixx="1.0" ixy="0.0" ixz="0.0" iyy="1.0" iyz="0.0" izz="1.0"/>
    </inertial>
  </link>
  <gazebo reference="robot1/camera_mount">
    <kp>1000000.0</kp>
    <kd>100.0</kd>
    <mu1>30.0</mu1>
    <mu2>30.0</mu2>
    <maxVel>1.0</maxVel>
    <minDepth>0.001</minDepth>
    <material>Gazebo/White</material>
    <selfCollide>1</selfCollide>
    <dampingFactor>0.01</dampingFactor>
  </gazebo>
  <joint name="robot1/camera_mount_link" type="fixed">
    <parent link="robot1/camera_mount"/>
    <child link="robot1/camera_link"/>
    <origin rpy="0 0 0" xyz="-0.015 0 0"/>
  </joint>
  <link name="robot1/camera_link"/>
  <joint name="robot1/camera_fixed_plugin_joint" type="fixed">
    <parent link="robot1/camera_link"/>
    <child link="robot1/camera_plugin_link"/>
    <origin rpy="1.5707963267948966 -1.5707963267948966 0" xyz="0 0 0"/>
  </joint>
  <link name="robot1/camera_plugin_link"/>
  <gazebo reference="robot1/camera_plugin_link">
    <kp>1000000.0</kp>
    <kd>100.0</kd>
    <mu1>30.0</mu1>
    <mu2>30.0</mu2>
    <maxVel>1.0</maxVel>
    <minDepth>0.001</minDepth>
    <material>Gazebo/White</material>
    <selfCollide>1</selfCollide>
    <dampingFactor>0.01</dampingFactor>
  </gazebo>
  <gazebo reference="robot1/camera_plugin_link">
    <sensor name="robot1/camera_sensor" type="depth">
      <update_rate>30.0</update_rate>
      <camera name="realsense_d435">
        <horizontal_fov>1.20428</horizontal_fov>
        <image>
          <width>640</width>
          <height>480</height>
          <format>R8G8B8</format>
        </image>
        <clip>
          <near>0.03</near>
          <far>3</far>
        </clip>
        <noise>
          <type>gaussian</type>
          <!-- Noise is sampled independently per pixel on each frame.
                That pixel's noise value is added to each of its color
                channels, which at that point lie in the range [0,1]. -->
          <mean>0.0</mean>
          <stddev>0.007</stddev>
        </noise>
      </camera>
      <plugin filename="libgazebo_ros_openni_kinect.so" name="camera_plugin">
        <baseline>0.2</baseline>
        <alwaysOn>true</alwaysOn>
        <!-- Keep this zero, update_rate in the parent <sensor> tag
            will control the frame rate. -->
        <updateRate>0.0</updateRate>
        <cameraName>robot1/camera</cameraName>
        <imageTopicName>color/image_raw</imageTopicName>
        <cameraInfoTopicName>color/camera_info</cameraInfoTopicName>
        <depthImageTopicName>depth/image_raw</depthImageTopicName>
        <depthImageCameraInfoTopicName>depth/camera_info</depthImageCameraInfoTopicName>
        <pointCloudTopicName>depth/points</pointCloudTopicName>
        <frameName>robot1/camera_link</frameName>
        <pointCloudCutoff>0.1</pointCloudCutoff>
        <pointCloudCutoffMax>3.0</pointCloudCutoffMax>
        <distortionK1>0</distortionK1>
        <distortionK2>0</distortionK2>
        <distortionK3>0</distortionK3>
        <distortionT1>0</distortionT1>
        <distortionT2>0</distortionT2>
        <CxPrime>0</CxPrime>
        <Cx>0</Cx>
        <Cy>0</Cy>
        <focalLength>0</focalLength>
        <hackBaseline>0</hackBaseline>
      </plugin>
    </sensor>
  </gazebo>
</robot>

